2021-01-13 21:09:36,971 - __main__ - DEBUG - Запуск бота
2021-01-13 21:09:39,620 - __main__ - INFO - Отправка сообщения в телеграм: У вас проверили работу "AnastasiaSar__api_sp1_bot.zip"!

К сожалению в работе нашлись ошибки.
2021-01-13 21:09:44,637 - telegram.vendor.ptb_urllib3.urllib3.connectionpool - WARNING - Retrying (Retry(total=2, connect=None, read=None, redirect=None)) after connection broken by 'ConnectTimeoutError(<telegram.vendor.ptb_urllib3.urllib3.connection.VerifiedHTTPSConnection object at 0x0000019102DBA640>, 'Connection to api.telegram.org timed out. (connect timeout=5.0)')': /bot1433757250:AAEo4RDod8FFHlZw0bnbR_tHqzHWjYUistA/sendMessage
2021-01-13 21:09:49,647 - telegram.vendor.ptb_urllib3.urllib3.connectionpool - WARNING - Retrying (Retry(total=1, connect=None, read=None, redirect=None)) after connection broken by 'ConnectTimeoutError(<telegram.vendor.ptb_urllib3.urllib3.connection.VerifiedHTTPSConnection object at 0x0000019102DBAFD0>, 'Connection to api.telegram.org timed out. (connect timeout=5.0)')': /bot1433757250:AAEo4RDod8FFHlZw0bnbR_tHqzHWjYUistA/sendMessage
2021-01-13 21:09:54,651 - telegram.vendor.ptb_urllib3.urllib3.connectionpool - WARNING - Retrying (Retry(total=0, connect=None, read=None, redirect=None)) after connection broken by 'ConnectTimeoutError(<telegram.vendor.ptb_urllib3.urllib3.connection.VerifiedHTTPSConnection object at 0x0000019102DBA550>, 'Connection to api.telegram.org timed out. (connect timeout=5.0)')': /bot1433757250:AAEo4RDod8FFHlZw0bnbR_tHqzHWjYUistA/sendMessage
2021-01-13 21:09:59,657 - __main__ - ERROR - Бот столкнулся с ошибкой: urllib3 HTTPError HTTPSConnectionPool(host='api.telegram.org', port=443): Max retries exceeded with url: /bot1433757250:AAEo4RDod8FFHlZw0bnbR_tHqzHWjYUistA/sendMessage (Caused by ConnectTimeoutError(<telegram.vendor.ptb_urllib3.urllib3.connection.VerifiedHTTPSConnection object at 0x0000019102DBA2E0>, 'Connection to api.telegram.org timed out. (connect timeout=5.0)'))
2021-01-13 21:10:05,826 - __main__ - INFO - Отправка сообщения в телеграм: У вас проверили работу "AnastasiaSar__api_sp1_bot.zip"!

К сожалению в работе нашлись ошибки.
2021-01-13 21:10:10,830 - telegram.vendor.ptb_urllib3.urllib3.connectionpool - WARNING - Retrying (Retry(total=2, connect=None, read=None, redirect=None)) after connection broken by 'ConnectTimeoutError(<telegram.vendor.ptb_urllib3.urllib3.connection.VerifiedHTTPSConnection object at 0x0000019102DBAB20>, 'Connection to api.telegram.org timed out. (connect timeout=5.0)')': /bot1433757250:AAEo4RDod8FFHlZw0bnbR_tHqzHWjYUistA/sendMessage
2021-01-13 21:10:17,157 - telegram.vendor.ptb_urllib3.urllib3.connectionpool - WARNING - Retrying (Retry(total=1, connect=None, read=None, redirect=None)) after connection broken by 'ConnectTimeoutError(<telegram.vendor.ptb_urllib3.urllib3.connectionpool.HTTPSConnectionPool object at 0x0000019102DBA3D0>, 'Connect timed out. (connect timeout=5.0)')': /bot1433757250:AAEo4RDod8FFHlZw0bnbR_tHqzHWjYUistA/sendMessage
2021-01-13 21:10:22,472 - telegram.vendor.ptb_urllib3.urllib3.connectionpool - WARNING - Retrying (Retry(total=0, connect=None, read=None, redirect=None)) after connection broken by 'ConnectTimeoutError(<telegram.vendor.ptb_urllib3.urllib3.connectionpool.HTTPSConnectionPool object at 0x0000019102DBA3D0>, 'Connect timed out. (connect timeout=5.0)')': /bot1433757250:AAEo4RDod8FFHlZw0bnbR_tHqzHWjYUistA/sendMessage
2021-01-13 21:10:28,790 - __main__ - ERROR - Бот столкнулся с ошибкой: urllib3 HTTPError HTTPSConnectionPool(host='api.telegram.org', port=443): Max retries exceeded with url: /bot1433757250:AAEo4RDod8FFHlZw0bnbR_tHqzHWjYUistA/sendMessage (Caused by ConnectTimeoutError(<telegram.vendor.ptb_urllib3.urllib3.connectionpool.HTTPSConnectionPool object at 0x0000019102DBA3D0>, 'Connect timed out. (connect timeout=5.0)'))
2021-01-13 21:10:36,233 - __main__ - INFO - Отправка сообщения в телеграм: У вас проверили работу "AnastasiaSar__api_sp1_bot.zip"!

К сожалению в работе нашлись ошибки.
2021-01-13 21:10:41,544 - telegram.vendor.ptb_urllib3.urllib3.connectionpool - WARNING - Retrying (Retry(total=2, connect=None, read=None, redirect=None)) after connection broken by 'ConnectTimeoutError(<telegram.vendor.ptb_urllib3.urllib3.connectionpool.HTTPSConnectionPool object at 0x0000019102DBA3D0>, 'Connect timed out. (connect timeout=5.0)')': /bot1433757250:AAEo4RDod8FFHlZw0bnbR_tHqzHWjYUistA/sendMessage
2021-01-13 21:13:38,972 - __main__ - INFO - Отправка сообщения в телеграм: privet
2021-01-13 21:13:43,989 - telegram.vendor.ptb_urllib3.urllib3.connectionpool - WARNING - Retrying (Retry(total=2, connect=None, read=None, redirect=None)) after connection broken by 'ConnectTimeoutError(<telegram.vendor.ptb_urllib3.urllib3.connection.VerifiedHTTPSConnection object at 0x0000018EB56872B0>, 'Connection to api.telegram.org timed out. (connect timeout=5.0)')': /bot1433757250:AAEo4RDod8FFHlZw0bnbR_tHqzHWjYUistA/sendMessage
2021-01-13 21:13:49,003 - telegram.vendor.ptb_urllib3.urllib3.connectionpool - WARNING - Retrying (Retry(total=1, connect=None, read=None, redirect=None)) after connection broken by 'ConnectTimeoutError(<telegram.vendor.ptb_urllib3.urllib3.connection.VerifiedHTTPSConnection object at 0x0000018EB5687430>, 'Connection to api.telegram.org timed out. (connect timeout=5.0)')': /bot1433757250:AAEo4RDod8FFHlZw0bnbR_tHqzHWjYUistA/sendMessage
2021-01-13 21:13:54,019 - telegram.vendor.ptb_urllib3.urllib3.connectionpool - WARNING - Retrying (Retry(total=0, connect=None, read=None, redirect=None)) after connection broken by 'ConnectTimeoutError(<telegram.vendor.ptb_urllib3.urllib3.connection.VerifiedHTTPSConnection object at 0x0000018EB5687550>, 'Connection to api.telegram.org timed out. (connect timeout=5.0)')': /bot1433757250:AAEo4RDod8FFHlZw0bnbR_tHqzHWjYUistA/sendMessage
2021-01-13 21:29:27,292 - __main__ - DEBUG - Запуск бота
2021-01-13 21:29:30,544 - __main__ - INFO - Отправка сообщения в телеграм: У вас проверили работу "AnastasiaSar__api_sp1_bot.zip"!

К сожалению в работе нашлись ошибки.
2021-01-13 21:29:35,547 - telegram.vendor.ptb_urllib3.urllib3.connectionpool - WARNING - Retrying (Retry(total=2, connect=None, read=None, redirect=None)) after connection broken by 'ConnectTimeoutError(<telegram.vendor.ptb_urllib3.urllib3.connection.VerifiedHTTPSConnection object at 0x0000025692BFA640>, 'Connection to api.telegram.org timed out. (connect timeout=5.0)')': /bot1433757250:AAEo4RDod8FFHlZw0bnbR_tHqzHWjYUistA/sendMessage
2021-01-13 21:29:40,552 - telegram.vendor.ptb_urllib3.urllib3.connectionpool - WARNING - Retrying (Retry(total=1, connect=None, read=None, redirect=None)) after connection broken by 'ConnectTimeoutError(<telegram.vendor.ptb_urllib3.urllib3.connection.VerifiedHTTPSConnection object at 0x0000025692BFAFD0>, 'Connection to api.telegram.org timed out. (connect timeout=5.0)')': /bot1433757250:AAEo4RDod8FFHlZw0bnbR_tHqzHWjYUistA/sendMessage
2021-01-13 21:29:45,564 - telegram.vendor.ptb_urllib3.urllib3.connectionpool - WARNING - Retrying (Retry(total=0, connect=None, read=None, redirect=None)) after connection broken by 'ConnectTimeoutError(<telegram.vendor.ptb_urllib3.urllib3.connection.VerifiedHTTPSConnection object at 0x0000025692BFA550>, 'Connection to api.telegram.org timed out. (connect timeout=5.0)')': /bot1433757250:AAEo4RDod8FFHlZw0bnbR_tHqzHWjYUistA/sendMessage
2021-01-13 21:29:50,572 - __main__ - ERROR - Бот столкнулся с ошибкой: urllib3 HTTPError HTTPSConnectionPool(host='api.telegram.org', port=443): Max retries exceeded with url: /bot1433757250:AAEo4RDod8FFHlZw0bnbR_tHqzHWjYUistA/sendMessage (Caused by ConnectTimeoutError(<telegram.vendor.ptb_urllib3.urllib3.connection.VerifiedHTTPSConnection object at 0x0000025692BFA2E0>, 'Connection to api.telegram.org timed out. (connect timeout=5.0)'))
2021-01-13 21:29:57,080 - __main__ - INFO - Отправка сообщения в телеграм: У вас проверили работу "AnastasiaSar__api_sp1_bot.zip"!

К сожалению в работе нашлись ошибки.
2021-01-13 21:30:02,084 - telegram.vendor.ptb_urllib3.urllib3.connectionpool - WARNING - Retrying (Retry(total=2, connect=None, read=None, redirect=None)) after connection broken by 'ConnectTimeoutError(<telegram.vendor.ptb_urllib3.urllib3.connection.VerifiedHTTPSConnection object at 0x0000025692BFAB20>, 'Connection to api.telegram.org timed out. (connect timeout=5.0)')': /bot1433757250:AAEo4RDod8FFHlZw0bnbR_tHqzHWjYUistA/sendMessage
2021-01-13 21:30:07,094 - telegram.vendor.ptb_urllib3.urllib3.connectionpool - WARNING - Retrying (Retry(total=1, connect=None, read=None, redirect=None)) after connection broken by 'ConnectTimeoutError(<telegram.vendor.ptb_urllib3.urllib3.connection.VerifiedHTTPSConnection object at 0x0000025692BFA370>, 'Connection to api.telegram.org timed out. (connect timeout=5.0)')': /bot1433757250:AAEo4RDod8FFHlZw0bnbR_tHqzHWjYUistA/sendMessage
2021-01-13 21:30:12,109 - telegram.vendor.ptb_urllib3.urllib3.connectionpool - WARNING - Retrying (Retry(total=0, connect=None, read=None, redirect=None)) after connection broken by 'ConnectTimeoutError(<telegram.vendor.ptb_urllib3.urllib3.connection.VerifiedHTTPSConnection object at 0x0000025692BFAFA0>, 'Connection to api.telegram.org timed out. (connect timeout=5.0)')': /bot1433757250:AAEo4RDod8FFHlZw0bnbR_tHqzHWjYUistA/sendMessage
2021-01-13 21:30:17,123 - __main__ - ERROR - Бот столкнулся с ошибкой: urllib3 HTTPError HTTPSConnectionPool(host='api.telegram.org', port=443): Max retries exceeded with url: /bot1433757250:AAEo4RDod8FFHlZw0bnbR_tHqzHWjYUistA/sendMessage (Caused by ConnectTimeoutError(<telegram.vendor.ptb_urllib3.urllib3.connection.VerifiedHTTPSConnection object at 0x0000025692C43130>, 'Connection to api.telegram.org timed out. (connect timeout=5.0)'))
2021-01-13 21:30:24,591 - __main__ - INFO - Отправка сообщения в телеграм: У вас проверили работу "AnastasiaSar__api_sp1_bot.zip"!

К сожалению в работе нашлись ошибки.
2021-01-13 21:30:29,595 - telegram.vendor.ptb_urllib3.urllib3.connectionpool - WARNING - Retrying (Retry(total=2, connect=None, read=None, redirect=None)) after connection broken by 'ConnectTimeoutError(<telegram.vendor.ptb_urllib3.urllib3.connection.VerifiedHTTPSConnection object at 0x0000025692BFA1F0>, 'Connection to api.telegram.org timed out. (connect timeout=5.0)')': /bot1433757250:AAEo4RDod8FFHlZw0bnbR_tHqzHWjYUistA/sendMessage
2021-01-13 21:30:34,620 - telegram.vendor.ptb_urllib3.urllib3.connectionpool - WARNING - Retrying (Retry(total=1, connect=None, read=None, redirect=None)) after connection broken by 'ConnectTimeoutError(<telegram.vendor.ptb_urllib3.urllib3.connection.VerifiedHTTPSConnection object at 0x0000025692BFA0D0>, 'Connection to api.telegram.org timed out. (connect timeout=5.0)')': /bot1433757250:AAEo4RDod8FFHlZw0bnbR_tHqzHWjYUistA/sendMessage
2021-01-13 21:30:39,631 - telegram.vendor.ptb_urllib3.urllib3.connectionpool - WARNING - Retrying (Retry(total=0, connect=None, read=None, redirect=None)) after connection broken by 'ConnectTimeoutError(<telegram.vendor.ptb_urllib3.urllib3.connection.VerifiedHTTPSConnection object at 0x0000025692BFAA30>, 'Connection to api.telegram.org timed out. (connect timeout=5.0)')': /bot1433757250:AAEo4RDod8FFHlZw0bnbR_tHqzHWjYUistA/sendMessage
2021-01-13 21:30:44,636 - __main__ - ERROR - Бот столкнулся с ошибкой: urllib3 HTTPError HTTPSConnectionPool(host='api.telegram.org', port=443): Max retries exceeded with url: /bot1433757250:AAEo4RDod8FFHlZw0bnbR_tHqzHWjYUistA/sendMessage (Caused by ConnectTimeoutError(<telegram.vendor.ptb_urllib3.urllib3.connection.VerifiedHTTPSConnection object at 0x0000025692BFA4F0>, 'Connection to api.telegram.org timed out. (connect timeout=5.0)'))
2021-01-13 21:30:52,419 - __main__ - INFO - Отправка сообщения в телеграм: У вас проверили работу "AnastasiaSar__api_sp1_bot.zip"!

К сожалению в работе нашлись ошибки.
2021-01-13 21:30:57,425 - telegram.vendor.ptb_urllib3.urllib3.connectionpool - WARNING - Retrying (Retry(total=2, connect=None, read=None, redirect=None)) after connection broken by 'ConnectTimeoutError(<telegram.vendor.ptb_urllib3.urllib3.connection.VerifiedHTTPSConnection object at 0x0000025692BFAA60>, 'Connection to api.telegram.org timed out. (connect timeout=5.0)')': /bot1433757250:AAEo4RDod8FFHlZw0bnbR_tHqzHWjYUistA/sendMessage
2021-01-13 21:31:02,438 - telegram.vendor.ptb_urllib3.urllib3.connectionpool - WARNING - Retrying (Retry(total=1, connect=None, read=None, redirect=None)) after connection broken by 'ConnectTimeoutError(<telegram.vendor.ptb_urllib3.urllib3.connection.VerifiedHTTPSConnection object at 0x0000025692BFA280>, 'Connection to api.telegram.org timed out. (connect timeout=5.0)')': /bot1433757250:AAEo4RDod8FFHlZw0bnbR_tHqzHWjYUistA/sendMessage
2021-01-13 21:31:07,445 - telegram.vendor.ptb_urllib3.urllib3.connectionpool - WARNING - Retrying (Retry(total=0, connect=None, read=None, redirect=None)) after connection broken by 'ConnectTimeoutError(<telegram.vendor.ptb_urllib3.urllib3.connection.VerifiedHTTPSConnection object at 0x0000025692BFA880>, 'Connection to api.telegram.org timed out. (connect timeout=5.0)')': /bot1433757250:AAEo4RDod8FFHlZw0bnbR_tHqzHWjYUistA/sendMessage
2021-01-13 21:31:12,459 - __main__ - ERROR - Бот столкнулся с ошибкой: urllib3 HTTPError HTTPSConnectionPool(host='api.telegram.org', port=443): Max retries exceeded with url: /bot1433757250:AAEo4RDod8FFHlZw0bnbR_tHqzHWjYUistA/sendMessage (Caused by ConnectTimeoutError(<telegram.vendor.ptb_urllib3.urllib3.connection.VerifiedHTTPSConnection object at 0x0000025692C45130>, 'Connection to api.telegram.org timed out. (connect timeout=5.0)'))
2021-01-13 21:31:19,537 - __main__ - INFO - Отправка сообщения в телеграм: У вас проверили работу "AnastasiaSar__api_sp1_bot.zip"!

К сожалению в работе нашлись ошибки.
2021-01-13 21:31:24,541 - telegram.vendor.ptb_urllib3.urllib3.connectionpool - WARNING - Retrying (Retry(total=2, connect=None, read=None, redirect=None)) after connection broken by 'ConnectTimeoutError(<telegram.vendor.ptb_urllib3.urllib3.connection.VerifiedHTTPSConnection object at 0x0000025692C452E0>, 'Connection to api.telegram.org timed out. (connect timeout=5.0)')': /bot1433757250:AAEo4RDod8FFHlZw0bnbR_tHqzHWjYUistA/sendMessage
2021-01-13 21:31:29,553 - telegram.vendor.ptb_urllib3.urllib3.connectionpool - WARNING - Retrying (Retry(total=1, connect=None, read=None, redirect=None)) after connection broken by 'ConnectTimeoutError(<telegram.vendor.ptb_urllib3.urllib3.connection.VerifiedHTTPSConnection object at 0x0000025692C45760>, 'Connection to api.telegram.org timed out. (connect timeout=5.0)')': /bot1433757250:AAEo4RDod8FFHlZw0bnbR_tHqzHWjYUistA/sendMessage
2021-01-13 21:31:34,557 - telegram.vendor.ptb_urllib3.urllib3.connectionpool - WARNING - Retrying (Retry(total=0, connect=None, read=None, redirect=None)) after connection broken by 'ConnectTimeoutError(<telegram.vendor.ptb_urllib3.urllib3.connection.VerifiedHTTPSConnection object at 0x0000025692C457C0>, 'Connection to api.telegram.org timed out. (connect timeout=5.0)')': /bot1433757250:AAEo4RDod8FFHlZw0bnbR_tHqzHWjYUistA/sendMessage
2021-01-13 21:31:39,574 - __main__ - ERROR - Бот столкнулся с ошибкой: urllib3 HTTPError HTTPSConnectionPool(host='api.telegram.org', port=443): Max retries exceeded with url: /bot1433757250:AAEo4RDod8FFHlZw0bnbR_tHqzHWjYUistA/sendMessage (Caused by ConnectTimeoutError(<telegram.vendor.ptb_urllib3.urllib3.connection.VerifiedHTTPSConnection object at 0x0000025692C45B80>, 'Connection to api.telegram.org timed out. (connect timeout=5.0)'))
2021-01-13 21:31:48,387 - __main__ - INFO - Отправка сообщения в телеграм: У вас проверили работу "AnastasiaSar__api_sp1_bot.zip"!

К сожалению в работе нашлись ошибки.
2021-01-13 21:33:12,175 - __main__ - DEBUG - Запуск бота
2021-01-13 21:33:23,334 - __main__ - ERROR - Бот столкнулся с ошибкой: 'str' object has no attribute 'status_code'
2021-01-13 21:33:32,917 - __main__ - ERROR - Бот столкнулся с ошибкой: 'str' object has no attribute 'status_code'
2021-01-13 21:33:53,320 - __main__ - ERROR - Бот столкнулся с ошибкой: 'str' object has no attribute 'status_code'
2021-01-13 21:34:02,746 - __main__ - ERROR - Бот столкнулся с ошибкой: 'str' object has no attribute 'status_code'
2021-01-13 21:34:12,513 - __main__ - ERROR - Бот столкнулся с ошибкой: 'str' object has no attribute 'status_code'
2021-01-13 21:34:20,639 - __main__ - ERROR - Бот столкнулся с ошибкой: 'str' object has no attribute 'status_code'
2021-01-13 21:34:33,298 - __main__ - ERROR - Бот столкнулся с ошибкой: 'str' object has no attribute 'status_code'
2021-01-13 21:34:42,085 - __main__ - ERROR - Бот столкнулся с ошибкой: 'str' object has no attribute 'status_code'
2021-01-13 21:34:51,636 - __main__ - ERROR - Бот столкнулся с ошибкой: 'str' object has no attribute 'status_code'
2021-01-13 21:35:00,774 - __main__ - ERROR - Бот столкнулся с ошибкой: 'str' object has no attribute 'status_code'
2021-01-13 21:35:10,390 - __main__ - ERROR - Бот столкнулся с ошибкой: 'str' object has no attribute 'status_code'
2021-01-13 21:35:29,573 - __main__ - DEBUG - Запуск бота
2021-01-13 21:35:31,747 - __main__ - ERROR - Бот столкнулся с ошибкой: 'str' object has no attribute 'status_code'
2021-01-13 21:35:38,941 - __main__ - ERROR - Бот столкнулся с ошибкой: 'str' object has no attribute 'status_code'
2021-01-13 21:35:51,180 - __main__ - ERROR - Бот столкнулся с ошибкой: 'str' object has no attribute 'status_code'
2021-01-13 21:35:57,695 - __main__ - ERROR - Бот столкнулся с ошибкой: 'str' object has no attribute 'status_code'
2021-01-13 21:36:07,377 - __main__ - ERROR - Бот столкнулся с ошибкой: 'str' object has no attribute 'status_code'
2021-01-13 21:36:16,451 - __main__ - ERROR - Бот столкнулся с ошибкой: 'str' object has no attribute 'status_code'
2021-01-13 21:36:24,455 - __main__ - ERROR - Бот столкнулся с ошибкой: 'str' object has no attribute 'status_code'
2021-01-13 21:36:31,782 - __main__ - ERROR - Бот столкнулся с ошибкой: 'str' object has no attribute 'status_code'
2021-01-13 21:36:40,136 - __main__ - ERROR - Бот столкнулся с ошибкой: 'str' object has no attribute 'status_code'
2021-01-13 21:36:46,469 - __main__ - ERROR - Бот столкнулся с ошибкой: 'str' object has no attribute 'status_code'
2021-01-13 21:36:55,150 - __main__ - ERROR - Бот столкнулся с ошибкой: 'str' object has no attribute 'status_code'
2021-01-13 21:37:16,329 - __main__ - DEBUG - Запуск бота
2021-01-13 21:37:20,373 - __main__ - INFO - Отправка сообщения в телеграм: У вас проверили работу "AnastasiaSar__api_sp1_bot.zip"!

К сожалению в работе нашлись ошибки.
2021-01-13 21:37:25,401 - telegram.vendor.ptb_urllib3.urllib3.connectionpool - WARNING - Retrying (Retry(total=2, connect=None, read=None, redirect=None)) after connection broken by 'ConnectTimeoutError(<telegram.vendor.ptb_urllib3.urllib3.connection.VerifiedHTTPSConnection object at 0x00000175F8A2A640>, 'Connection to api.telegram.org timed out. (connect timeout=5.0)')': /bot1433757250:AAEo4RDod8FFHlZw0bnbR_tHqzHWjYUistA/sendMessage
2021-01-13 21:37:30,409 - telegram.vendor.ptb_urllib3.urllib3.connectionpool - WARNING - Retrying (Retry(total=1, connect=None, read=None, redirect=None)) after connection broken by 'ConnectTimeoutError(<telegram.vendor.ptb_urllib3.urllib3.connection.VerifiedHTTPSConnection object at 0x00000175F8A2AFD0>, 'Connection to api.telegram.org timed out. (connect timeout=5.0)')': /bot1433757250:AAEo4RDod8FFHlZw0bnbR_tHqzHWjYUistA/sendMessage
2021-01-13 21:37:35,422 - telegram.vendor.ptb_urllib3.urllib3.connectionpool - WARNING - Retrying (Retry(total=0, connect=None, read=None, redirect=None)) after connection broken by 'ConnectTimeoutError(<telegram.vendor.ptb_urllib3.urllib3.connection.VerifiedHTTPSConnection object at 0x00000175F8A2A550>, 'Connection to api.telegram.org timed out. (connect timeout=5.0)')': /bot1433757250:AAEo4RDod8FFHlZw0bnbR_tHqzHWjYUistA/sendMessage
2021-01-13 21:37:40,444 - __main__ - ERROR - Бот столкнулся с ошибкой: urllib3 HTTPError HTTPSConnectionPool(host='api.telegram.org', port=443): Max retries exceeded with url: /bot1433757250:AAEo4RDod8FFHlZw0bnbR_tHqzHWjYUistA/sendMessage (Caused by ConnectTimeoutError(<telegram.vendor.ptb_urllib3.urllib3.connection.VerifiedHTTPSConnection object at 0x00000175F8A2A2E0>, 'Connection to api.telegram.org timed out. (connect timeout=5.0)'))
2021-01-13 21:37:57,233 - __main__ - INFO - Отправка сообщения в телеграм: У вас проверили работу "AnastasiaSar__api_sp1_bot.zip"!

К сожалению в работе нашлись ошибки.
2021-01-13 21:38:02,237 - telegram.vendor.ptb_urllib3.urllib3.connectionpool - WARNING - Retrying (Retry(total=2, connect=None, read=None, redirect=None)) after connection broken by 'ConnectTimeoutError(<telegram.vendor.ptb_urllib3.urllib3.connection.VerifiedHTTPSConnection object at 0x00000175F8A2AB20>, 'Connection to api.telegram.org timed out. (connect timeout=5.0)')': /bot1433757250:AAEo4RDod8FFHlZw0bnbR_tHqzHWjYUistA/sendMessage
2021-01-13 21:38:07,240 - telegram.vendor.ptb_urllib3.urllib3.connectionpool - WARNING - Retrying (Retry(total=1, connect=None, read=None, redirect=None)) after connection broken by 'ConnectTimeoutError(<telegram.vendor.ptb_urllib3.urllib3.connection.VerifiedHTTPSConnection object at 0x00000175F8A2A370>, 'Connection to api.telegram.org timed out. (connect timeout=5.0)')': /bot1433757250:AAEo4RDod8FFHlZw0bnbR_tHqzHWjYUistA/sendMessage
2021-01-13 21:38:12,533 - telegram.vendor.ptb_urllib3.urllib3.connectionpool - WARNING - Retrying (Retry(total=0, connect=None, read=None, redirect=None)) after connection broken by 'ConnectTimeoutError(<telegram.vendor.ptb_urllib3.urllib3.connection.VerifiedHTTPSConnection object at 0x00000175F8A2AFA0>, 'Connection to api.telegram.org timed out. (connect timeout=5.0)')': /bot1433757250:AAEo4RDod8FFHlZw0bnbR_tHqzHWjYUistA/sendMessage
2021-01-13 21:38:17,540 - __main__ - ERROR - Бот столкнулся с ошибкой: urllib3 HTTPError HTTPSConnectionPool(host='api.telegram.org', port=443): Max retries exceeded with url: /bot1433757250:AAEo4RDod8FFHlZw0bnbR_tHqzHWjYUistA/sendMessage (Caused by ConnectTimeoutError(<telegram.vendor.ptb_urllib3.urllib3.connection.VerifiedHTTPSConnection object at 0x00000175F8A73130>, 'Connection to api.telegram.org timed out. (connect timeout=5.0)'))
2021-01-13 21:38:24,800 - __main__ - INFO - Отправка сообщения в телеграм: У вас проверили работу "AnastasiaSar__api_sp1_bot.zip"!

К сожалению в работе нашлись ошибки.
2021-01-13 21:38:29,811 - telegram.vendor.ptb_urllib3.urllib3.connectionpool - WARNING - Retrying (Retry(total=2, connect=None, read=None, redirect=None)) after connection broken by 'ConnectTimeoutError(<telegram.vendor.ptb_urllib3.urllib3.connection.VerifiedHTTPSConnection object at 0x00000175F8A2A1F0>, 'Connection to api.telegram.org timed out. (connect timeout=5.0)')': /bot1433757250:AAEo4RDod8FFHlZw0bnbR_tHqzHWjYUistA/sendMessage
2021-01-13 21:38:34,817 - telegram.vendor.ptb_urllib3.urllib3.connectionpool - WARNING - Retrying (Retry(total=1, connect=None, read=None, redirect=None)) after connection broken by 'ConnectTimeoutError(<telegram.vendor.ptb_urllib3.urllib3.connection.VerifiedHTTPSConnection object at 0x00000175F8A2A0D0>, 'Connection to api.telegram.org timed out. (connect timeout=5.0)')': /bot1433757250:AAEo4RDod8FFHlZw0bnbR_tHqzHWjYUistA/sendMessage
2021-01-13 21:38:39,831 - telegram.vendor.ptb_urllib3.urllib3.connectionpool - WARNING - Retrying (Retry(total=0, connect=None, read=None, redirect=None)) after connection broken by 'ConnectTimeoutError(<telegram.vendor.ptb_urllib3.urllib3.connection.VerifiedHTTPSConnection object at 0x00000175F8A2AA30>, 'Connection to api.telegram.org timed out. (connect timeout=5.0)')': /bot1433757250:AAEo4RDod8FFHlZw0bnbR_tHqzHWjYUistA/sendMessage
2021-01-13 21:38:44,842 - __main__ - ERROR - Бот столкнулся с ошибкой: urllib3 HTTPError HTTPSConnectionPool(host='api.telegram.org', port=443): Max retries exceeded with url: /bot1433757250:AAEo4RDod8FFHlZw0bnbR_tHqzHWjYUistA/sendMessage (Caused by ConnectTimeoutError(<telegram.vendor.ptb_urllib3.urllib3.connection.VerifiedHTTPSConnection object at 0x00000175F8A2A4F0>, 'Connection to api.telegram.org timed out. (connect timeout=5.0)'))
2021-01-13 21:38:59,359 - __main__ - INFO - Отправка сообщения в телеграм: У вас проверили работу "AnastasiaSar__api_sp1_bot.zip"!

К сожалению в работе нашлись ошибки.
2021-01-13 21:39:04,371 - telegram.vendor.ptb_urllib3.urllib3.connectionpool - WARNING - Retrying (Retry(total=2, connect=None, read=None, redirect=None)) after connection broken by 'ConnectTimeoutError(<telegram.vendor.ptb_urllib3.urllib3.connection.VerifiedHTTPSConnection object at 0x00000175F8A2AA60>, 'Connection to api.telegram.org timed out. (connect timeout=5.0)')': /bot1433757250:AAEo4RDod8FFHlZw0bnbR_tHqzHWjYUistA/sendMessage
2021-01-13 21:39:09,373 - telegram.vendor.ptb_urllib3.urllib3.connectionpool - WARNING - Retrying (Retry(total=1, connect=None, read=None, redirect=None)) after connection broken by 'ConnectTimeoutError(<telegram.vendor.ptb_urllib3.urllib3.connection.VerifiedHTTPSConnection object at 0x00000175F8A2A280>, 'Connection to api.telegram.org timed out. (connect timeout=5.0)')': /bot1433757250:AAEo4RDod8FFHlZw0bnbR_tHqzHWjYUistA/sendMessage
2021-01-13 21:39:14,388 - telegram.vendor.ptb_urllib3.urllib3.connectionpool - WARNING - Retrying (Retry(total=0, connect=None, read=None, redirect=None)) after connection broken by 'ConnectTimeoutError(<telegram.vendor.ptb_urllib3.urllib3.connection.VerifiedHTTPSConnection object at 0x00000175F8A2A880>, 'Connection to api.telegram.org timed out. (connect timeout=5.0)')': /bot1433757250:AAEo4RDod8FFHlZw0bnbR_tHqzHWjYUistA/sendMessage
2021-01-13 21:39:19,394 - __main__ - ERROR - Бот столкнулся с ошибкой: urllib3 HTTPError HTTPSConnectionPool(host='api.telegram.org', port=443): Max retries exceeded with url: /bot1433757250:AAEo4RDod8FFHlZw0bnbR_tHqzHWjYUistA/sendMessage (Caused by ConnectTimeoutError(<telegram.vendor.ptb_urllib3.urllib3.connection.VerifiedHTTPSConnection object at 0x00000175F8A75130>, 'Connection to api.telegram.org timed out. (connect timeout=5.0)'))
2021-01-13 21:39:28,995 - __main__ - INFO - Отправка сообщения в телеграм: У вас проверили работу "AnastasiaSar__api_sp1_bot.zip"!

К сожалению в работе нашлись ошибки.
2021-01-13 21:39:34,002 - telegram.vendor.ptb_urllib3.urllib3.connectionpool - WARNING - Retrying (Retry(total=2, connect=None, read=None, redirect=None)) after connection broken by 'ConnectTimeoutError(<telegram.vendor.ptb_urllib3.urllib3.connection.VerifiedHTTPSConnection object at 0x00000175F8A752E0>, 'Connection to api.telegram.org timed out. (connect timeout=5.0)')': /bot1433757250:AAEo4RDod8FFHlZw0bnbR_tHqzHWjYUistA/sendMessage
2021-01-13 21:39:39,013 - telegram.vendor.ptb_urllib3.urllib3.connectionpool - WARNING - Retrying (Retry(total=1, connect=None, read=None, redirect=None)) after connection broken by 'ConnectTimeoutError(<telegram.vendor.ptb_urllib3.urllib3.connection.VerifiedHTTPSConnection object at 0x00000175F8A75760>, 'Connection to api.telegram.org timed out. (connect timeout=5.0)')': /bot1433757250:AAEo4RDod8FFHlZw0bnbR_tHqzHWjYUistA/sendMessage
2021-01-13 21:39:44,020 - telegram.vendor.ptb_urllib3.urllib3.connectionpool - WARNING - Retrying (Retry(total=0, connect=None, read=None, redirect=None)) after connection broken by 'ConnectTimeoutError(<telegram.vendor.ptb_urllib3.urllib3.connection.VerifiedHTTPSConnection object at 0x00000175F8A757C0>, 'Connection to api.telegram.org timed out. (connect timeout=5.0)')': /bot1433757250:AAEo4RDod8FFHlZw0bnbR_tHqzHWjYUistA/sendMessage
2021-01-13 21:39:49,027 - __main__ - ERROR - Бот столкнулся с ошибкой: urllib3 HTTPError HTTPSConnectionPool(host='api.telegram.org', port=443): Max retries exceeded with url: /bot1433757250:AAEo4RDod8FFHlZw0bnbR_tHqzHWjYUistA/sendMessage (Caused by ConnectTimeoutError(<telegram.vendor.ptb_urllib3.urllib3.connection.VerifiedHTTPSConnection object at 0x00000175F8A75B80>, 'Connection to api.telegram.org timed out. (connect timeout=5.0)'))
2021-01-13 21:39:57,386 - __main__ - INFO - Отправка сообщения в телеграм: У вас проверили работу "AnastasiaSar__api_sp1_bot.zip"!

К сожалению в работе нашлись ошибки.
2021-01-13 21:40:02,402 - telegram.vendor.ptb_urllib3.urllib3.connectionpool - WARNING - Retrying (Retry(total=2, connect=None, read=None, redirect=None)) after connection broken by 'ConnectTimeoutError(<telegram.vendor.ptb_urllib3.urllib3.connection.VerifiedHTTPSConnection object at 0x00000175F8A75BE0>, 'Connection to api.telegram.org timed out. (connect timeout=5.0)')': /bot1433757250:AAEo4RDod8FFHlZw0bnbR_tHqzHWjYUistA/sendMessage
2021-01-13 21:40:07,414 - telegram.vendor.ptb_urllib3.urllib3.connectionpool - WARNING - Retrying (Retry(total=1, connect=None, read=None, redirect=None)) after connection broken by 'ConnectTimeoutError(<telegram.vendor.ptb_urllib3.urllib3.connection.VerifiedHTTPSConnection object at 0x00000175F8A75550>, 'Connection to api.telegram.org timed out. (connect timeout=5.0)')': /bot1433757250:AAEo4RDod8FFHlZw0bnbR_tHqzHWjYUistA/sendMessage
2021-01-13 21:40:12,421 - telegram.vendor.ptb_urllib3.urllib3.connectionpool - WARNING - Retrying (Retry(total=0, connect=None, read=None, redirect=None)) after connection broken by 'ConnectTimeoutError(<telegram.vendor.ptb_urllib3.urllib3.connection.VerifiedHTTPSConnection object at 0x00000175F8A75CD0>, 'Connection to api.telegram.org timed out. (connect timeout=5.0)')': /bot1433757250:AAEo4RDod8FFHlZw0bnbR_tHqzHWjYUistA/sendMessage
2021-01-13 21:40:17,434 - __main__ - ERROR - Бот столкнулся с ошибкой: urllib3 HTTPError HTTPSConnectionPool(host='api.telegram.org', port=443): Max retries exceeded with url: /bot1433757250:AAEo4RDod8FFHlZw0bnbR_tHqzHWjYUistA/sendMessage (Caused by ConnectTimeoutError(<telegram.vendor.ptb_urllib3.urllib3.connection.VerifiedHTTPSConnection object at 0x00000175F8A75730>, 'Connection to api.telegram.org timed out. (connect timeout=5.0)'))
2021-01-13 21:40:30,413 - __main__ - INFO - Отправка сообщения в телеграм: У вас проверили работу "AnastasiaSar__api_sp1_bot.zip"!

К сожалению в работе нашлись ошибки.
2021-01-13 21:40:35,417 - telegram.vendor.ptb_urllib3.urllib3.connectionpool - WARNING - Retrying (Retry(total=2, connect=None, read=None, redirect=None)) after connection broken by 'ConnectTimeoutError(<telegram.vendor.ptb_urllib3.urllib3.connection.VerifiedHTTPSConnection object at 0x00000175F8A75640>, 'Connection to api.telegram.org timed out. (connect timeout=5.0)')': /bot1433757250:AAEo4RDod8FFHlZw0bnbR_tHqzHWjYUistA/sendMessage
2021-01-13 21:40:40,434 - telegram.vendor.ptb_urllib3.urllib3.connectionpool - WARNING - Retrying (Retry(total=1, connect=None, read=None, redirect=None)) after connection broken by 'ConnectTimeoutError(<telegram.vendor.ptb_urllib3.urllib3.connection.VerifiedHTTPSConnection object at 0x00000175F8A75F10>, 'Connection to api.telegram.org timed out. (connect timeout=5.0)')': /bot1433757250:AAEo4RDod8FFHlZw0bnbR_tHqzHWjYUistA/sendMessage
2021-01-13 21:40:45,444 - telegram.vendor.ptb_urllib3.urllib3.connectionpool - WARNING - Retrying (Retry(total=0, connect=None, read=None, redirect=None)) after connection broken by 'ConnectTimeoutError(<telegram.vendor.ptb_urllib3.urllib3.connection.VerifiedHTTPSConnection object at 0x00000175F8A754F0>, 'Connection to api.telegram.org timed out. (connect timeout=5.0)')': /bot1433757250:AAEo4RDod8FFHlZw0bnbR_tHqzHWjYUistA/sendMessage
2021-01-13 21:40:50,455 - __main__ - ERROR - Бот столкнулся с ошибкой: urllib3 HTTPError HTTPSConnectionPool(host='api.telegram.org', port=443): Max retries exceeded with url: /bot1433757250:AAEo4RDod8FFHlZw0bnbR_tHqzHWjYUistA/sendMessage (Caused by ConnectTimeoutError(<telegram.vendor.ptb_urllib3.urllib3.connection.VerifiedHTTPSConnection object at 0x00000175F8A75400>, 'Connection to api.telegram.org timed out. (connect timeout=5.0)'))
2021-01-13 21:41:00,817 - __main__ - INFO - Отправка сообщения в телеграм: У вас проверили работу "AnastasiaSar__api_sp1_bot.zip"!

К сожалению в работе нашлись ошибки.
2021-01-13 21:41:05,830 - telegram.vendor.ptb_urllib3.urllib3.connectionpool - WARNING - Retrying (Retry(total=2, connect=None, read=None, redirect=None)) after connection broken by 'ConnectTimeoutError(<telegram.vendor.ptb_urllib3.urllib3.connection.VerifiedHTTPSConnection object at 0x00000175F8A2A880>, 'Connection to api.telegram.org timed out. (connect timeout=5.0)')': /bot1433757250:AAEo4RDod8FFHlZw0bnbR_tHqzHWjYUistA/sendMessage
2021-01-13 21:41:10,845 - telegram.vendor.ptb_urllib3.urllib3.connectionpool - WARNING - Retrying (Retry(total=1, connect=None, read=None, redirect=None)) after connection broken by 'ConnectTimeoutError(<telegram.vendor.ptb_urllib3.urllib3.connection.VerifiedHTTPSConnection object at 0x00000175F8A2AF70>, 'Connection to api.telegram.org timed out. (connect timeout=5.0)')': /bot1433757250:AAEo4RDod8FFHlZw0bnbR_tHqzHWjYUistA/sendMessage
2021-01-13 21:41:15,856 - telegram.vendor.ptb_urllib3.urllib3.connectionpool - WARNING - Retrying (Retry(total=0, connect=None, read=None, redirect=None)) after connection broken by 'ConnectTimeoutError(<telegram.vendor.ptb_urllib3.urllib3.connection.VerifiedHTTPSConnection object at 0x00000175F8A2A5E0>, 'Connection to api.telegram.org timed out. (connect timeout=5.0)')': /bot1433757250:AAEo4RDod8FFHlZw0bnbR_tHqzHWjYUistA/sendMessage
2021-01-13 21:41:20,860 - __main__ - ERROR - Бот столкнулся с ошибкой: urllib3 HTTPError HTTPSConnectionPool(host='api.telegram.org', port=443): Max retries exceeded with url: /bot1433757250:AAEo4RDod8FFHlZw0bnbR_tHqzHWjYUistA/sendMessage (Caused by ConnectTimeoutError(<telegram.vendor.ptb_urllib3.urllib3.connection.VerifiedHTTPSConnection object at 0x00000175F8A2A550>, 'Connection to api.telegram.org timed out. (connect timeout=5.0)'))
2021-01-13 21:41:27,363 - __main__ - INFO - Отправка сообщения в телеграм: У вас проверили работу "AnastasiaSar__api_sp1_bot.zip"!

К сожалению в работе нашлись ошибки.
2021-01-13 21:41:32,365 - telegram.vendor.ptb_urllib3.urllib3.connectionpool - WARNING - Retrying (Retry(total=2, connect=None, read=None, redirect=None)) after connection broken by 'ConnectTimeoutError(<telegram.vendor.ptb_urllib3.urllib3.connection.VerifiedHTTPSConnection object at 0x00000175F8A2A8E0>, 'Connection to api.telegram.org timed out. (connect timeout=5.0)')': /bot1433757250:AAEo4RDod8FFHlZw0bnbR_tHqzHWjYUistA/sendMessage
2021-01-13 21:41:37,380 - telegram.vendor.ptb_urllib3.urllib3.connectionpool - WARNING - Retrying (Retry(total=1, connect=None, read=None, redirect=None)) after connection broken by 'ConnectTimeoutError(<telegram.vendor.ptb_urllib3.urllib3.connection.VerifiedHTTPSConnection object at 0x00000175F8A2A370>, 'Connection to api.telegram.org timed out. (connect timeout=5.0)')': /bot1433757250:AAEo4RDod8FFHlZw0bnbR_tHqzHWjYUistA/sendMessage
2021-01-13 21:41:42,390 - telegram.vendor.ptb_urllib3.urllib3.connectionpool - WARNING - Retrying (Retry(total=0, connect=None, read=None, redirect=None)) after connection broken by 'ConnectTimeoutError(<telegram.vendor.ptb_urllib3.urllib3.connection.VerifiedHTTPSConnection object at 0x00000175F8A2A4F0>, 'Connection to api.telegram.org timed out. (connect timeout=5.0)')': /bot1433757250:AAEo4RDod8FFHlZw0bnbR_tHqzHWjYUistA/sendMessage
2021-01-13 21:41:47,391 - __main__ - ERROR - Бот столкнулся с ошибкой: urllib3 HTTPError HTTPSConnectionPool(host='api.telegram.org', port=443): Max retries exceeded with url: /bot1433757250:AAEo4RDod8FFHlZw0bnbR_tHqzHWjYUistA/sendMessage (Caused by ConnectTimeoutError(<telegram.vendor.ptb_urllib3.urllib3.connection.VerifiedHTTPSConnection object at 0x00000175F8A75F70>, 'Connection to api.telegram.org timed out. (connect timeout=5.0)'))
2021-01-13 21:41:55,561 - __main__ - INFO - Отправка сообщения в телеграм: У вас проверили работу "AnastasiaSar__api_sp1_bot.zip"!

К сожалению в работе нашлись ошибки.
2021-01-13 21:42:00,569 - telegram.vendor.ptb_urllib3.urllib3.connectionpool - WARNING - Retrying (Retry(total=2, connect=None, read=None, redirect=None)) after connection broken by 'ConnectTimeoutError(<telegram.vendor.ptb_urllib3.urllib3.connection.VerifiedHTTPSConnection object at 0x00000175F8A75610>, 'Connection to api.telegram.org timed out. (connect timeout=5.0)')': /bot1433757250:AAEo4RDod8FFHlZw0bnbR_tHqzHWjYUistA/sendMessage
2021-01-13 21:42:05,578 - telegram.vendor.ptb_urllib3.urllib3.connectionpool - WARNING - Retrying (Retry(total=1, connect=None, read=None, redirect=None)) after connection broken by 'ConnectTimeoutError(<telegram.vendor.ptb_urllib3.urllib3.connection.VerifiedHTTPSConnection object at 0x00000175F8A75880>, 'Connection to api.telegram.org timed out. (connect timeout=5.0)')': /bot1433757250:AAEo4RDod8FFHlZw0bnbR_tHqzHWjYUistA/sendMessage
2021-01-13 21:42:10,584 - telegram.vendor.ptb_urllib3.urllib3.connectionpool - WARNING - Retrying (Retry(total=0, connect=None, read=None, redirect=None)) after connection broken by 'ConnectTimeoutError(<telegram.vendor.ptb_urllib3.urllib3.connection.VerifiedHTTPSConnection object at 0x00000175F8A75340>, 'Connection to api.telegram.org timed out. (connect timeout=5.0)')': /bot1433757250:AAEo4RDod8FFHlZw0bnbR_tHqzHWjYUistA/sendMessage
2021-01-13 21:42:15,589 - __main__ - ERROR - Бот столкнулся с ошибкой: urllib3 HTTPError HTTPSConnectionPool(host='api.telegram.org', port=443): Max retries exceeded with url: /bot1433757250:AAEo4RDod8FFHlZw0bnbR_tHqzHWjYUistA/sendMessage (Caused by ConnectTimeoutError(<telegram.vendor.ptb_urllib3.urllib3.connection.VerifiedHTTPSConnection object at 0x00000175F8A755E0>, 'Connection to api.telegram.org timed out. (connect timeout=5.0)'))
2021-01-13 21:42:22,833 - __main__ - INFO - Отправка сообщения в телеграм: У вас проверили работу "AnastasiaSar__api_sp1_bot.zip"!

К сожалению в работе нашлись ошибки.
2021-01-13 21:42:27,838 - telegram.vendor.ptb_urllib3.urllib3.connectionpool - WARNING - Retrying (Retry(total=2, connect=None, read=None, redirect=None)) after connection broken by 'ConnectTimeoutError(<telegram.vendor.ptb_urllib3.urllib3.connection.VerifiedHTTPSConnection object at 0x00000175F8A75C70>, 'Connection to api.telegram.org timed out. (connect timeout=5.0)')': /bot1433757250:AAEo4RDod8FFHlZw0bnbR_tHqzHWjYUistA/sendMessage
2021-01-13 21:42:32,844 - telegram.vendor.ptb_urllib3.urllib3.connectionpool - WARNING - Retrying (Retry(total=1, connect=None, read=None, redirect=None)) after connection broken by 'ConnectTimeoutError(<telegram.vendor.ptb_urllib3.urllib3.connection.VerifiedHTTPSConnection object at 0x00000175F8A75070>, 'Connection to api.telegram.org timed out. (connect timeout=5.0)')': /bot1433757250:AAEo4RDod8FFHlZw0bnbR_tHqzHWjYUistA/sendMessage
2021-01-13 21:42:37,856 - telegram.vendor.ptb_urllib3.urllib3.connectionpool - WARNING - Retrying (Retry(total=0, connect=None, read=None, redirect=None)) after connection broken by 'ConnectTimeoutError(<telegram.vendor.ptb_urllib3.urllib3.connection.VerifiedHTTPSConnection object at 0x00000175F8A75D90>, 'Connection to api.telegram.org timed out. (connect timeout=5.0)')': /bot1433757250:AAEo4RDod8FFHlZw0bnbR_tHqzHWjYUistA/sendMessage
2021-01-13 21:42:42,872 - __main__ - ERROR - Бот столкнулся с ошибкой: urllib3 HTTPError HTTPSConnectionPool(host='api.telegram.org', port=443): Max retries exceeded with url: /bot1433757250:AAEo4RDod8FFHlZw0bnbR_tHqzHWjYUistA/sendMessage (Caused by ConnectTimeoutError(<telegram.vendor.ptb_urllib3.urllib3.connection.VerifiedHTTPSConnection object at 0x00000175F8A75850>, 'Connection to api.telegram.org timed out. (connect timeout=5.0)'))
2021-01-13 21:42:51,191 - __main__ - INFO - Отправка сообщения в телеграм: У вас проверили работу "AnastasiaSar__api_sp1_bot.zip"!

К сожалению в работе нашлись ошибки.
2021-01-13 21:42:56,199 - telegram.vendor.ptb_urllib3.urllib3.connectionpool - WARNING - Retrying (Retry(total=2, connect=None, read=None, redirect=None)) after connection broken by 'ConnectTimeoutError(<telegram.vendor.ptb_urllib3.urllib3.connection.VerifiedHTTPSConnection object at 0x00000175F8A2A640>, 'Connection to api.telegram.org timed out. (connect timeout=5.0)')': /bot1433757250:AAEo4RDod8FFHlZw0bnbR_tHqzHWjYUistA/sendMessage
2021-01-13 21:43:01,202 - telegram.vendor.ptb_urllib3.urllib3.connectionpool - WARNING - Retrying (Retry(total=1, connect=None, read=None, redirect=None)) after connection broken by 'ConnectTimeoutError(<telegram.vendor.ptb_urllib3.urllib3.connection.VerifiedHTTPSConnection object at 0x00000175F8A7F0D0>, 'Connection to api.telegram.org timed out. (connect timeout=5.0)')': /bot1433757250:AAEo4RDod8FFHlZw0bnbR_tHqzHWjYUistA/sendMessage
2021-01-13 21:43:06,211 - telegram.vendor.ptb_urllib3.urllib3.connectionpool - WARNING - Retrying (Retry(total=0, connect=None, read=None, redirect=None)) after connection broken by 'ConnectTimeoutError(<telegram.vendor.ptb_urllib3.urllib3.connection.VerifiedHTTPSConnection object at 0x00000175F8A7F160>, 'Connection to api.telegram.org timed out. (connect timeout=5.0)')': /bot1433757250:AAEo4RDod8FFHlZw0bnbR_tHqzHWjYUistA/sendMessage
2021-01-13 21:43:11,222 - __main__ - ERROR - Бот столкнулся с ошибкой: urllib3 HTTPError HTTPSConnectionPool(host='api.telegram.org', port=443): Max retries exceeded with url: /bot1433757250:AAEo4RDod8FFHlZw0bnbR_tHqzHWjYUistA/sendMessage (Caused by ConnectTimeoutError(<telegram.vendor.ptb_urllib3.urllib3.connection.VerifiedHTTPSConnection object at 0x00000175F8A7FA60>, 'Connection to api.telegram.org timed out. (connect timeout=5.0)'))
2021-01-13 21:43:19,713 - __main__ - INFO - Отправка сообщения в телеграм: У вас проверили работу "AnastasiaSar__api_sp1_bot.zip"!

К сожалению в работе нашлись ошибки.
2021-01-13 21:43:24,726 - telegram.vendor.ptb_urllib3.urllib3.connectionpool - WARNING - Retrying (Retry(total=2, connect=None, read=None, redirect=None)) after connection broken by 'ConnectTimeoutError(<telegram.vendor.ptb_urllib3.urllib3.connection.VerifiedHTTPSConnection object at 0x00000175F8A7FA90>, 'Connection to api.telegram.org timed out. (connect timeout=5.0)')': /bot1433757250:AAEo4RDod8FFHlZw0bnbR_tHqzHWjYUistA/sendMessage
2021-01-13 21:43:29,739 - telegram.vendor.ptb_urllib3.urllib3.connectionpool - WARNING - Retrying (Retry(total=1, connect=None, read=None, redirect=None)) after connection broken by 'ConnectTimeoutError(<telegram.vendor.ptb_urllib3.urllib3.connection.VerifiedHTTPSConnection object at 0x00000175F8A7F610>, 'Connection to api.telegram.org timed out. (connect timeout=5.0)')': /bot1433757250:AAEo4RDod8FFHlZw0bnbR_tHqzHWjYUistA/sendMessage
2021-01-13 21:43:34,748 - telegram.vendor.ptb_urllib3.urllib3.connectionpool - WARNING - Retrying (Retry(total=0, connect=None, read=None, redirect=None)) after connection broken by 'ConnectTimeoutError(<telegram.vendor.ptb_urllib3.urllib3.connection.VerifiedHTTPSConnection object at 0x00000175F8A7FC10>, 'Connection to api.telegram.org timed out. (connect timeout=5.0)')': /bot1433757250:AAEo4RDod8FFHlZw0bnbR_tHqzHWjYUistA/sendMessage
2021-01-13 21:43:39,755 - __main__ - ERROR - Бот столкнулся с ошибкой: urllib3 HTTPError HTTPSConnectionPool(host='api.telegram.org', port=443): Max retries exceeded with url: /bot1433757250:AAEo4RDod8FFHlZw0bnbR_tHqzHWjYUistA/sendMessage (Caused by ConnectTimeoutError(<telegram.vendor.ptb_urllib3.urllib3.connection.VerifiedHTTPSConnection object at 0x00000175F8A75A30>, 'Connection to api.telegram.org timed out. (connect timeout=5.0)'))
2021-01-13 21:43:46,601 - __main__ - INFO - Отправка сообщения в телеграм: У вас проверили работу "AnastasiaSar__api_sp1_bot.zip"!

К сожалению в работе нашлись ошибки.
2021-01-13 21:43:51,617 - telegram.vendor.ptb_urllib3.urllib3.connectionpool - WARNING - Retrying (Retry(total=2, connect=None, read=None, redirect=None)) after connection broken by 'ConnectTimeoutError(<telegram.vendor.ptb_urllib3.urllib3.connection.VerifiedHTTPSConnection object at 0x00000175F8A75160>, 'Connection to api.telegram.org timed out. (connect timeout=5.0)')': /bot1433757250:AAEo4RDod8FFHlZw0bnbR_tHqzHWjYUistA/sendMessage
2021-01-13 21:43:56,631 - telegram.vendor.ptb_urllib3.urllib3.connectionpool - WARNING - Retrying (Retry(total=1, connect=None, read=None, redirect=None)) after connection broken by 'ConnectTimeoutError(<telegram.vendor.ptb_urllib3.urllib3.connection.VerifiedHTTPSConnection object at 0x00000175F8A759D0>, 'Connection to api.telegram.org timed out. (connect timeout=5.0)')': /bot1433757250:AAEo4RDod8FFHlZw0bnbR_tHqzHWjYUistA/sendMessage
2021-01-13 21:44:01,641 - telegram.vendor.ptb_urllib3.urllib3.connectionpool - WARNING - Retrying (Retry(total=0, connect=None, read=None, redirect=None)) after connection broken by 'ConnectTimeoutError(<telegram.vendor.ptb_urllib3.urllib3.connection.VerifiedHTTPSConnection object at 0x00000175F8A75340>, 'Connection to api.telegram.org timed out. (connect timeout=5.0)')': /bot1433757250:AAEo4RDod8FFHlZw0bnbR_tHqzHWjYUistA/sendMessage
2021-01-13 21:44:06,650 - __main__ - ERROR - Бот столкнулся с ошибкой: urllib3 HTTPError HTTPSConnectionPool(host='api.telegram.org', port=443): Max retries exceeded with url: /bot1433757250:AAEo4RDod8FFHlZw0bnbR_tHqzHWjYUistA/sendMessage (Caused by ConnectTimeoutError(<telegram.vendor.ptb_urllib3.urllib3.connection.VerifiedHTTPSConnection object at 0x00000175F8A75700>, 'Connection to api.telegram.org timed out. (connect timeout=5.0)'))
2021-01-13 21:44:12,845 - __main__ - INFO - Отправка сообщения в телеграм: У вас проверили работу "AnastasiaSar__api_sp1_bot.zip"!

К сожалению в работе нашлись ошибки.
2021-01-13 21:44:17,847 - telegram.vendor.ptb_urllib3.urllib3.connectionpool - WARNING - Retrying (Retry(total=2, connect=None, read=None, redirect=None)) after connection broken by 'ConnectTimeoutError(<telegram.vendor.ptb_urllib3.urllib3.connection.VerifiedHTTPSConnection object at 0x00000175F8A75070>, 'Connection to api.telegram.org timed out. (connect timeout=5.0)')': /bot1433757250:AAEo4RDod8FFHlZw0bnbR_tHqzHWjYUistA/sendMessage
2021-01-13 21:44:22,858 - telegram.vendor.ptb_urllib3.urllib3.connectionpool - WARNING - Retrying (Retry(total=1, connect=None, read=None, redirect=None)) after connection broken by 'ConnectTimeoutError(<telegram.vendor.ptb_urllib3.urllib3.connection.VerifiedHTTPSConnection object at 0x00000175F8A75C70>, 'Connection to api.telegram.org timed out. (connect timeout=5.0)')': /bot1433757250:AAEo4RDod8FFHlZw0bnbR_tHqzHWjYUistA/sendMessage
2021-01-13 21:44:27,860 - telegram.vendor.ptb_urllib3.urllib3.connectionpool - WARNING - Retrying (Retry(total=0, connect=None, read=None, redirect=None)) after connection broken by 'ConnectTimeoutError(<telegram.vendor.ptb_urllib3.urllib3.connection.VerifiedHTTPSConnection object at 0x00000175F8A75520>, 'Connection to api.telegram.org timed out. (connect timeout=5.0)')': /bot1433757250:AAEo4RDod8FFHlZw0bnbR_tHqzHWjYUistA/sendMessage
2021-01-13 21:44:32,868 - __main__ - ERROR - Бот столкнулся с ошибкой: urllib3 HTTPError HTTPSConnectionPool(host='api.telegram.org', port=443): Max retries exceeded with url: /bot1433757250:AAEo4RDod8FFHlZw0bnbR_tHqzHWjYUistA/sendMessage (Caused by ConnectTimeoutError(<telegram.vendor.ptb_urllib3.urllib3.connection.VerifiedHTTPSConnection object at 0x00000175F8A75D90>, 'Connection to api.telegram.org timed out. (connect timeout=5.0)'))
2021-01-13 21:44:42,953 - __main__ - INFO - Отправка сообщения в телеграм: У вас проверили работу "AnastasiaSar__api_sp1_bot.zip"!

К сожалению в работе нашлись ошибки.
2021-01-13 21:44:47,968 - telegram.vendor.ptb_urllib3.urllib3.connectionpool - WARNING - Retrying (Retry(total=2, connect=None, read=None, redirect=None)) after connection broken by 'ConnectTimeoutError(<telegram.vendor.ptb_urllib3.urllib3.connection.VerifiedHTTPSConnection object at 0x00000175F8A75190>, 'Connection to api.telegram.org timed out. (connect timeout=5.0)')': /bot1433757250:AAEo4RDod8FFHlZw0bnbR_tHqzHWjYUistA/sendMessage
2021-01-13 21:44:52,970 - telegram.vendor.ptb_urllib3.urllib3.connectionpool - WARNING - Retrying (Retry(total=1, connect=None, read=None, redirect=None)) after connection broken by 'ConnectTimeoutError(<telegram.vendor.ptb_urllib3.urllib3.connection.VerifiedHTTPSConnection object at 0x00000175F8A2A3A0>, 'Connection to api.telegram.org timed out. (connect timeout=5.0)')': /bot1433757250:AAEo4RDod8FFHlZw0bnbR_tHqzHWjYUistA/sendMessage
2021-01-13 21:44:57,983 - telegram.vendor.ptb_urllib3.urllib3.connectionpool - WARNING - Retrying (Retry(total=0, connect=None, read=None, redirect=None)) after connection broken by 'ConnectTimeoutError(<telegram.vendor.ptb_urllib3.urllib3.connection.VerifiedHTTPSConnection object at 0x00000175F8A2A850>, 'Connection to api.telegram.org timed out. (connect timeout=5.0)')': /bot1433757250:AAEo4RDod8FFHlZw0bnbR_tHqzHWjYUistA/sendMessage
2021-01-13 21:45:02,991 - __main__ - ERROR - Бот столкнулся с ошибкой: urllib3 HTTPError HTTPSConnectionPool(host='api.telegram.org', port=443): Max retries exceeded with url: /bot1433757250:AAEo4RDod8FFHlZw0bnbR_tHqzHWjYUistA/sendMessage (Caused by ConnectTimeoutError(<telegram.vendor.ptb_urllib3.urllib3.connection.VerifiedHTTPSConnection object at 0x00000175F8A2A250>, 'Connection to api.telegram.org timed out. (connect timeout=5.0)'))
2021-01-13 22:06:46,329 - __main__ - DEBUG - Запуск бота
2021-01-13 22:06:48,588 - __main__ - INFO - Отправка сообщения в телеграм: У вас проверили работу "AnastasiaSar__api_sp1_bot.zip"!

К сожалению в работе нашлись ошибки.
2021-01-13 22:06:53,605 - telegram.vendor.ptb_urllib3.urllib3.connectionpool - WARNING - Retrying (Retry(total=2, connect=None, read=None, redirect=None)) after connection broken by 'ConnectTimeoutError(<telegram.vendor.ptb_urllib3.urllib3.connection.VerifiedHTTPSConnection object at 0x000002076AABD730>, 'Connection to api.telegram.org timed out. (connect timeout=5.0)')': /bot1433757250:AAEo4RDod8FFHlZw0bnbR_tHqzHWjYUistA/sendMessage
2021-01-13 22:06:58,617 - telegram.vendor.ptb_urllib3.urllib3.connectionpool - WARNING - Retrying (Retry(total=1, connect=None, read=None, redirect=None)) after connection broken by 'ConnectTimeoutError(<telegram.vendor.ptb_urllib3.urllib3.connection.VerifiedHTTPSConnection object at 0x000002076AABDEE0>, 'Connection to api.telegram.org timed out. (connect timeout=5.0)')': /bot1433757250:AAEo4RDod8FFHlZw0bnbR_tHqzHWjYUistA/sendMessage
2021-01-13 22:07:03,634 - telegram.vendor.ptb_urllib3.urllib3.connectionpool - WARNING - Retrying (Retry(total=0, connect=None, read=None, redirect=None)) after connection broken by 'ConnectTimeoutError(<telegram.vendor.ptb_urllib3.urllib3.connection.VerifiedHTTPSConnection object at 0x000002076AABDD90>, 'Connection to api.telegram.org timed out. (connect timeout=5.0)')': /bot1433757250:AAEo4RDod8FFHlZw0bnbR_tHqzHWjYUistA/sendMessage
2021-01-13 22:07:08,637 - __main__ - ERROR - Бот столкнулся с ошибкой: urllib3 HTTPError HTTPSConnectionPool(host='api.telegram.org', port=443): Max retries exceeded with url: /bot1433757250:AAEo4RDod8FFHlZw0bnbR_tHqzHWjYUistA/sendMessage (Caused by ConnectTimeoutError(<telegram.vendor.ptb_urllib3.urllib3.connection.VerifiedHTTPSConnection object at 0x000002076AABD3D0>, 'Connection to api.telegram.org timed out. (connect timeout=5.0)'))
2021-01-13 22:07:16,969 - __main__ - INFO - Отправка сообщения в телеграм: У вас проверили работу "AnastasiaSar__api_sp1_bot.zip"!

К сожалению в работе нашлись ошибки.
2021-01-13 22:07:21,985 - telegram.vendor.ptb_urllib3.urllib3.connectionpool - WARNING - Retrying (Retry(total=2, connect=None, read=None, redirect=None)) after connection broken by 'ConnectTimeoutError(<telegram.vendor.ptb_urllib3.urllib3.connection.VerifiedHTTPSConnection object at 0x000002076AABD880>, 'Connection to api.telegram.org timed out. (connect timeout=5.0)')': /bot1433757250:AAEo4RDod8FFHlZw0bnbR_tHqzHWjYUistA/sendMessage
2021-01-13 22:07:26,997 - telegram.vendor.ptb_urllib3.urllib3.connectionpool - WARNING - Retrying (Retry(total=1, connect=None, read=None, redirect=None)) after connection broken by 'ConnectTimeoutError(<telegram.vendor.ptb_urllib3.urllib3.connection.VerifiedHTTPSConnection object at 0x000002076AABD8E0>, 'Connection to api.telegram.org timed out. (connect timeout=5.0)')': /bot1433757250:AAEo4RDod8FFHlZw0bnbR_tHqzHWjYUistA/sendMessage
2021-01-13 22:07:32,012 - telegram.vendor.ptb_urllib3.urllib3.connectionpool - WARNING - Retrying (Retry(total=0, connect=None, read=None, redirect=None)) after connection broken by 'ConnectTimeoutError(<telegram.vendor.ptb_urllib3.urllib3.connection.VerifiedHTTPSConnection object at 0x000002076AABD610>, 'Connection to api.telegram.org timed out. (connect timeout=5.0)')': /bot1433757250:AAEo4RDod8FFHlZw0bnbR_tHqzHWjYUistA/sendMessage
2021-01-13 22:07:37,025 - __main__ - ERROR - Бот столкнулся с ошибкой: urllib3 HTTPError HTTPSConnectionPool(host='api.telegram.org', port=443): Max retries exceeded with url: /bot1433757250:AAEo4RDod8FFHlZw0bnbR_tHqzHWjYUistA/sendMessage (Caused by ConnectTimeoutError(<telegram.vendor.ptb_urllib3.urllib3.connection.VerifiedHTTPSConnection object at 0x000002076AABD6A0>, 'Connection to api.telegram.org timed out. (connect timeout=5.0)'))
2021-01-13 22:07:44,328 - __main__ - INFO - Отправка сообщения в телеграм: У вас проверили работу "AnastasiaSar__api_sp1_bot.zip"!

К сожалению в работе нашлись ошибки.
2021-01-13 22:07:49,336 - telegram.vendor.ptb_urllib3.urllib3.connectionpool - WARNING - Retrying (Retry(total=2, connect=None, read=None, redirect=None)) after connection broken by 'ConnectTimeoutError(<telegram.vendor.ptb_urllib3.urllib3.connection.VerifiedHTTPSConnection object at 0x000002076AABD880>, 'Connection to api.telegram.org timed out. (connect timeout=5.0)')': /bot1433757250:AAEo4RDod8FFHlZw0bnbR_tHqzHWjYUistA/sendMessage
2021-01-13 22:07:54,349 - telegram.vendor.ptb_urllib3.urllib3.connectionpool - WARNING - Retrying (Retry(total=1, connect=None, read=None, redirect=None)) after connection broken by 'ConnectTimeoutError(<telegram.vendor.ptb_urllib3.urllib3.connection.VerifiedHTTPSConnection object at 0x000002076AABD670>, 'Connection to api.telegram.org timed out. (connect timeout=5.0)')': /bot1433757250:AAEo4RDod8FFHlZw0bnbR_tHqzHWjYUistA/sendMessage
2021-01-13 22:07:59,362 - telegram.vendor.ptb_urllib3.urllib3.connectionpool - WARNING - Retrying (Retry(total=0, connect=None, read=None, redirect=None)) after connection broken by 'ConnectTimeoutError(<telegram.vendor.ptb_urllib3.urllib3.connection.VerifiedHTTPSConnection object at 0x000002076AABDEB0>, 'Connection to api.telegram.org timed out. (connect timeout=5.0)')': /bot1433757250:AAEo4RDod8FFHlZw0bnbR_tHqzHWjYUistA/sendMessage
2021-01-13 22:08:04,371 - __main__ - ERROR - Бот столкнулся с ошибкой: urllib3 HTTPError HTTPSConnectionPool(host='api.telegram.org', port=443): Max retries exceeded with url: /bot1433757250:AAEo4RDod8FFHlZw0bnbR_tHqzHWjYUistA/sendMessage (Caused by ConnectTimeoutError(<telegram.vendor.ptb_urllib3.urllib3.connection.VerifiedHTTPSConnection object at 0x000002076AABD430>, 'Connection to api.telegram.org timed out. (connect timeout=5.0)'))
2021-01-13 22:08:13,538 - __main__ - INFO - Отправка сообщения в телеграм: У вас проверили работу "AnastasiaSar__api_sp1_bot.zip"!

К сожалению в работе нашлись ошибки.
2021-01-13 22:08:18,546 - telegram.vendor.ptb_urllib3.urllib3.connectionpool - WARNING - Retrying (Retry(total=2, connect=None, read=None, redirect=None)) after connection broken by 'ConnectTimeoutError(<telegram.vendor.ptb_urllib3.urllib3.connection.VerifiedHTTPSConnection object at 0x000002076AABD2E0>, 'Connection to api.telegram.org timed out. (connect timeout=5.0)')': /bot1433757250:AAEo4RDod8FFHlZw0bnbR_tHqzHWjYUistA/sendMessage
2021-01-13 22:08:23,553 - telegram.vendor.ptb_urllib3.urllib3.connectionpool - WARNING - Retrying (Retry(total=1, connect=None, read=None, redirect=None)) after connection broken by 'ConnectTimeoutError(<telegram.vendor.ptb_urllib3.urllib3.connection.VerifiedHTTPSConnection object at 0x000002076AABDD90>, 'Connection to api.telegram.org timed out. (connect timeout=5.0)')': /bot1433757250:AAEo4RDod8FFHlZw0bnbR_tHqzHWjYUistA/sendMessage
2021-01-13 22:08:28,555 - telegram.vendor.ptb_urllib3.urllib3.connectionpool - WARNING - Retrying (Retry(total=0, connect=None, read=None, redirect=None)) after connection broken by 'ConnectTimeoutError(<telegram.vendor.ptb_urllib3.urllib3.connection.VerifiedHTTPSConnection object at 0x000002076AABD100>, 'Connection to api.telegram.org timed out. (connect timeout=5.0)')': /bot1433757250:AAEo4RDod8FFHlZw0bnbR_tHqzHWjYUistA/sendMessage
2021-01-13 22:08:31,654 - __main__ - DEBUG - Запуск бота
2021-01-13 22:08:39,009 - __main__ - INFO - Отправка сообщения в телеграм: У вас проверили работу "AnastasiaSar__api_sp1_bot.zip"!

К сожалению в работе нашлись ошибки.
2021-01-13 22:08:44,018 - telegram.vendor.ptb_urllib3.urllib3.connectionpool - WARNING - Retrying (Retry(total=2, connect=None, read=None, redirect=None)) after connection broken by 'ConnectTimeoutError(<telegram.vendor.ptb_urllib3.urllib3.connection.VerifiedHTTPSConnection object at 0x0000017E3E8DD730>, 'Connection to api.telegram.org timed out. (connect timeout=5.0)')': /bot1433757250:AAEo4RDod8FFHlZw0bnbR_tHqzHWjYUistA/sendMessage
2021-01-13 22:08:49,032 - telegram.vendor.ptb_urllib3.urllib3.connectionpool - WARNING - Retrying (Retry(total=1, connect=None, read=None, redirect=None)) after connection broken by 'ConnectTimeoutError(<telegram.vendor.ptb_urllib3.urllib3.connection.VerifiedHTTPSConnection object at 0x0000017E3E8DDEE0>, 'Connection to api.telegram.org timed out. (connect timeout=5.0)')': /bot1433757250:AAEo4RDod8FFHlZw0bnbR_tHqzHWjYUistA/sendMessage
2021-01-13 22:08:54,037 - telegram.vendor.ptb_urllib3.urllib3.connectionpool - WARNING - Retrying (Retry(total=0, connect=None, read=None, redirect=None)) after connection broken by 'ConnectTimeoutError(<telegram.vendor.ptb_urllib3.urllib3.connection.VerifiedHTTPSConnection object at 0x0000017E3E8DDD90>, 'Connection to api.telegram.org timed out. (connect timeout=5.0)')': /bot1433757250:AAEo4RDod8FFHlZw0bnbR_tHqzHWjYUistA/sendMessage
2021-01-13 22:08:59,040 - __main__ - ERROR - Бот столкнулся с ошибкой: urllib3 HTTPError HTTPSConnectionPool(host='api.telegram.org', port=443): Max retries exceeded with url: /bot1433757250:AAEo4RDod8FFHlZw0bnbR_tHqzHWjYUistA/sendMessage (Caused by ConnectTimeoutError(<telegram.vendor.ptb_urllib3.urllib3.connection.VerifiedHTTPSConnection object at 0x0000017E3E8DD3D0>, 'Connection to api.telegram.org timed out. (connect timeout=5.0)'))
2021-01-13 22:09:11,564 - __main__ - INFO - Отправка сообщения в телеграм: У вас проверили работу "AnastasiaSar__api_sp1_bot.zip"!

К сожалению в работе нашлись ошибки.
2021-01-13 22:09:16,574 - telegram.vendor.ptb_urllib3.urllib3.connectionpool - WARNING - Retrying (Retry(total=2, connect=None, read=None, redirect=None)) after connection broken by 'ConnectTimeoutError(<telegram.vendor.ptb_urllib3.urllib3.connection.VerifiedHTTPSConnection object at 0x0000017E3E8DD880>, 'Connection to api.telegram.org timed out. (connect timeout=5.0)')': /bot1433757250:AAEo4RDod8FFHlZw0bnbR_tHqzHWjYUistA/sendMessage
2021-01-13 22:09:21,584 - telegram.vendor.ptb_urllib3.urllib3.connectionpool - WARNING - Retrying (Retry(total=1, connect=None, read=None, redirect=None)) after connection broken by 'ConnectTimeoutError(<telegram.vendor.ptb_urllib3.urllib3.connection.VerifiedHTTPSConnection object at 0x0000017E3E8DD8E0>, 'Connection to api.telegram.org timed out. (connect timeout=5.0)')': /bot1433757250:AAEo4RDod8FFHlZw0bnbR_tHqzHWjYUistA/sendMessage
2021-01-13 22:09:26,589 - telegram.vendor.ptb_urllib3.urllib3.connectionpool - WARNING - Retrying (Retry(total=0, connect=None, read=None, redirect=None)) after connection broken by 'ConnectTimeoutError(<telegram.vendor.ptb_urllib3.urllib3.connection.VerifiedHTTPSConnection object at 0x0000017E3E8DD610>, 'Connection to api.telegram.org timed out. (connect timeout=5.0)')': /bot1433757250:AAEo4RDod8FFHlZw0bnbR_tHqzHWjYUistA/sendMessage
2021-01-13 22:09:31,595 - __main__ - ERROR - Бот столкнулся с ошибкой: urllib3 HTTPError HTTPSConnectionPool(host='api.telegram.org', port=443): Max retries exceeded with url: /bot1433757250:AAEo4RDod8FFHlZw0bnbR_tHqzHWjYUistA/sendMessage (Caused by ConnectTimeoutError(<telegram.vendor.ptb_urllib3.urllib3.connection.VerifiedHTTPSConnection object at 0x0000017E3E8DD6A0>, 'Connection to api.telegram.org timed out. (connect timeout=5.0)'))
2021-01-13 22:09:39,456 - __main__ - INFO - Отправка сообщения в телеграм: У вас проверили работу "AnastasiaSar__api_sp1_bot.zip"!

К сожалению в работе нашлись ошибки.
2021-01-13 22:09:44,463 - telegram.vendor.ptb_urllib3.urllib3.connectionpool - WARNING - Retrying (Retry(total=2, connect=None, read=None, redirect=None)) after connection broken by 'ConnectTimeoutError(<telegram.vendor.ptb_urllib3.urllib3.connection.VerifiedHTTPSConnection object at 0x0000017E3E8DD880>, 'Connection to api.telegram.org timed out. (connect timeout=5.0)')': /bot1433757250:AAEo4RDod8FFHlZw0bnbR_tHqzHWjYUistA/sendMessage
2021-01-13 22:09:49,467 - telegram.vendor.ptb_urllib3.urllib3.connectionpool - WARNING - Retrying (Retry(total=1, connect=None, read=None, redirect=None)) after connection broken by 'ConnectTimeoutError(<telegram.vendor.ptb_urllib3.urllib3.connection.VerifiedHTTPSConnection object at 0x0000017E3E8DD670>, 'Connection to api.telegram.org timed out. (connect timeout=5.0)')': /bot1433757250:AAEo4RDod8FFHlZw0bnbR_tHqzHWjYUistA/sendMessage
2021-01-13 22:09:54,476 - telegram.vendor.ptb_urllib3.urllib3.connectionpool - WARNING - Retrying (Retry(total=0, connect=None, read=None, redirect=None)) after connection broken by 'ConnectTimeoutError(<telegram.vendor.ptb_urllib3.urllib3.connection.VerifiedHTTPSConnection object at 0x0000017E3E8DDEB0>, 'Connection to api.telegram.org timed out. (connect timeout=5.0)')': /bot1433757250:AAEo4RDod8FFHlZw0bnbR_tHqzHWjYUistA/sendMessage
2021-01-13 22:09:59,487 - __main__ - ERROR - Бот столкнулся с ошибкой: urllib3 HTTPError HTTPSConnectionPool(host='api.telegram.org', port=443): Max retries exceeded with url: /bot1433757250:AAEo4RDod8FFHlZw0bnbR_tHqzHWjYUistA/sendMessage (Caused by ConnectTimeoutError(<telegram.vendor.ptb_urllib3.urllib3.connection.VerifiedHTTPSConnection object at 0x0000017E3E8DD430>, 'Connection to api.telegram.org timed out. (connect timeout=5.0)'))
2021-01-14 02:44:25,193 - __main__ - DEBUG - Запуск бота
2021-01-14 02:44:26,442 - __main__ - INFO - Отправка сообщения в телеграм: У вас проверили работу "AnastasiaSar__api_sp1_bot.zip"!

К сожалению в работе нашлись ошибки.
2021-01-14 02:44:31,459 - telegram.vendor.ptb_urllib3.urllib3.connectionpool - WARNING - Retrying (Retry(total=2, connect=None, read=None, redirect=None)) after connection broken by 'ConnectTimeoutError(<telegram.vendor.ptb_urllib3.urllib3.connection.VerifiedHTTPSConnection object at 0x00000220F7E7D730>, 'Connection to api.telegram.org timed out. (connect timeout=5.0)')': /bot1433757250:AAEo4RDod8FFHlZw0bnbR_tHqzHWjYUistA/sendMessage
2021-01-14 02:44:36,463 - telegram.vendor.ptb_urllib3.urllib3.connectionpool - WARNING - Retrying (Retry(total=1, connect=None, read=None, redirect=None)) after connection broken by 'ConnectTimeoutError(<telegram.vendor.ptb_urllib3.urllib3.connection.VerifiedHTTPSConnection object at 0x00000220F7E7DEE0>, 'Connection to api.telegram.org timed out. (connect timeout=5.0)')': /bot1433757250:AAEo4RDod8FFHlZw0bnbR_tHqzHWjYUistA/sendMessage
2021-01-14 02:44:41,467 - telegram.vendor.ptb_urllib3.urllib3.connectionpool - WARNING - Retrying (Retry(total=0, connect=None, read=None, redirect=None)) after connection broken by 'ConnectTimeoutError(<telegram.vendor.ptb_urllib3.urllib3.connection.VerifiedHTTPSConnection object at 0x00000220F7E7DD90>, 'Connection to api.telegram.org timed out. (connect timeout=5.0)')': /bot1433757250:AAEo4RDod8FFHlZw0bnbR_tHqzHWjYUistA/sendMessage
2021-01-14 02:44:46,477 - __main__ - ERROR - Бот столкнулся с ошибкой: urllib3 HTTPError HTTPSConnectionPool(host='api.telegram.org', port=443): Max retries exceeded with url: /bot1433757250:AAEo4RDod8FFHlZw0bnbR_tHqzHWjYUistA/sendMessage (Caused by ConnectTimeoutError(<telegram.vendor.ptb_urllib3.urllib3.connection.VerifiedHTTPSConnection object at 0x00000220F7E7D3D0>, 'Connection to api.telegram.org timed out. (connect timeout=5.0)'))
2021-01-14 02:44:49,620 - __main__ - DEBUG - Запуск бота
2021-01-14 02:44:50,898 - __main__ - INFO - Отправка сообщения в телеграм: У вас проверили работу "AnastasiaSar__api_sp1_bot.zip"!

К сожалению в работе нашлись ошибки.
2021-01-14 02:44:54,119 - __main__ - DEBUG - Запуск бота
2021-01-14 02:44:55,394 - __main__ - INFO - Отправка сообщения в телеграм: У вас проверили работу "AnastasiaSar__api_sp1_bot.zip"!

К сожалению в работе нашлись ошибки.
2021-01-14 02:45:00,410 - telegram.vendor.ptb_urllib3.urllib3.connectionpool - WARNING - Retrying (Retry(total=2, connect=None, read=None, redirect=None)) after connection broken by 'ConnectTimeoutError(<telegram.vendor.ptb_urllib3.urllib3.connection.VerifiedHTTPSConnection object at 0x000001647B60D730>, 'Connection to api.telegram.org timed out. (connect timeout=5.0)')': /bot1433757250:AAEo4RDod8FFHlZw0bnbR_tHqzHWjYUistA/sendMessage
2021-01-14 02:45:05,571 - telegram.vendor.ptb_urllib3.urllib3.connectionpool - WARNING - Retrying (Retry(total=1, connect=None, read=None, redirect=None)) after connection broken by 'ConnectTimeoutError(<telegram.vendor.ptb_urllib3.urllib3.connection.VerifiedHTTPSConnection object at 0x000001647B60DEE0>, 'Connection to api.telegram.org timed out. (connect timeout=5.0)')': /bot1433757250:AAEo4RDod8FFHlZw0bnbR_tHqzHWjYUistA/sendMessage
2021-01-14 02:45:10,584 - telegram.vendor.ptb_urllib3.urllib3.connectionpool - WARNING - Retrying (Retry(total=0, connect=None, read=None, redirect=None)) after connection broken by 'ConnectTimeoutError(<telegram.vendor.ptb_urllib3.urllib3.connection.VerifiedHTTPSConnection object at 0x000001647B60DD90>, 'Connection to api.telegram.org timed out. (connect timeout=5.0)')': /bot1433757250:AAEo4RDod8FFHlZw0bnbR_tHqzHWjYUistA/sendMessage
2021-01-14 02:45:15,589 - __main__ - ERROR - Бот столкнулся с ошибкой: urllib3 HTTPError HTTPSConnectionPool(host='api.telegram.org', port=443): Max retries exceeded with url: /bot1433757250:AAEo4RDod8FFHlZw0bnbR_tHqzHWjYUistA/sendMessage (Caused by ConnectTimeoutError(<telegram.vendor.ptb_urllib3.urllib3.connection.VerifiedHTTPSConnection object at 0x000001647B60D3D0>, 'Connection to api.telegram.org timed out. (connect timeout=5.0)'))
2021-01-14 02:45:22,450 - __main__ - INFO - Отправка сообщения в телеграм: У вас проверили работу "AnastasiaSar__api_sp1_bot.zip"!

К сожалению в работе нашлись ошибки.
2021-01-14 02:45:27,455 - telegram.vendor.ptb_urllib3.urllib3.connectionpool - WARNING - Retrying (Retry(total=2, connect=None, read=None, redirect=None)) after connection broken by 'ConnectTimeoutError(<telegram.vendor.ptb_urllib3.urllib3.connection.VerifiedHTTPSConnection object at 0x000001647B60D880>, 'Connection to api.telegram.org timed out. (connect timeout=5.0)')': /bot1433757250:AAEo4RDod8FFHlZw0bnbR_tHqzHWjYUistA/sendMessage
2021-01-14 02:45:32,468 - telegram.vendor.ptb_urllib3.urllib3.connectionpool - WARNING - Retrying (Retry(total=1, connect=None, read=None, redirect=None)) after connection broken by 'ConnectTimeoutError(<telegram.vendor.ptb_urllib3.urllib3.connection.VerifiedHTTPSConnection object at 0x000001647B60D8E0>, 'Connection to api.telegram.org timed out. (connect timeout=5.0)')': /bot1433757250:AAEo4RDod8FFHlZw0bnbR_tHqzHWjYUistA/sendMessage
2021-01-14 02:45:37,492 - telegram.vendor.ptb_urllib3.urllib3.connectionpool - WARNING - Retrying (Retry(total=0, connect=None, read=None, redirect=None)) after connection broken by 'ConnectTimeoutError(<telegram.vendor.ptb_urllib3.urllib3.connection.VerifiedHTTPSConnection object at 0x000001647B60D610>, 'Connection to api.telegram.org timed out. (connect timeout=5.0)')': /bot1433757250:AAEo4RDod8FFHlZw0bnbR_tHqzHWjYUistA/sendMessage
2021-01-14 02:45:42,503 - __main__ - ERROR - Бот столкнулся с ошибкой: urllib3 HTTPError HTTPSConnectionPool(host='api.telegram.org', port=443): Max retries exceeded with url: /bot1433757250:AAEo4RDod8FFHlZw0bnbR_tHqzHWjYUistA/sendMessage (Caused by ConnectTimeoutError(<telegram.vendor.ptb_urllib3.urllib3.connection.VerifiedHTTPSConnection object at 0x000001647B60D6A0>, 'Connection to api.telegram.org timed out. (connect timeout=5.0)'))
2021-01-14 02:45:48,727 - __main__ - INFO - Отправка сообщения в телеграм: У вас проверили работу "AnastasiaSar__api_sp1_bot.zip"!

К сожалению в работе нашлись ошибки.
2021-01-14 02:45:53,739 - telegram.vendor.ptb_urllib3.urllib3.connectionpool - WARNING - Retrying (Retry(total=2, connect=None, read=None, redirect=None)) after connection broken by 'ConnectTimeoutError(<telegram.vendor.ptb_urllib3.urllib3.connection.VerifiedHTTPSConnection object at 0x000001647B60D880>, 'Connection to api.telegram.org timed out. (connect timeout=5.0)')': /bot1433757250:AAEo4RDod8FFHlZw0bnbR_tHqzHWjYUistA/sendMessage
2021-01-14 02:45:58,748 - telegram.vendor.ptb_urllib3.urllib3.connectionpool - WARNING - Retrying (Retry(total=1, connect=None, read=None, redirect=None)) after connection broken by 'ConnectTimeoutError(<telegram.vendor.ptb_urllib3.urllib3.connection.VerifiedHTTPSConnection object at 0x000001647B60D670>, 'Connection to api.telegram.org timed out. (connect timeout=5.0)')': /bot1433757250:AAEo4RDod8FFHlZw0bnbR_tHqzHWjYUistA/sendMessage
2021-01-14 02:46:03,760 - telegram.vendor.ptb_urllib3.urllib3.connectionpool - WARNING - Retrying (Retry(total=0, connect=None, read=None, redirect=None)) after connection broken by 'ConnectTimeoutError(<telegram.vendor.ptb_urllib3.urllib3.connection.VerifiedHTTPSConnection object at 0x000001647B60DEB0>, 'Connection to api.telegram.org timed out. (connect timeout=5.0)')': /bot1433757250:AAEo4RDod8FFHlZw0bnbR_tHqzHWjYUistA/sendMessage
2021-01-14 02:46:08,769 - __main__ - ERROR - Бот столкнулся с ошибкой: urllib3 HTTPError HTTPSConnectionPool(host='api.telegram.org', port=443): Max retries exceeded with url: /bot1433757250:AAEo4RDod8FFHlZw0bnbR_tHqzHWjYUistA/sendMessage (Caused by ConnectTimeoutError(<telegram.vendor.ptb_urllib3.urllib3.connection.VerifiedHTTPSConnection object at 0x000001647B60D430>, 'Connection to api.telegram.org timed out. (connect timeout=5.0)'))
2021-01-14 02:46:15,083 - __main__ - INFO - Отправка сообщения в телеграм: У вас проверили работу "AnastasiaSar__api_sp1_bot.zip"!

К сожалению в работе нашлись ошибки.
2021-01-14 02:46:20,089 - telegram.vendor.ptb_urllib3.urllib3.connectionpool - WARNING - Retrying (Retry(total=2, connect=None, read=None, redirect=None)) after connection broken by 'ConnectTimeoutError(<telegram.vendor.ptb_urllib3.urllib3.connection.VerifiedHTTPSConnection object at 0x000001647B60D2E0>, 'Connection to api.telegram.org timed out. (connect timeout=5.0)')': /bot1433757250:AAEo4RDod8FFHlZw0bnbR_tHqzHWjYUistA/sendMessage
2021-01-14 02:46:25,101 - telegram.vendor.ptb_urllib3.urllib3.connectionpool - WARNING - Retrying (Retry(total=1, connect=None, read=None, redirect=None)) after connection broken by 'ConnectTimeoutError(<telegram.vendor.ptb_urllib3.urllib3.connection.VerifiedHTTPSConnection object at 0x000001647B60DD90>, 'Connection to api.telegram.org timed out. (connect timeout=5.0)')': /bot1433757250:AAEo4RDod8FFHlZw0bnbR_tHqzHWjYUistA/sendMessage
2021-01-14 02:46:30,117 - telegram.vendor.ptb_urllib3.urllib3.connectionpool - WARNING - Retrying (Retry(total=0, connect=None, read=None, redirect=None)) after connection broken by 'ConnectTimeoutError(<telegram.vendor.ptb_urllib3.urllib3.connection.VerifiedHTTPSConnection object at 0x000001647B60D100>, 'Connection to api.telegram.org timed out. (connect timeout=5.0)')': /bot1433757250:AAEo4RDod8FFHlZw0bnbR_tHqzHWjYUistA/sendMessage
2021-01-14 02:46:35,126 - __main__ - ERROR - Бот столкнулся с ошибкой: urllib3 HTTPError HTTPSConnectionPool(host='api.telegram.org', port=443): Max retries exceeded with url: /bot1433757250:AAEo4RDod8FFHlZw0bnbR_tHqzHWjYUistA/sendMessage (Caused by ConnectTimeoutError(<telegram.vendor.ptb_urllib3.urllib3.connection.VerifiedHTTPSConnection object at 0x000001647B60D1F0>, 'Connection to api.telegram.org timed out. (connect timeout=5.0)'))
2021-01-14 02:46:41,457 - __main__ - INFO - Отправка сообщения в телеграм: У вас проверили работу "AnastasiaSar__api_sp1_bot.zip"!

К сожалению в работе нашлись ошибки.
2021-01-14 02:46:46,471 - telegram.vendor.ptb_urllib3.urllib3.connectionpool - WARNING - Retrying (Retry(total=2, connect=None, read=None, redirect=None)) after connection broken by 'ConnectTimeoutError(<telegram.vendor.ptb_urllib3.urllib3.connection.VerifiedHTTPSConnection object at 0x000001647B658100>, 'Connection to api.telegram.org timed out. (connect timeout=5.0)')': /bot1433757250:AAEo4RDod8FFHlZw0bnbR_tHqzHWjYUistA/sendMessage
2021-01-14 02:46:51,474 - telegram.vendor.ptb_urllib3.urllib3.connectionpool - WARNING - Retrying (Retry(total=1, connect=None, read=None, redirect=None)) after connection broken by 'ConnectTimeoutError(<telegram.vendor.ptb_urllib3.urllib3.connection.VerifiedHTTPSConnection object at 0x000001647B6580D0>, 'Connection to api.telegram.org timed out. (connect timeout=5.0)')': /bot1433757250:AAEo4RDod8FFHlZw0bnbR_tHqzHWjYUistA/sendMessage
2021-01-14 02:46:56,481 - telegram.vendor.ptb_urllib3.urllib3.connectionpool - WARNING - Retrying (Retry(total=0, connect=None, read=None, redirect=None)) after connection broken by 'ConnectTimeoutError(<telegram.vendor.ptb_urllib3.urllib3.connection.VerifiedHTTPSConnection object at 0x000001647B6586A0>, 'Connection to api.telegram.org timed out. (connect timeout=5.0)')': /bot1433757250:AAEo4RDod8FFHlZw0bnbR_tHqzHWjYUistA/sendMessage
2021-01-14 02:47:01,493 - __main__ - ERROR - Бот столкнулся с ошибкой: urllib3 HTTPError HTTPSConnectionPool(host='api.telegram.org', port=443): Max retries exceeded with url: /bot1433757250:AAEo4RDod8FFHlZw0bnbR_tHqzHWjYUistA/sendMessage (Caused by ConnectTimeoutError(<telegram.vendor.ptb_urllib3.urllib3.connection.VerifiedHTTPSConnection object at 0x000001647B658B80>, 'Connection to api.telegram.org timed out. (connect timeout=5.0)'))
2021-01-14 02:47:07,774 - __main__ - INFO - Отправка сообщения в телеграм: У вас проверили работу "AnastasiaSar__api_sp1_bot.zip"!

К сожалению в работе нашлись ошибки.
2021-01-14 02:47:12,781 - telegram.vendor.ptb_urllib3.urllib3.connectionpool - WARNING - Retrying (Retry(total=2, connect=None, read=None, redirect=None)) after connection broken by 'ConnectTimeoutError(<telegram.vendor.ptb_urllib3.urllib3.connection.VerifiedHTTPSConnection object at 0x000001647B6588B0>, 'Connection to api.telegram.org timed out. (connect timeout=5.0)')': /bot1433757250:AAEo4RDod8FFHlZw0bnbR_tHqzHWjYUistA/sendMessage
2021-01-14 02:47:17,796 - telegram.vendor.ptb_urllib3.urllib3.connectionpool - WARNING - Retrying (Retry(total=1, connect=None, read=None, redirect=None)) after connection broken by 'ConnectTimeoutError(<telegram.vendor.ptb_urllib3.urllib3.connection.VerifiedHTTPSConnection object at 0x000001647B6583A0>, 'Connection to api.telegram.org timed out. (connect timeout=5.0)')': /bot1433757250:AAEo4RDod8FFHlZw0bnbR_tHqzHWjYUistA/sendMessage
2021-01-14 02:47:20,852 - __main__ - DEBUG - Запуск бота
2021-01-14 02:47:22,123 - __main__ - INFO - Отправка сообщения в телеграм: У вас проверили работу "AnastasiaSar__api_sp1_bot.zip"!

К сожалению в работе нашлись ошибки.
2021-01-14 02:47:22,798 - telegram.vendor.ptb_urllib3.urllib3.connectionpool - WARNING - Retrying (Retry(total=0, connect=None, read=None, redirect=None)) after connection broken by 'ConnectTimeoutError(<telegram.vendor.ptb_urllib3.urllib3.connection.VerifiedHTTPSConnection object at 0x000001647B658BE0>, 'Connection to api.telegram.org timed out. (connect timeout=5.0)')': /bot1433757250:AAEo4RDod8FFHlZw0bnbR_tHqzHWjYUistA/sendMessage
2021-01-14 02:47:27,127 - telegram.vendor.ptb_urllib3.urllib3.connectionpool - WARNING - Retrying (Retry(total=2, connect=None, read=None, redirect=None)) after connection broken by 'ConnectTimeoutError(<telegram.vendor.ptb_urllib3.urllib3.connection.VerifiedHTTPSConnection object at 0x0000014622E0B640>, 'Connection to api.telegram.org timed out. (connect timeout=5.0)')': /bot1433757250:AAEo4RDod8FFHlZw0bnbR_tHqzHWjYUistA/sendMessage
2021-01-14 02:47:27,813 - __main__ - ERROR - Бот столкнулся с ошибкой: urllib3 HTTPError HTTPSConnectionPool(host='api.telegram.org', port=443): Max retries exceeded with url: /bot1433757250:AAEo4RDod8FFHlZw0bnbR_tHqzHWjYUistA/sendMessage (Caused by ConnectTimeoutError(<telegram.vendor.ptb_urllib3.urllib3.connection.VerifiedHTTPSConnection object at 0x000001647B6583D0>, 'Connection to api.telegram.org timed out. (connect timeout=5.0)'))
2021-01-14 02:47:32,141 - telegram.vendor.ptb_urllib3.urllib3.connectionpool - WARNING - Retrying (Retry(total=1, connect=None, read=None, redirect=None)) after connection broken by 'ConnectTimeoutError(<telegram.vendor.ptb_urllib3.urllib3.connection.VerifiedHTTPSConnection object at 0x0000014622E0BFD0>, 'Connection to api.telegram.org timed out. (connect timeout=5.0)')': /bot1433757250:AAEo4RDod8FFHlZw0bnbR_tHqzHWjYUistA/sendMessage
2021-01-14 02:47:34,103 - __main__ - INFO - Отправка сообщения в телеграм: У вас проверили работу "AnastasiaSar__api_sp1_bot.zip"!

К сожалению в работе нашлись ошибки.
2021-01-14 02:47:37,153 - telegram.vendor.ptb_urllib3.urllib3.connectionpool - WARNING - Retrying (Retry(total=0, connect=None, read=None, redirect=None)) after connection broken by 'ConnectTimeoutError(<telegram.vendor.ptb_urllib3.urllib3.connection.VerifiedHTTPSConnection object at 0x0000014622E0B550>, 'Connection to api.telegram.org timed out. (connect timeout=5.0)')': /bot1433757250:AAEo4RDod8FFHlZw0bnbR_tHqzHWjYUistA/sendMessage
2021-01-14 02:47:38,786 - __main__ - DEBUG - Запуск бота
2021-01-14 02:47:40,083 - __main__ - INFO - Отправка сообщения в телеграм: У вас проверили работу "AnastasiaSar__api_sp1_bot.zip"!

К сожалению в работе нашлись ошибки.
2021-01-14 02:47:42,165 - __main__ - ERROR - Бот столкнулся с ошибкой: urllib3 HTTPError HTTPSConnectionPool(host='api.telegram.org', port=443): Max retries exceeded with url: /bot1433757250:AAEo4RDod8FFHlZw0bnbR_tHqzHWjYUistA/sendMessage (Caused by ConnectTimeoutError(<telegram.vendor.ptb_urllib3.urllib3.connection.VerifiedHTTPSConnection object at 0x0000014622E0B2E0>, 'Connection to api.telegram.org timed out. (connect timeout=5.0)'))
2021-01-14 02:47:45,092 - telegram.vendor.ptb_urllib3.urllib3.connectionpool - WARNING - Retrying (Retry(total=2, connect=None, read=None, redirect=None)) after connection broken by 'ConnectTimeoutError(<telegram.vendor.ptb_urllib3.urllib3.connection.VerifiedHTTPSConnection object at 0x000002B0234BD730>, 'Connection to api.telegram.org timed out. (connect timeout=5.0)')': /bot1433757250:AAEo4RDod8FFHlZw0bnbR_tHqzHWjYUistA/sendMessage
2021-01-14 02:47:48,483 - __main__ - INFO - Отправка сообщения в телеграм: У вас проверили работу "AnastasiaSar__api_sp1_bot.zip"!

К сожалению в работе нашлись ошибки.
2021-01-14 02:47:50,099 - telegram.vendor.ptb_urllib3.urllib3.connectionpool - WARNING - Retrying (Retry(total=1, connect=None, read=None, redirect=None)) after connection broken by 'ConnectTimeoutError(<telegram.vendor.ptb_urllib3.urllib3.connection.VerifiedHTTPSConnection object at 0x000002B0234BDEE0>, 'Connection to api.telegram.org timed out. (connect timeout=5.0)')': /bot1433757250:AAEo4RDod8FFHlZw0bnbR_tHqzHWjYUistA/sendMessage
2021-01-14 02:47:53,489 - telegram.vendor.ptb_urllib3.urllib3.connectionpool - WARNING - Retrying (Retry(total=2, connect=None, read=None, redirect=None)) after connection broken by 'ConnectTimeoutError(<telegram.vendor.ptb_urllib3.urllib3.connection.VerifiedHTTPSConnection object at 0x0000014622E0BB20>, 'Connection to api.telegram.org timed out. (connect timeout=5.0)')': /bot1433757250:AAEo4RDod8FFHlZw0bnbR_tHqzHWjYUistA/sendMessage
2021-01-14 02:47:57,623 - __main__ - DEBUG - Запуск бота
2021-01-14 02:47:58,496 - telegram.vendor.ptb_urllib3.urllib3.connectionpool - WARNING - Retrying (Retry(total=1, connect=None, read=None, redirect=None)) after connection broken by 'ConnectTimeoutError(<telegram.vendor.ptb_urllib3.urllib3.connection.VerifiedHTTPSConnection object at 0x0000014622E0B370>, 'Connection to api.telegram.org timed out. (connect timeout=5.0)')': /bot1433757250:AAEo4RDod8FFHlZw0bnbR_tHqzHWjYUistA/sendMessage
2021-01-14 02:47:58,764 - __main__ - INFO - Отправка сообщения в телеграм: У вас проверили работу "AnastasiaSar__api_sp1_bot.zip"!

К сожалению в работе нашлись ошибки.
2021-01-14 02:48:03,500 - telegram.vendor.ptb_urllib3.urllib3.connectionpool - WARNING - Retrying (Retry(total=0, connect=None, read=None, redirect=None)) after connection broken by 'ConnectTimeoutError(<telegram.vendor.ptb_urllib3.urllib3.connection.VerifiedHTTPSConnection object at 0x0000014622E0BFA0>, 'Connection to api.telegram.org timed out. (connect timeout=5.0)')': /bot1433757250:AAEo4RDod8FFHlZw0bnbR_tHqzHWjYUistA/sendMessage
2021-01-14 02:48:03,780 - telegram.vendor.ptb_urllib3.urllib3.connectionpool - WARNING - Retrying (Retry(total=2, connect=None, read=None, redirect=None)) after connection broken by 'ConnectTimeoutError(<telegram.vendor.ptb_urllib3.urllib3.connection.VerifiedHTTPSConnection object at 0x0000018798F3D730>, 'Connection to api.telegram.org timed out. (connect timeout=5.0)')': /bot1433757250:AAEo4RDod8FFHlZw0bnbR_tHqzHWjYUistA/sendMessage
2021-01-14 02:48:08,516 - __main__ - ERROR - Бот столкнулся с ошибкой: urllib3 HTTPError HTTPSConnectionPool(host='api.telegram.org', port=443): Max retries exceeded with url: /bot1433757250:AAEo4RDod8FFHlZw0bnbR_tHqzHWjYUistA/sendMessage (Caused by ConnectTimeoutError(<telegram.vendor.ptb_urllib3.urllib3.connection.VerifiedHTTPSConnection object at 0x0000014622E53130>, 'Connection to api.telegram.org timed out. (connect timeout=5.0)'))
2021-01-14 02:48:08,796 - telegram.vendor.ptb_urllib3.urllib3.connectionpool - WARNING - Retrying (Retry(total=1, connect=None, read=None, redirect=None)) after connection broken by 'ConnectTimeoutError(<telegram.vendor.ptb_urllib3.urllib3.connection.VerifiedHTTPSConnection object at 0x0000018798F3DEE0>, 'Connection to api.telegram.org timed out. (connect timeout=5.0)')': /bot1433757250:AAEo4RDod8FFHlZw0bnbR_tHqzHWjYUistA/sendMessage
2021-01-14 02:48:13,803 - telegram.vendor.ptb_urllib3.urllib3.connectionpool - WARNING - Retrying (Retry(total=0, connect=None, read=None, redirect=None)) after connection broken by 'ConnectTimeoutError(<telegram.vendor.ptb_urllib3.urllib3.connection.VerifiedHTTPSConnection object at 0x0000018798F3DD90>, 'Connection to api.telegram.org timed out. (connect timeout=5.0)')': /bot1433757250:AAEo4RDod8FFHlZw0bnbR_tHqzHWjYUistA/sendMessage
2021-01-14 02:48:14,718 - __main__ - INFO - Отправка сообщения в телеграм: У вас проверили работу "AnastasiaSar__api_sp1_bot.zip"!

К сожалению в работе нашлись ошибки.
2021-01-14 02:48:18,818 - __main__ - ERROR - Бот столкнулся с ошибкой: urllib3 HTTPError HTTPSConnectionPool(host='api.telegram.org', port=443): Max retries exceeded with url: /bot1433757250:AAEo4RDod8FFHlZw0bnbR_tHqzHWjYUistA/sendMessage (Caused by ConnectTimeoutError(<telegram.vendor.ptb_urllib3.urllib3.connection.VerifiedHTTPSConnection object at 0x0000018798F3D3D0>, 'Connection to api.telegram.org timed out. (connect timeout=5.0)'))
2021-01-14 02:48:19,736 - telegram.vendor.ptb_urllib3.urllib3.connectionpool - WARNING - Retrying (Retry(total=2, connect=None, read=None, redirect=None)) after connection broken by 'ConnectTimeoutError(<telegram.vendor.ptb_urllib3.urllib3.connection.VerifiedHTTPSConnection object at 0x0000014622E0B1F0>, 'Connection to api.telegram.org timed out. (connect timeout=5.0)')': /bot1433757250:AAEo4RDod8FFHlZw0bnbR_tHqzHWjYUistA/sendMessage
2021-01-14 02:48:24,750 - telegram.vendor.ptb_urllib3.urllib3.connectionpool - WARNING - Retrying (Retry(total=1, connect=None, read=None, redirect=None)) after connection broken by 'ConnectTimeoutError(<telegram.vendor.ptb_urllib3.urllib3.connection.VerifiedHTTPSConnection object at 0x0000014622E0B0D0>, 'Connection to api.telegram.org timed out. (connect timeout=5.0)')': /bot1433757250:AAEo4RDod8FFHlZw0bnbR_tHqzHWjYUistA/sendMessage
2021-01-14 02:48:25,054 - __main__ - INFO - Отправка сообщения в телеграм: У вас проверили работу "AnastasiaSar__api_sp1_bot.zip"!

К сожалению в работе нашлись ошибки.
2021-01-14 02:48:29,754 - telegram.vendor.ptb_urllib3.urllib3.connectionpool - WARNING - Retrying (Retry(total=0, connect=None, read=None, redirect=None)) after connection broken by 'ConnectTimeoutError(<telegram.vendor.ptb_urllib3.urllib3.connection.VerifiedHTTPSConnection object at 0x0000014622E0BA30>, 'Connection to api.telegram.org timed out. (connect timeout=5.0)')': /bot1433757250:AAEo4RDod8FFHlZw0bnbR_tHqzHWjYUistA/sendMessage
2021-01-14 02:48:30,066 - telegram.vendor.ptb_urllib3.urllib3.connectionpool - WARNING - Retrying (Retry(total=2, connect=None, read=None, redirect=None)) after connection broken by 'ConnectTimeoutError(<telegram.vendor.ptb_urllib3.urllib3.connection.VerifiedHTTPSConnection object at 0x0000018798F3D880>, 'Connection to api.telegram.org timed out. (connect timeout=5.0)')': /bot1433757250:AAEo4RDod8FFHlZw0bnbR_tHqzHWjYUistA/sendMessage
2021-01-14 02:48:34,767 - __main__ - ERROR - Бот столкнулся с ошибкой: urllib3 HTTPError HTTPSConnectionPool(host='api.telegram.org', port=443): Max retries exceeded with url: /bot1433757250:AAEo4RDod8FFHlZw0bnbR_tHqzHWjYUistA/sendMessage (Caused by ConnectTimeoutError(<telegram.vendor.ptb_urllib3.urllib3.connection.VerifiedHTTPSConnection object at 0x0000014622E0B4F0>, 'Connection to api.telegram.org timed out. (connect timeout=5.0)'))
2021-01-14 02:48:35,082 - telegram.vendor.ptb_urllib3.urllib3.connectionpool - WARNING - Retrying (Retry(total=1, connect=None, read=None, redirect=None)) after connection broken by 'ConnectTimeoutError(<telegram.vendor.ptb_urllib3.urllib3.connection.VerifiedHTTPSConnection object at 0x0000018798F3D8E0>, 'Connection to api.telegram.org timed out. (connect timeout=5.0)')': /bot1433757250:AAEo4RDod8FFHlZw0bnbR_tHqzHWjYUistA/sendMessage
2021-01-14 02:48:40,091 - telegram.vendor.ptb_urllib3.urllib3.connectionpool - WARNING - Retrying (Retry(total=0, connect=None, read=None, redirect=None)) after connection broken by 'ConnectTimeoutError(<telegram.vendor.ptb_urllib3.urllib3.connection.VerifiedHTTPSConnection object at 0x0000018798F3D610>, 'Connection to api.telegram.org timed out. (connect timeout=5.0)')': /bot1433757250:AAEo4RDod8FFHlZw0bnbR_tHqzHWjYUistA/sendMessage
2021-01-14 02:48:41,171 - __main__ - INFO - Отправка сообщения в телеграм: У вас проверили работу "AnastasiaSar__api_sp1_bot.zip"!

К сожалению в работе нашлись ошибки.
2021-01-14 02:48:45,106 - __main__ - ERROR - Бот столкнулся с ошибкой: urllib3 HTTPError HTTPSConnectionPool(host='api.telegram.org', port=443): Max retries exceeded with url: /bot1433757250:AAEo4RDod8FFHlZw0bnbR_tHqzHWjYUistA/sendMessage (Caused by ConnectTimeoutError(<telegram.vendor.ptb_urllib3.urllib3.connection.VerifiedHTTPSConnection object at 0x0000018798F3D6A0>, 'Connection to api.telegram.org timed out. (connect timeout=5.0)'))
2021-01-14 02:48:46,186 - telegram.vendor.ptb_urllib3.urllib3.connectionpool - WARNING - Retrying (Retry(total=2, connect=None, read=None, redirect=None)) after connection broken by 'ConnectTimeoutError(<telegram.vendor.ptb_urllib3.urllib3.connection.VerifiedHTTPSConnection object at 0x0000014622E0BA60>, 'Connection to api.telegram.org timed out. (connect timeout=5.0)')': /bot1433757250:AAEo4RDod8FFHlZw0bnbR_tHqzHWjYUistA/sendMessage
2021-01-14 02:48:47,372 - __main__ - DEBUG - Запуск бота
2021-01-14 02:48:48,735 - __main__ - INFO - Отправка сообщения в телеграм: У вас проверили работу "AnastasiaSar__api_sp1_bot.zip"!

К сожалению в работе нашлись ошибки.
2021-01-14 02:48:51,196 - telegram.vendor.ptb_urllib3.urllib3.connectionpool - WARNING - Retrying (Retry(total=1, connect=None, read=None, redirect=None)) after connection broken by 'ConnectTimeoutError(<telegram.vendor.ptb_urllib3.urllib3.connection.VerifiedHTTPSConnection object at 0x0000014622E0B280>, 'Connection to api.telegram.org timed out. (connect timeout=5.0)')': /bot1433757250:AAEo4RDod8FFHlZw0bnbR_tHqzHWjYUistA/sendMessage
2021-01-14 02:48:53,753 - telegram.vendor.ptb_urllib3.urllib3.connectionpool - WARNING - Retrying (Retry(total=2, connect=None, read=None, redirect=None)) after connection broken by 'ConnectTimeoutError(<telegram.vendor.ptb_urllib3.urllib3.connection.VerifiedHTTPSConnection object at 0x000001C085E4D730>, 'Connection to api.telegram.org timed out. (connect timeout=5.0)')': /bot1433757250:AAEo4RDod8FFHlZw0bnbR_tHqzHWjYUistA/sendMessage
2021-01-14 02:48:56,200 - telegram.vendor.ptb_urllib3.urllib3.connectionpool - WARNING - Retrying (Retry(total=0, connect=None, read=None, redirect=None)) after connection broken by 'ConnectTimeoutError(<telegram.vendor.ptb_urllib3.urllib3.connection.VerifiedHTTPSConnection object at 0x0000014622E0B880>, 'Connection to api.telegram.org timed out. (connect timeout=5.0)')': /bot1433757250:AAEo4RDod8FFHlZw0bnbR_tHqzHWjYUistA/sendMessage
2021-01-14 02:48:58,769 - telegram.vendor.ptb_urllib3.urllib3.connectionpool - WARNING - Retrying (Retry(total=1, connect=None, read=None, redirect=None)) after connection broken by 'ConnectTimeoutError(<telegram.vendor.ptb_urllib3.urllib3.connection.VerifiedHTTPSConnection object at 0x000001C085E4DEE0>, 'Connection to api.telegram.org timed out. (connect timeout=5.0)')': /bot1433757250:AAEo4RDod8FFHlZw0bnbR_tHqzHWjYUistA/sendMessage
2021-01-14 02:49:01,216 - __main__ - ERROR - Бот столкнулся с ошибкой: urllib3 HTTPError HTTPSConnectionPool(host='api.telegram.org', port=443): Max retries exceeded with url: /bot1433757250:AAEo4RDod8FFHlZw0bnbR_tHqzHWjYUistA/sendMessage (Caused by ConnectTimeoutError(<telegram.vendor.ptb_urllib3.urllib3.connection.VerifiedHTTPSConnection object at 0x0000014622E58130>, 'Connection to api.telegram.org timed out. (connect timeout=5.0)'))
2021-01-14 02:49:03,783 - telegram.vendor.ptb_urllib3.urllib3.connectionpool - WARNING - Retrying (Retry(total=0, connect=None, read=None, redirect=None)) after connection broken by 'ConnectTimeoutError(<telegram.vendor.ptb_urllib3.urllib3.connection.VerifiedHTTPSConnection object at 0x000001C085E4DD90>, 'Connection to api.telegram.org timed out. (connect timeout=5.0)')': /bot1433757250:AAEo4RDod8FFHlZw0bnbR_tHqzHWjYUistA/sendMessage
2021-01-14 02:49:07,459 - __main__ - INFO - Отправка сообщения в телеграм: У вас проверили работу "AnastasiaSar__api_sp1_bot.zip"!

К сожалению в работе нашлись ошибки.
2021-01-14 02:49:08,787 - __main__ - ERROR - Бот столкнулся с ошибкой: urllib3 HTTPError HTTPSConnectionPool(host='api.telegram.org', port=443): Max retries exceeded with url: /bot1433757250:AAEo4RDod8FFHlZw0bnbR_tHqzHWjYUistA/sendMessage (Caused by ConnectTimeoutError(<telegram.vendor.ptb_urllib3.urllib3.connection.VerifiedHTTPSConnection object at 0x000001C085E4D3D0>, 'Connection to api.telegram.org timed out. (connect timeout=5.0)'))
2021-01-14 02:49:12,462 - telegram.vendor.ptb_urllib3.urllib3.connectionpool - WARNING - Retrying (Retry(total=2, connect=None, read=None, redirect=None)) after connection broken by 'ConnectTimeoutError(<telegram.vendor.ptb_urllib3.urllib3.connection.VerifiedHTTPSConnection object at 0x0000014622E582E0>, 'Connection to api.telegram.org timed out. (connect timeout=5.0)')': /bot1433757250:AAEo4RDod8FFHlZw0bnbR_tHqzHWjYUistA/sendMessage
2021-01-14 02:49:15,105 - __main__ - INFO - Отправка сообщения в телеграм: У вас проверили работу "AnastasiaSar__api_sp1_bot.zip"!

К сожалению в работе нашлись ошибки.
2021-01-14 02:49:17,476 - telegram.vendor.ptb_urllib3.urllib3.connectionpool - WARNING - Retrying (Retry(total=1, connect=None, read=None, redirect=None)) after connection broken by 'ConnectTimeoutError(<telegram.vendor.ptb_urllib3.urllib3.connection.VerifiedHTTPSConnection object at 0x0000014622E58760>, 'Connection to api.telegram.org timed out. (connect timeout=5.0)')': /bot1433757250:AAEo4RDod8FFHlZw0bnbR_tHqzHWjYUistA/sendMessage
2021-01-14 02:49:20,118 - telegram.vendor.ptb_urllib3.urllib3.connectionpool - WARNING - Retrying (Retry(total=2, connect=None, read=None, redirect=None)) after connection broken by 'ConnectTimeoutError(<telegram.vendor.ptb_urllib3.urllib3.connection.VerifiedHTTPSConnection object at 0x000001C085E4D880>, 'Connection to api.telegram.org timed out. (connect timeout=5.0)')': /bot1433757250:AAEo4RDod8FFHlZw0bnbR_tHqzHWjYUistA/sendMessage
2021-01-14 02:49:22,482 - telegram.vendor.ptb_urllib3.urllib3.connectionpool - WARNING - Retrying (Retry(total=0, connect=None, read=None, redirect=None)) after connection broken by 'ConnectTimeoutError(<telegram.vendor.ptb_urllib3.urllib3.connection.VerifiedHTTPSConnection object at 0x0000014622E587C0>, 'Connection to api.telegram.org timed out. (connect timeout=5.0)')': /bot1433757250:AAEo4RDod8FFHlZw0bnbR_tHqzHWjYUistA/sendMessage
2021-01-14 02:49:24,537 - __main__ - DEBUG - Запуск бота
2021-01-14 02:49:25,804 - __main__ - INFO - Отправка сообщения в телеграм: У вас проверили работу "AnastasiaSar__api_sp1_bot.zip"!

К сожалению в работе нашлись ошибки.
2021-01-14 02:49:27,497 - __main__ - ERROR - Бот столкнулся с ошибкой: urllib3 HTTPError HTTPSConnectionPool(host='api.telegram.org', port=443): Max retries exceeded with url: /bot1433757250:AAEo4RDod8FFHlZw0bnbR_tHqzHWjYUistA/sendMessage (Caused by ConnectTimeoutError(<telegram.vendor.ptb_urllib3.urllib3.connection.VerifiedHTTPSConnection object at 0x0000014622E58B80>, 'Connection to api.telegram.org timed out. (connect timeout=5.0)'))
2021-01-14 02:49:30,820 - telegram.vendor.ptb_urllib3.urllib3.connectionpool - WARNING - Retrying (Retry(total=2, connect=None, read=None, redirect=None)) after connection broken by 'ConnectTimeoutError(<telegram.vendor.ptb_urllib3.urllib3.connection.VerifiedHTTPSConnection object at 0x000001B125FAD730>, 'Connection to api.telegram.org timed out. (connect timeout=5.0)')': /bot1433757250:AAEo4RDod8FFHlZw0bnbR_tHqzHWjYUistA/sendMessage
2021-01-14 02:49:33,800 - __main__ - INFO - Отправка сообщения в телеграм: У вас проверили работу "AnastasiaSar__api_sp1_bot.zip"!

К сожалению в работе нашлись ошибки.
2021-01-14 02:49:35,840 - telegram.vendor.ptb_urllib3.urllib3.connectionpool - WARNING - Retrying (Retry(total=1, connect=None, read=None, redirect=None)) after connection broken by 'ConnectTimeoutError(<telegram.vendor.ptb_urllib3.urllib3.connection.VerifiedHTTPSConnection object at 0x000001B125FADEE0>, 'Connection to api.telegram.org timed out. (connect timeout=5.0)')': /bot1433757250:AAEo4RDod8FFHlZw0bnbR_tHqzHWjYUistA/sendMessage
2021-01-14 02:49:38,811 - telegram.vendor.ptb_urllib3.urllib3.connectionpool - WARNING - Retrying (Retry(total=2, connect=None, read=None, redirect=None)) after connection broken by 'ConnectTimeoutError(<telegram.vendor.ptb_urllib3.urllib3.connection.VerifiedHTTPSConnection object at 0x0000014622E58BE0>, 'Connection to api.telegram.org timed out. (connect timeout=5.0)')': /bot1433757250:AAEo4RDod8FFHlZw0bnbR_tHqzHWjYUistA/sendMessage
2021-01-14 02:49:40,848 - telegram.vendor.ptb_urllib3.urllib3.connectionpool - WARNING - Retrying (Retry(total=0, connect=None, read=None, redirect=None)) after connection broken by 'ConnectTimeoutError(<telegram.vendor.ptb_urllib3.urllib3.connection.VerifiedHTTPSConnection object at 0x000001B125FADD90>, 'Connection to api.telegram.org timed out. (connect timeout=5.0)')': /bot1433757250:AAEo4RDod8FFHlZw0bnbR_tHqzHWjYUistA/sendMessage
2021-01-14 02:49:43,821 - telegram.vendor.ptb_urllib3.urllib3.connectionpool - WARNING - Retrying (Retry(total=1, connect=None, read=None, redirect=None)) after connection broken by 'ConnectTimeoutError(<telegram.vendor.ptb_urllib3.urllib3.connection.VerifiedHTTPSConnection object at 0x0000014622E58550>, 'Connection to api.telegram.org timed out. (connect timeout=5.0)')': /bot1433757250:AAEo4RDod8FFHlZw0bnbR_tHqzHWjYUistA/sendMessage
2021-01-14 02:49:45,857 - __main__ - ERROR - Бот столкнулся с ошибкой: urllib3 HTTPError HTTPSConnectionPool(host='api.telegram.org', port=443): Max retries exceeded with url: /bot1433757250:AAEo4RDod8FFHlZw0bnbR_tHqzHWjYUistA/sendMessage (Caused by ConnectTimeoutError(<telegram.vendor.ptb_urllib3.urllib3.connection.VerifiedHTTPSConnection object at 0x000001B125FAD3D0>, 'Connection to api.telegram.org timed out. (connect timeout=5.0)'))
2021-01-14 02:49:48,836 - telegram.vendor.ptb_urllib3.urllib3.connectionpool - WARNING - Retrying (Retry(total=0, connect=None, read=None, redirect=None)) after connection broken by 'ConnectTimeoutError(<telegram.vendor.ptb_urllib3.urllib3.connection.VerifiedHTTPSConnection object at 0x0000014622E58CD0>, 'Connection to api.telegram.org timed out. (connect timeout=5.0)')': /bot1433757250:AAEo4RDod8FFHlZw0bnbR_tHqzHWjYUistA/sendMessage
2021-01-14 02:49:52,104 - __main__ - INFO - Отправка сообщения в телеграм: У вас проверили работу "AnastasiaSar__api_sp1_bot.zip"!

К сожалению в работе нашлись ошибки.
2021-01-14 02:49:53,848 - __main__ - ERROR - Бот столкнулся с ошибкой: urllib3 HTTPError HTTPSConnectionPool(host='api.telegram.org', port=443): Max retries exceeded with url: /bot1433757250:AAEo4RDod8FFHlZw0bnbR_tHqzHWjYUistA/sendMessage (Caused by ConnectTimeoutError(<telegram.vendor.ptb_urllib3.urllib3.connection.VerifiedHTTPSConnection object at 0x0000014622E58730>, 'Connection to api.telegram.org timed out. (connect timeout=5.0)'))
2021-01-14 02:49:57,118 - telegram.vendor.ptb_urllib3.urllib3.connectionpool - WARNING - Retrying (Retry(total=2, connect=None, read=None, redirect=None)) after connection broken by 'ConnectTimeoutError(<telegram.vendor.ptb_urllib3.urllib3.connection.VerifiedHTTPSConnection object at 0x000001B125FAD880>, 'Connection to api.telegram.org timed out. (connect timeout=5.0)')': /bot1433757250:AAEo4RDod8FFHlZw0bnbR_tHqzHWjYUistA/sendMessage
2021-01-14 02:50:00,063 - __main__ - INFO - Отправка сообщения в телеграм: У вас проверили работу "AnastasiaSar__api_sp1_bot.zip"!

К сожалению в работе нашлись ошибки.
2021-01-14 02:50:02,134 - telegram.vendor.ptb_urllib3.urllib3.connectionpool - WARNING - Retrying (Retry(total=1, connect=None, read=None, redirect=None)) after connection broken by 'ConnectTimeoutError(<telegram.vendor.ptb_urllib3.urllib3.connection.VerifiedHTTPSConnection object at 0x000001B125FAD8E0>, 'Connection to api.telegram.org timed out. (connect timeout=5.0)')': /bot1433757250:AAEo4RDod8FFHlZw0bnbR_tHqzHWjYUistA/sendMessage
2021-01-14 02:50:05,069 - telegram.vendor.ptb_urllib3.urllib3.connectionpool - WARNING - Retrying (Retry(total=2, connect=None, read=None, redirect=None)) after connection broken by 'ConnectTimeoutError(<telegram.vendor.ptb_urllib3.urllib3.connection.VerifiedHTTPSConnection object at 0x0000014622E58640>, 'Connection to api.telegram.org timed out. (connect timeout=5.0)')': /bot1433757250:AAEo4RDod8FFHlZw0bnbR_tHqzHWjYUistA/sendMessage
2021-01-14 02:50:07,137 - telegram.vendor.ptb_urllib3.urllib3.connectionpool - WARNING - Retrying (Retry(total=0, connect=None, read=None, redirect=None)) after connection broken by 'ConnectTimeoutError(<telegram.vendor.ptb_urllib3.urllib3.connection.VerifiedHTTPSConnection object at 0x000001B125FAD610>, 'Connection to api.telegram.org timed out. (connect timeout=5.0)')': /bot1433757250:AAEo4RDod8FFHlZw0bnbR_tHqzHWjYUistA/sendMessage
2021-01-14 02:50:10,081 - telegram.vendor.ptb_urllib3.urllib3.connectionpool - WARNING - Retrying (Retry(total=1, connect=None, read=None, redirect=None)) after connection broken by 'ConnectTimeoutError(<telegram.vendor.ptb_urllib3.urllib3.connection.VerifiedHTTPSConnection object at 0x0000014622E58F10>, 'Connection to api.telegram.org timed out. (connect timeout=5.0)')': /bot1433757250:AAEo4RDod8FFHlZw0bnbR_tHqzHWjYUistA/sendMessage
2021-01-14 02:50:12,149 - __main__ - ERROR - Бот столкнулся с ошибкой: urllib3 HTTPError HTTPSConnectionPool(host='api.telegram.org', port=443): Max retries exceeded with url: /bot1433757250:AAEo4RDod8FFHlZw0bnbR_tHqzHWjYUistA/sendMessage (Caused by ConnectTimeoutError(<telegram.vendor.ptb_urllib3.urllib3.connection.VerifiedHTTPSConnection object at 0x000001B125FAD6A0>, 'Connection to api.telegram.org timed out. (connect timeout=5.0)'))
2021-01-14 02:50:15,085 - telegram.vendor.ptb_urllib3.urllib3.connectionpool - WARNING - Retrying (Retry(total=0, connect=None, read=None, redirect=None)) after connection broken by 'ConnectTimeoutError(<telegram.vendor.ptb_urllib3.urllib3.connection.VerifiedHTTPSConnection object at 0x0000014622E584F0>, 'Connection to api.telegram.org timed out. (connect timeout=5.0)')': /bot1433757250:AAEo4RDod8FFHlZw0bnbR_tHqzHWjYUistA/sendMessage
2021-01-14 02:50:18,350 - __main__ - INFO - Отправка сообщения в телеграм: У вас проверили работу "AnastasiaSar__api_sp1_bot.zip"!

К сожалению в работе нашлись ошибки.
2021-01-14 02:50:20,096 - __main__ - ERROR - Бот столкнулся с ошибкой: urllib3 HTTPError HTTPSConnectionPool(host='api.telegram.org', port=443): Max retries exceeded with url: /bot1433757250:AAEo4RDod8FFHlZw0bnbR_tHqzHWjYUistA/sendMessage (Caused by ConnectTimeoutError(<telegram.vendor.ptb_urllib3.urllib3.connection.VerifiedHTTPSConnection object at 0x0000014622E58400>, 'Connection to api.telegram.org timed out. (connect timeout=5.0)'))
2021-01-14 02:50:23,353 - telegram.vendor.ptb_urllib3.urllib3.connectionpool - WARNING - Retrying (Retry(total=2, connect=None, read=None, redirect=None)) after connection broken by 'ConnectTimeoutError(<telegram.vendor.ptb_urllib3.urllib3.connection.VerifiedHTTPSConnection object at 0x000001B125FAD880>, 'Connection to api.telegram.org timed out. (connect timeout=5.0)')': /bot1433757250:AAEo4RDod8FFHlZw0bnbR_tHqzHWjYUistA/sendMessage
2021-01-14 02:50:26,401 - __main__ - INFO - Отправка сообщения в телеграм: У вас проверили работу "AnastasiaSar__api_sp1_bot.zip"!

К сожалению в работе нашлись ошибки.
2021-01-14 02:50:28,366 - telegram.vendor.ptb_urllib3.urllib3.connectionpool - WARNING - Retrying (Retry(total=1, connect=None, read=None, redirect=None)) after connection broken by 'ConnectTimeoutError(<telegram.vendor.ptb_urllib3.urllib3.connection.VerifiedHTTPSConnection object at 0x000001B125FAD670>, 'Connection to api.telegram.org timed out. (connect timeout=5.0)')': /bot1433757250:AAEo4RDod8FFHlZw0bnbR_tHqzHWjYUistA/sendMessage
2021-01-14 02:50:31,413 - telegram.vendor.ptb_urllib3.urllib3.connectionpool - WARNING - Retrying (Retry(total=2, connect=None, read=None, redirect=None)) after connection broken by 'ConnectTimeoutError(<telegram.vendor.ptb_urllib3.urllib3.connection.VerifiedHTTPSConnection object at 0x0000014622E0B880>, 'Connection to api.telegram.org timed out. (connect timeout=5.0)')': /bot1433757250:AAEo4RDod8FFHlZw0bnbR_tHqzHWjYUistA/sendMessage
2021-01-14 02:50:33,379 - telegram.vendor.ptb_urllib3.urllib3.connectionpool - WARNING - Retrying (Retry(total=0, connect=None, read=None, redirect=None)) after connection broken by 'ConnectTimeoutError(<telegram.vendor.ptb_urllib3.urllib3.connection.VerifiedHTTPSConnection object at 0x000001B125FADEB0>, 'Connection to api.telegram.org timed out. (connect timeout=5.0)')': /bot1433757250:AAEo4RDod8FFHlZw0bnbR_tHqzHWjYUistA/sendMessage
2021-01-14 02:50:36,426 - telegram.vendor.ptb_urllib3.urllib3.connectionpool - WARNING - Retrying (Retry(total=1, connect=None, read=None, redirect=None)) after connection broken by 'ConnectTimeoutError(<telegram.vendor.ptb_urllib3.urllib3.connection.VerifiedHTTPSConnection object at 0x0000014622E0BF70>, 'Connection to api.telegram.org timed out. (connect timeout=5.0)')': /bot1433757250:AAEo4RDod8FFHlZw0bnbR_tHqzHWjYUistA/sendMessage
2021-01-14 02:50:38,403 - __main__ - ERROR - Бот столкнулся с ошибкой: urllib3 HTTPError HTTPSConnectionPool(host='api.telegram.org', port=443): Max retries exceeded with url: /bot1433757250:AAEo4RDod8FFHlZw0bnbR_tHqzHWjYUistA/sendMessage (Caused by ConnectTimeoutError(<telegram.vendor.ptb_urllib3.urllib3.connection.VerifiedHTTPSConnection object at 0x000001B125FAD430>, 'Connection to api.telegram.org timed out. (connect timeout=5.0)'))
2021-01-14 02:50:41,430 - telegram.vendor.ptb_urllib3.urllib3.connectionpool - WARNING - Retrying (Retry(total=0, connect=None, read=None, redirect=None)) after connection broken by 'ConnectTimeoutError(<telegram.vendor.ptb_urllib3.urllib3.connection.VerifiedHTTPSConnection object at 0x0000014622E0B5E0>, 'Connection to api.telegram.org timed out. (connect timeout=5.0)')': /bot1433757250:AAEo4RDod8FFHlZw0bnbR_tHqzHWjYUistA/sendMessage
2021-01-14 02:50:44,703 - __main__ - INFO - Отправка сообщения в телеграм: У вас проверили работу "AnastasiaSar__api_sp1_bot.zip"!

К сожалению в работе нашлись ошибки.
2021-01-14 02:50:46,432 - __main__ - ERROR - Бот столкнулся с ошибкой: urllib3 HTTPError HTTPSConnectionPool(host='api.telegram.org', port=443): Max retries exceeded with url: /bot1433757250:AAEo4RDod8FFHlZw0bnbR_tHqzHWjYUistA/sendMessage (Caused by ConnectTimeoutError(<telegram.vendor.ptb_urllib3.urllib3.connection.VerifiedHTTPSConnection object at 0x0000014622E0B550>, 'Connection to api.telegram.org timed out. (connect timeout=5.0)'))
2021-01-14 02:50:49,716 - telegram.vendor.ptb_urllib3.urllib3.connectionpool - WARNING - Retrying (Retry(total=2, connect=None, read=None, redirect=None)) after connection broken by 'ConnectTimeoutError(<telegram.vendor.ptb_urllib3.urllib3.connection.VerifiedHTTPSConnection object at 0x000001B125FAD2E0>, 'Connection to api.telegram.org timed out. (connect timeout=5.0)')': /bot1433757250:AAEo4RDod8FFHlZw0bnbR_tHqzHWjYUistA/sendMessage
2021-01-14 02:50:52,681 - __main__ - INFO - Отправка сообщения в телеграм: У вас проверили работу "AnastasiaSar__api_sp1_bot.zip"!

К сожалению в работе нашлись ошибки.
2021-01-14 02:50:54,727 - telegram.vendor.ptb_urllib3.urllib3.connectionpool - WARNING - Retrying (Retry(total=1, connect=None, read=None, redirect=None)) after connection broken by 'ConnectTimeoutError(<telegram.vendor.ptb_urllib3.urllib3.connection.VerifiedHTTPSConnection object at 0x000001B125FADD90>, 'Connection to api.telegram.org timed out. (connect timeout=5.0)')': /bot1433757250:AAEo4RDod8FFHlZw0bnbR_tHqzHWjYUistA/sendMessage
2021-01-14 02:50:57,696 - telegram.vendor.ptb_urllib3.urllib3.connectionpool - WARNING - Retrying (Retry(total=2, connect=None, read=None, redirect=None)) after connection broken by 'ConnectTimeoutError(<telegram.vendor.ptb_urllib3.urllib3.connection.VerifiedHTTPSConnection object at 0x0000014622E0B8E0>, 'Connection to api.telegram.org timed out. (connect timeout=5.0)')': /bot1433757250:AAEo4RDod8FFHlZw0bnbR_tHqzHWjYUistA/sendMessage
2021-01-14 02:50:59,734 - telegram.vendor.ptb_urllib3.urllib3.connectionpool - WARNING - Retrying (Retry(total=0, connect=None, read=None, redirect=None)) after connection broken by 'ConnectTimeoutError(<telegram.vendor.ptb_urllib3.urllib3.connection.VerifiedHTTPSConnection object at 0x000001B125FAD100>, 'Connection to api.telegram.org timed out. (connect timeout=5.0)')': /bot1433757250:AAEo4RDod8FFHlZw0bnbR_tHqzHWjYUistA/sendMessage
2021-01-14 02:51:02,708 - telegram.vendor.ptb_urllib3.urllib3.connectionpool - WARNING - Retrying (Retry(total=1, connect=None, read=None, redirect=None)) after connection broken by 'ConnectTimeoutError(<telegram.vendor.ptb_urllib3.urllib3.connection.VerifiedHTTPSConnection object at 0x0000014622E0B370>, 'Connection to api.telegram.org timed out. (connect timeout=5.0)')': /bot1433757250:AAEo4RDod8FFHlZw0bnbR_tHqzHWjYUistA/sendMessage
2021-01-14 02:51:04,742 - __main__ - ERROR - Бот столкнулся с ошибкой: urllib3 HTTPError HTTPSConnectionPool(host='api.telegram.org', port=443): Max retries exceeded with url: /bot1433757250:AAEo4RDod8FFHlZw0bnbR_tHqzHWjYUistA/sendMessage (Caused by ConnectTimeoutError(<telegram.vendor.ptb_urllib3.urllib3.connection.VerifiedHTTPSConnection object at 0x000001B125FAD1F0>, 'Connection to api.telegram.org timed out. (connect timeout=5.0)'))
2021-01-14 02:51:07,721 - telegram.vendor.ptb_urllib3.urllib3.connectionpool - WARNING - Retrying (Retry(total=0, connect=None, read=None, redirect=None)) after connection broken by 'ConnectTimeoutError(<telegram.vendor.ptb_urllib3.urllib3.connection.VerifiedHTTPSConnection object at 0x0000014622E0B4F0>, 'Connection to api.telegram.org timed out. (connect timeout=5.0)')': /bot1433757250:AAEo4RDod8FFHlZw0bnbR_tHqzHWjYUistA/sendMessage
2021-01-14 02:51:11,095 - __main__ - INFO - Отправка сообщения в телеграм: У вас проверили работу "AnastasiaSar__api_sp1_bot.zip"!

К сожалению в работе нашлись ошибки.
2021-01-14 02:51:12,737 - __main__ - ERROR - Бот столкнулся с ошибкой: urllib3 HTTPError HTTPSConnectionPool(host='api.telegram.org', port=443): Max retries exceeded with url: /bot1433757250:AAEo4RDod8FFHlZw0bnbR_tHqzHWjYUistA/sendMessage (Caused by ConnectTimeoutError(<telegram.vendor.ptb_urllib3.urllib3.connection.VerifiedHTTPSConnection object at 0x0000014622E58F70>, 'Connection to api.telegram.org timed out. (connect timeout=5.0)'))
2021-01-14 02:51:16,109 - telegram.vendor.ptb_urllib3.urllib3.connectionpool - WARNING - Retrying (Retry(total=2, connect=None, read=None, redirect=None)) after connection broken by 'ConnectTimeoutError(<telegram.vendor.ptb_urllib3.urllib3.connection.VerifiedHTTPSConnection object at 0x000001B125FF8100>, 'Connection to api.telegram.org timed out. (connect timeout=5.0)')': /bot1433757250:AAEo4RDod8FFHlZw0bnbR_tHqzHWjYUistA/sendMessage
2021-01-14 02:51:18,973 - __main__ - INFO - Отправка сообщения в телеграм: У вас проверили работу "AnastasiaSar__api_sp1_bot.zip"!

К сожалению в работе нашлись ошибки.
2021-01-14 02:51:21,118 - telegram.vendor.ptb_urllib3.urllib3.connectionpool - WARNING - Retrying (Retry(total=1, connect=None, read=None, redirect=None)) after connection broken by 'ConnectTimeoutError(<telegram.vendor.ptb_urllib3.urllib3.connection.VerifiedHTTPSConnection object at 0x000001B125FF80D0>, 'Connection to api.telegram.org timed out. (connect timeout=5.0)')': /bot1433757250:AAEo4RDod8FFHlZw0bnbR_tHqzHWjYUistA/sendMessage
2021-01-14 02:51:23,975 - telegram.vendor.ptb_urllib3.urllib3.connectionpool - WARNING - Retrying (Retry(total=2, connect=None, read=None, redirect=None)) after connection broken by 'ConnectTimeoutError(<telegram.vendor.ptb_urllib3.urllib3.connection.VerifiedHTTPSConnection object at 0x0000014622E58610>, 'Connection to api.telegram.org timed out. (connect timeout=5.0)')': /bot1433757250:AAEo4RDod8FFHlZw0bnbR_tHqzHWjYUistA/sendMessage
2021-01-14 02:51:26,127 - telegram.vendor.ptb_urllib3.urllib3.connectionpool - WARNING - Retrying (Retry(total=0, connect=None, read=None, redirect=None)) after connection broken by 'ConnectTimeoutError(<telegram.vendor.ptb_urllib3.urllib3.connection.VerifiedHTTPSConnection object at 0x000001B125FF86A0>, 'Connection to api.telegram.org timed out. (connect timeout=5.0)')': /bot1433757250:AAEo4RDod8FFHlZw0bnbR_tHqzHWjYUistA/sendMessage
2021-01-14 02:51:28,985 - telegram.vendor.ptb_urllib3.urllib3.connectionpool - WARNING - Retrying (Retry(total=1, connect=None, read=None, redirect=None)) after connection broken by 'ConnectTimeoutError(<telegram.vendor.ptb_urllib3.urllib3.connection.VerifiedHTTPSConnection object at 0x0000014622E58880>, 'Connection to api.telegram.org timed out. (connect timeout=5.0)')': /bot1433757250:AAEo4RDod8FFHlZw0bnbR_tHqzHWjYUistA/sendMessage
2021-01-14 02:51:31,138 - __main__ - ERROR - Бот столкнулся с ошибкой: urllib3 HTTPError HTTPSConnectionPool(host='api.telegram.org', port=443): Max retries exceeded with url: /bot1433757250:AAEo4RDod8FFHlZw0bnbR_tHqzHWjYUistA/sendMessage (Caused by ConnectTimeoutError(<telegram.vendor.ptb_urllib3.urllib3.connection.VerifiedHTTPSConnection object at 0x000001B125FF8B80>, 'Connection to api.telegram.org timed out. (connect timeout=5.0)'))
2021-01-14 02:51:33,993 - telegram.vendor.ptb_urllib3.urllib3.connectionpool - WARNING - Retrying (Retry(total=0, connect=None, read=None, redirect=None)) after connection broken by 'ConnectTimeoutError(<telegram.vendor.ptb_urllib3.urllib3.connection.VerifiedHTTPSConnection object at 0x0000014622E58340>, 'Connection to api.telegram.org timed out. (connect timeout=5.0)')': /bot1433757250:AAEo4RDod8FFHlZw0bnbR_tHqzHWjYUistA/sendMessage
2021-01-14 02:51:37,736 - __main__ - INFO - Отправка сообщения в телеграм: У вас проверили работу "AnastasiaSar__api_sp1_bot.zip"!

К сожалению в работе нашлись ошибки.
2021-01-14 02:51:39,004 - __main__ - ERROR - Бот столкнулся с ошибкой: urllib3 HTTPError HTTPSConnectionPool(host='api.telegram.org', port=443): Max retries exceeded with url: /bot1433757250:AAEo4RDod8FFHlZw0bnbR_tHqzHWjYUistA/sendMessage (Caused by ConnectTimeoutError(<telegram.vendor.ptb_urllib3.urllib3.connection.VerifiedHTTPSConnection object at 0x0000014622E585E0>, 'Connection to api.telegram.org timed out. (connect timeout=5.0)'))
2021-01-14 02:51:42,748 - telegram.vendor.ptb_urllib3.urllib3.connectionpool - WARNING - Retrying (Retry(total=2, connect=None, read=None, redirect=None)) after connection broken by 'ConnectTimeoutError(<telegram.vendor.ptb_urllib3.urllib3.connection.VerifiedHTTPSConnection object at 0x000001B125FF88B0>, 'Connection to api.telegram.org timed out. (connect timeout=5.0)')': /bot1433757250:AAEo4RDod8FFHlZw0bnbR_tHqzHWjYUistA/sendMessage
2021-01-14 02:51:45,362 - __main__ - INFO - Отправка сообщения в телеграм: У вас проверили работу "AnastasiaSar__api_sp1_bot.zip"!

К сожалению в работе нашлись ошибки.
2021-01-14 02:51:47,762 - telegram.vendor.ptb_urllib3.urllib3.connectionpool - WARNING - Retrying (Retry(total=1, connect=None, read=None, redirect=None)) after connection broken by 'ConnectTimeoutError(<telegram.vendor.ptb_urllib3.urllib3.connection.VerifiedHTTPSConnection object at 0x000001B125FF83A0>, 'Connection to api.telegram.org timed out. (connect timeout=5.0)')': /bot1433757250:AAEo4RDod8FFHlZw0bnbR_tHqzHWjYUistA/sendMessage
2021-01-14 02:51:50,376 - telegram.vendor.ptb_urllib3.urllib3.connectionpool - WARNING - Retrying (Retry(total=2, connect=None, read=None, redirect=None)) after connection broken by 'ConnectTimeoutError(<telegram.vendor.ptb_urllib3.urllib3.connection.VerifiedHTTPSConnection object at 0x0000014622E58C70>, 'Connection to api.telegram.org timed out. (connect timeout=5.0)')': /bot1433757250:AAEo4RDod8FFHlZw0bnbR_tHqzHWjYUistA/sendMessage
2021-01-14 02:51:52,773 - telegram.vendor.ptb_urllib3.urllib3.connectionpool - WARNING - Retrying (Retry(total=0, connect=None, read=None, redirect=None)) after connection broken by 'ConnectTimeoutError(<telegram.vendor.ptb_urllib3.urllib3.connection.VerifiedHTTPSConnection object at 0x000001B125FF8BE0>, 'Connection to api.telegram.org timed out. (connect timeout=5.0)')': /bot1433757250:AAEo4RDod8FFHlZw0bnbR_tHqzHWjYUistA/sendMessage
2021-01-14 02:51:55,382 - telegram.vendor.ptb_urllib3.urllib3.connectionpool - WARNING - Retrying (Retry(total=1, connect=None, read=None, redirect=None)) after connection broken by 'ConnectTimeoutError(<telegram.vendor.ptb_urllib3.urllib3.connection.VerifiedHTTPSConnection object at 0x0000014622E58070>, 'Connection to api.telegram.org timed out. (connect timeout=5.0)')': /bot1433757250:AAEo4RDod8FFHlZw0bnbR_tHqzHWjYUistA/sendMessage
2021-01-14 02:51:57,781 - __main__ - ERROR - Бот столкнулся с ошибкой: urllib3 HTTPError HTTPSConnectionPool(host='api.telegram.org', port=443): Max retries exceeded with url: /bot1433757250:AAEo4RDod8FFHlZw0bnbR_tHqzHWjYUistA/sendMessage (Caused by ConnectTimeoutError(<telegram.vendor.ptb_urllib3.urllib3.connection.VerifiedHTTPSConnection object at 0x000001B125FF83D0>, 'Connection to api.telegram.org timed out. (connect timeout=5.0)'))
2021-01-14 02:52:00,386 - telegram.vendor.ptb_urllib3.urllib3.connectionpool - WARNING - Retrying (Retry(total=0, connect=None, read=None, redirect=None)) after connection broken by 'ConnectTimeoutError(<telegram.vendor.ptb_urllib3.urllib3.connection.VerifiedHTTPSConnection object at 0x0000014622E58D90>, 'Connection to api.telegram.org timed out. (connect timeout=5.0)')': /bot1433757250:AAEo4RDod8FFHlZw0bnbR_tHqzHWjYUistA/sendMessage
2021-01-14 02:52:04,044 - __main__ - INFO - Отправка сообщения в телеграм: У вас проверили работу "AnastasiaSar__api_sp1_bot.zip"!

К сожалению в работе нашлись ошибки.
2021-01-14 02:52:05,397 - __main__ - ERROR - Бот столкнулся с ошибкой: urllib3 HTTPError HTTPSConnectionPool(host='api.telegram.org', port=443): Max retries exceeded with url: /bot1433757250:AAEo4RDod8FFHlZw0bnbR_tHqzHWjYUistA/sendMessage (Caused by ConnectTimeoutError(<telegram.vendor.ptb_urllib3.urllib3.connection.VerifiedHTTPSConnection object at 0x0000014622E58850>, 'Connection to api.telegram.org timed out. (connect timeout=5.0)'))
2021-01-14 02:52:09,069 - telegram.vendor.ptb_urllib3.urllib3.connectionpool - WARNING - Retrying (Retry(total=2, connect=None, read=None, redirect=None)) after connection broken by 'ConnectTimeoutError(<telegram.vendor.ptb_urllib3.urllib3.connection.VerifiedHTTPSConnection object at 0x000001B125FF8310>, 'Connection to api.telegram.org timed out. (connect timeout=5.0)')': /bot1433757250:AAEo4RDod8FFHlZw0bnbR_tHqzHWjYUistA/sendMessage
2021-01-14 02:52:11,645 - __main__ - INFO - Отправка сообщения в телеграм: У вас проверили работу "AnastasiaSar__api_sp1_bot.zip"!

К сожалению в работе нашлись ошибки.
2021-01-14 02:52:14,079 - telegram.vendor.ptb_urllib3.urllib3.connectionpool - WARNING - Retrying (Retry(total=1, connect=None, read=None, redirect=None)) after connection broken by 'ConnectTimeoutError(<telegram.vendor.ptb_urllib3.urllib3.connection.VerifiedHTTPSConnection object at 0x000001B125FF8760>, 'Connection to api.telegram.org timed out. (connect timeout=5.0)')': /bot1433757250:AAEo4RDod8FFHlZw0bnbR_tHqzHWjYUistA/sendMessage
2021-01-14 02:52:16,648 - telegram.vendor.ptb_urllib3.urllib3.connectionpool - WARNING - Retrying (Retry(total=2, connect=None, read=None, redirect=None)) after connection broken by 'ConnectTimeoutError(<telegram.vendor.ptb_urllib3.urllib3.connection.VerifiedHTTPSConnection object at 0x0000014622E0B640>, 'Connection to api.telegram.org timed out. (connect timeout=5.0)')': /bot1433757250:AAEo4RDod8FFHlZw0bnbR_tHqzHWjYUistA/sendMessage
2021-01-14 02:52:19,095 - telegram.vendor.ptb_urllib3.urllib3.connectionpool - WARNING - Retrying (Retry(total=0, connect=None, read=None, redirect=None)) after connection broken by 'ConnectTimeoutError(<telegram.vendor.ptb_urllib3.urllib3.connection.VerifiedHTTPSConnection object at 0x000001B125FF82B0>, 'Connection to api.telegram.org timed out. (connect timeout=5.0)')': /bot1433757250:AAEo4RDod8FFHlZw0bnbR_tHqzHWjYUistA/sendMessage
2021-01-14 02:52:21,663 - telegram.vendor.ptb_urllib3.urllib3.connectionpool - WARNING - Retrying (Retry(total=1, connect=None, read=None, redirect=None)) after connection broken by 'ConnectTimeoutError(<telegram.vendor.ptb_urllib3.urllib3.connection.VerifiedHTTPSConnection object at 0x0000014622E5F0D0>, 'Connection to api.telegram.org timed out. (connect timeout=5.0)')': /bot1433757250:AAEo4RDod8FFHlZw0bnbR_tHqzHWjYUistA/sendMessage
2021-01-14 02:52:24,106 - __main__ - ERROR - Бот столкнулся с ошибкой: urllib3 HTTPError HTTPSConnectionPool(host='api.telegram.org', port=443): Max retries exceeded with url: /bot1433757250:AAEo4RDod8FFHlZw0bnbR_tHqzHWjYUistA/sendMessage (Caused by ConnectTimeoutError(<telegram.vendor.ptb_urllib3.urllib3.connection.VerifiedHTTPSConnection object at 0x000001B125FF87F0>, 'Connection to api.telegram.org timed out. (connect timeout=5.0)'))
2021-01-14 02:52:26,672 - telegram.vendor.ptb_urllib3.urllib3.connectionpool - WARNING - Retrying (Retry(total=0, connect=None, read=None, redirect=None)) after connection broken by 'ConnectTimeoutError(<telegram.vendor.ptb_urllib3.urllib3.connection.VerifiedHTTPSConnection object at 0x0000014622E5F160>, 'Connection to api.telegram.org timed out. (connect timeout=5.0)')': /bot1433757250:AAEo4RDod8FFHlZw0bnbR_tHqzHWjYUistA/sendMessage
2021-01-14 02:52:30,478 - __main__ - INFO - Отправка сообщения в телеграм: У вас проверили работу "AnastasiaSar__api_sp1_bot.zip"!

К сожалению в работе нашлись ошибки.
2021-01-14 02:52:31,689 - __main__ - ERROR - Бот столкнулся с ошибкой: urllib3 HTTPError HTTPSConnectionPool(host='api.telegram.org', port=443): Max retries exceeded with url: /bot1433757250:AAEo4RDod8FFHlZw0bnbR_tHqzHWjYUistA/sendMessage (Caused by ConnectTimeoutError(<telegram.vendor.ptb_urllib3.urllib3.connection.VerifiedHTTPSConnection object at 0x0000014622E5FA60>, 'Connection to api.telegram.org timed out. (connect timeout=5.0)'))
2021-01-14 02:52:35,485 - telegram.vendor.ptb_urllib3.urllib3.connectionpool - WARNING - Retrying (Retry(total=2, connect=None, read=None, redirect=None)) after connection broken by 'ConnectTimeoutError(<telegram.vendor.ptb_urllib3.urllib3.connection.VerifiedHTTPSConnection object at 0x000001B125FADFA0>, 'Connection to api.telegram.org timed out. (connect timeout=5.0)')': /bot1433757250:AAEo4RDod8FFHlZw0bnbR_tHqzHWjYUistA/sendMessage
2021-01-14 02:52:37,952 - __main__ - INFO - Отправка сообщения в телеграм: У вас проверили работу "AnastasiaSar__api_sp1_bot.zip"!

К сожалению в работе нашлись ошибки.
2021-01-14 02:52:40,509 - telegram.vendor.ptb_urllib3.urllib3.connectionpool - WARNING - Retrying (Retry(total=1, connect=None, read=None, redirect=None)) after connection broken by 'ConnectTimeoutError(<telegram.vendor.ptb_urllib3.urllib3.connection.VerifiedHTTPSConnection object at 0x000001B125FAD940>, 'Connection to api.telegram.org timed out. (connect timeout=5.0)')': /bot1433757250:AAEo4RDod8FFHlZw0bnbR_tHqzHWjYUistA/sendMessage
2021-01-14 02:52:42,958 - telegram.vendor.ptb_urllib3.urllib3.connectionpool - WARNING - Retrying (Retry(total=2, connect=None, read=None, redirect=None)) after connection broken by 'ConnectTimeoutError(<telegram.vendor.ptb_urllib3.urllib3.connection.VerifiedHTTPSConnection object at 0x0000014622E5FA90>, 'Connection to api.telegram.org timed out. (connect timeout=5.0)')': /bot1433757250:AAEo4RDod8FFHlZw0bnbR_tHqzHWjYUistA/sendMessage
2021-01-14 02:52:45,512 - telegram.vendor.ptb_urllib3.urllib3.connectionpool - WARNING - Retrying (Retry(total=0, connect=None, read=None, redirect=None)) after connection broken by 'ConnectTimeoutError(<telegram.vendor.ptb_urllib3.urllib3.connection.VerifiedHTTPSConnection object at 0x000001B125FAD460>, 'Connection to api.telegram.org timed out. (connect timeout=5.0)')': /bot1433757250:AAEo4RDod8FFHlZw0bnbR_tHqzHWjYUistA/sendMessage
2021-01-14 02:52:47,969 - telegram.vendor.ptb_urllib3.urllib3.connectionpool - WARNING - Retrying (Retry(total=1, connect=None, read=None, redirect=None)) after connection broken by 'ConnectTimeoutError(<telegram.vendor.ptb_urllib3.urllib3.connection.VerifiedHTTPSConnection object at 0x0000014622E5F610>, 'Connection to api.telegram.org timed out. (connect timeout=5.0)')': /bot1433757250:AAEo4RDod8FFHlZw0bnbR_tHqzHWjYUistA/sendMessage
2021-01-14 02:52:50,525 - __main__ - ERROR - Бот столкнулся с ошибкой: urllib3 HTTPError HTTPSConnectionPool(host='api.telegram.org', port=443): Max retries exceeded with url: /bot1433757250:AAEo4RDod8FFHlZw0bnbR_tHqzHWjYUistA/sendMessage (Caused by ConnectTimeoutError(<telegram.vendor.ptb_urllib3.urllib3.connection.VerifiedHTTPSConnection object at 0x000001B125FADE50>, 'Connection to api.telegram.org timed out. (connect timeout=5.0)'))
2021-01-14 02:52:52,987 - telegram.vendor.ptb_urllib3.urllib3.connectionpool - WARNING - Retrying (Retry(total=0, connect=None, read=None, redirect=None)) after connection broken by 'ConnectTimeoutError(<telegram.vendor.ptb_urllib3.urllib3.connection.VerifiedHTTPSConnection object at 0x0000014622E5FC10>, 'Connection to api.telegram.org timed out. (connect timeout=5.0)')': /bot1433757250:AAEo4RDod8FFHlZw0bnbR_tHqzHWjYUistA/sendMessage
2021-01-14 02:52:56,708 - __main__ - INFO - Отправка сообщения в телеграм: У вас проверили работу "AnastasiaSar__api_sp1_bot.zip"!

К сожалению в работе нашлись ошибки.
2021-01-14 02:52:57,996 - __main__ - ERROR - Бот столкнулся с ошибкой: urllib3 HTTPError HTTPSConnectionPool(host='api.telegram.org', port=443): Max retries exceeded with url: /bot1433757250:AAEo4RDod8FFHlZw0bnbR_tHqzHWjYUistA/sendMessage (Caused by ConnectTimeoutError(<telegram.vendor.ptb_urllib3.urllib3.connection.VerifiedHTTPSConnection object at 0x0000014622E58A30>, 'Connection to api.telegram.org timed out. (connect timeout=5.0)'))
2021-01-14 02:53:01,711 - telegram.vendor.ptb_urllib3.urllib3.connectionpool - WARNING - Retrying (Retry(total=2, connect=None, read=None, redirect=None)) after connection broken by 'ConnectTimeoutError(<telegram.vendor.ptb_urllib3.urllib3.connection.VerifiedHTTPSConnection object at 0x000001B125FADEB0>, 'Connection to api.telegram.org timed out. (connect timeout=5.0)')': /bot1433757250:AAEo4RDod8FFHlZw0bnbR_tHqzHWjYUistA/sendMessage
2021-01-14 02:53:04,241 - __main__ - INFO - Отправка сообщения в телеграм: У вас проверили работу "AnastasiaSar__api_sp1_bot.zip"!

К сожалению в работе нашлись ошибки.
2021-01-14 02:53:06,723 - telegram.vendor.ptb_urllib3.urllib3.connectionpool - WARNING - Retrying (Retry(total=1, connect=None, read=None, redirect=None)) after connection broken by 'ConnectTimeoutError(<telegram.vendor.ptb_urllib3.urllib3.connection.VerifiedHTTPSConnection object at 0x000001B125FAD970>, 'Connection to api.telegram.org timed out. (connect timeout=5.0)')': /bot1433757250:AAEo4RDod8FFHlZw0bnbR_tHqzHWjYUistA/sendMessage
2021-01-14 02:53:09,254 - telegram.vendor.ptb_urllib3.urllib3.connectionpool - WARNING - Retrying (Retry(total=2, connect=None, read=None, redirect=None)) after connection broken by 'ConnectTimeoutError(<telegram.vendor.ptb_urllib3.urllib3.connection.VerifiedHTTPSConnection object at 0x0000014622E58160>, 'Connection to api.telegram.org timed out. (connect timeout=5.0)')': /bot1433757250:AAEo4RDod8FFHlZw0bnbR_tHqzHWjYUistA/sendMessage
2021-01-14 02:53:11,726 - telegram.vendor.ptb_urllib3.urllib3.connectionpool - WARNING - Retrying (Retry(total=0, connect=None, read=None, redirect=None)) after connection broken by 'ConnectTimeoutError(<telegram.vendor.ptb_urllib3.urllib3.connection.VerifiedHTTPSConnection object at 0x000001B125FAD610>, 'Connection to api.telegram.org timed out. (connect timeout=5.0)')': /bot1433757250:AAEo4RDod8FFHlZw0bnbR_tHqzHWjYUistA/sendMessage
2021-01-14 02:53:14,266 - telegram.vendor.ptb_urllib3.urllib3.connectionpool - WARNING - Retrying (Retry(total=1, connect=None, read=None, redirect=None)) after connection broken by 'ConnectTimeoutError(<telegram.vendor.ptb_urllib3.urllib3.connection.VerifiedHTTPSConnection object at 0x0000014622E589D0>, 'Connection to api.telegram.org timed out. (connect timeout=5.0)')': /bot1433757250:AAEo4RDod8FFHlZw0bnbR_tHqzHWjYUistA/sendMessage
2021-01-14 02:53:16,729 - __main__ - ERROR - Бот столкнулся с ошибкой: urllib3 HTTPError HTTPSConnectionPool(host='api.telegram.org', port=443): Max retries exceeded with url: /bot1433757250:AAEo4RDod8FFHlZw0bnbR_tHqzHWjYUistA/sendMessage (Caused by ConnectTimeoutError(<telegram.vendor.ptb_urllib3.urllib3.connection.VerifiedHTTPSConnection object at 0x000001B125FAD070>, 'Connection to api.telegram.org timed out. (connect timeout=5.0)'))
2021-01-14 02:53:19,269 - telegram.vendor.ptb_urllib3.urllib3.connectionpool - WARNING - Retrying (Retry(total=0, connect=None, read=None, redirect=None)) after connection broken by 'ConnectTimeoutError(<telegram.vendor.ptb_urllib3.urllib3.connection.VerifiedHTTPSConnection object at 0x0000014622E58340>, 'Connection to api.telegram.org timed out. (connect timeout=5.0)')': /bot1433757250:AAEo4RDod8FFHlZw0bnbR_tHqzHWjYUistA/sendMessage
2021-01-14 02:53:22,963 - __main__ - INFO - Отправка сообщения в телеграм: У вас проверили работу "AnastasiaSar__api_sp1_bot.zip"!

К сожалению в работе нашлись ошибки.
2021-01-14 02:53:24,273 - __main__ - ERROR - Бот столкнулся с ошибкой: urllib3 HTTPError HTTPSConnectionPool(host='api.telegram.org', port=443): Max retries exceeded with url: /bot1433757250:AAEo4RDod8FFHlZw0bnbR_tHqzHWjYUistA/sendMessage (Caused by ConnectTimeoutError(<telegram.vendor.ptb_urllib3.urllib3.connection.VerifiedHTTPSConnection object at 0x0000014622E58700>, 'Connection to api.telegram.org timed out. (connect timeout=5.0)'))
2021-01-14 02:53:27,967 - telegram.vendor.ptb_urllib3.urllib3.connectionpool - WARNING - Retrying (Retry(total=2, connect=None, read=None, redirect=None)) after connection broken by 'ConnectTimeoutError(<telegram.vendor.ptb_urllib3.urllib3.connection.VerifiedHTTPSConnection object at 0x000001B125FF8640>, 'Connection to api.telegram.org timed out. (connect timeout=5.0)')': /bot1433757250:AAEo4RDod8FFHlZw0bnbR_tHqzHWjYUistA/sendMessage
2021-01-14 02:53:30,567 - __main__ - INFO - Отправка сообщения в телеграм: У вас проверили работу "AnastasiaSar__api_sp1_bot.zip"!

К сожалению в работе нашлись ошибки.
2021-01-14 02:53:32,976 - telegram.vendor.ptb_urllib3.urllib3.connectionpool - WARNING - Retrying (Retry(total=1, connect=None, read=None, redirect=None)) after connection broken by 'ConnectTimeoutError(<telegram.vendor.ptb_urllib3.urllib3.connection.VerifiedHTTPSConnection object at 0x000001B125FF83D0>, 'Connection to api.telegram.org timed out. (connect timeout=5.0)')': /bot1433757250:AAEo4RDod8FFHlZw0bnbR_tHqzHWjYUistA/sendMessage
2021-01-14 02:53:35,574 - telegram.vendor.ptb_urllib3.urllib3.connectionpool - WARNING - Retrying (Retry(total=2, connect=None, read=None, redirect=None)) after connection broken by 'ConnectTimeoutError(<telegram.vendor.ptb_urllib3.urllib3.connection.VerifiedHTTPSConnection object at 0x0000014622E58070>, 'Connection to api.telegram.org timed out. (connect timeout=5.0)')': /bot1433757250:AAEo4RDod8FFHlZw0bnbR_tHqzHWjYUistA/sendMessage
2021-01-14 02:53:37,993 - telegram.vendor.ptb_urllib3.urllib3.connectionpool - WARNING - Retrying (Retry(total=0, connect=None, read=None, redirect=None)) after connection broken by 'ConnectTimeoutError(<telegram.vendor.ptb_urllib3.urllib3.connection.VerifiedHTTPSConnection object at 0x000001B125FF8160>, 'Connection to api.telegram.org timed out. (connect timeout=5.0)')': /bot1433757250:AAEo4RDod8FFHlZw0bnbR_tHqzHWjYUistA/sendMessage
2021-01-14 02:53:40,586 - telegram.vendor.ptb_urllib3.urllib3.connectionpool - WARNING - Retrying (Retry(total=1, connect=None, read=None, redirect=None)) after connection broken by 'ConnectTimeoutError(<telegram.vendor.ptb_urllib3.urllib3.connection.VerifiedHTTPSConnection object at 0x0000014622E58C70>, 'Connection to api.telegram.org timed out. (connect timeout=5.0)')': /bot1433757250:AAEo4RDod8FFHlZw0bnbR_tHqzHWjYUistA/sendMessage
2021-01-14 02:53:42,996 - __main__ - ERROR - Бот столкнулся с ошибкой: urllib3 HTTPError HTTPSConnectionPool(host='api.telegram.org', port=443): Max retries exceeded with url: /bot1433757250:AAEo4RDod8FFHlZw0bnbR_tHqzHWjYUistA/sendMessage (Caused by ConnectTimeoutError(<telegram.vendor.ptb_urllib3.urllib3.connection.VerifiedHTTPSConnection object at 0x000001B125FF8880>, 'Connection to api.telegram.org timed out. (connect timeout=5.0)'))
2021-01-14 02:53:45,600 - telegram.vendor.ptb_urllib3.urllib3.connectionpool - WARNING - Retrying (Retry(total=0, connect=None, read=None, redirect=None)) after connection broken by 'ConnectTimeoutError(<telegram.vendor.ptb_urllib3.urllib3.connection.VerifiedHTTPSConnection object at 0x0000014622E58520>, 'Connection to api.telegram.org timed out. (connect timeout=5.0)')': /bot1433757250:AAEo4RDod8FFHlZw0bnbR_tHqzHWjYUistA/sendMessage
2021-01-14 02:53:49,212 - __main__ - INFO - Отправка сообщения в телеграм: У вас проверили работу "AnastasiaSar__api_sp1_bot.zip"!

К сожалению в работе нашлись ошибки.
2021-01-14 02:53:50,616 - __main__ - ERROR - Бот столкнулся с ошибкой: urllib3 HTTPError HTTPSConnectionPool(host='api.telegram.org', port=443): Max retries exceeded with url: /bot1433757250:AAEo4RDod8FFHlZw0bnbR_tHqzHWjYUistA/sendMessage (Caused by ConnectTimeoutError(<telegram.vendor.ptb_urllib3.urllib3.connection.VerifiedHTTPSConnection object at 0x0000014622E58D90>, 'Connection to api.telegram.org timed out. (connect timeout=5.0)'))
2021-01-14 02:53:54,224 - telegram.vendor.ptb_urllib3.urllib3.connectionpool - WARNING - Retrying (Retry(total=2, connect=None, read=None, redirect=None)) after connection broken by 'ConnectTimeoutError(<telegram.vendor.ptb_urllib3.urllib3.connection.VerifiedHTTPSConnection object at 0x000001B125FF8CA0>, 'Connection to api.telegram.org timed out. (connect timeout=5.0)')': /bot1433757250:AAEo4RDod8FFHlZw0bnbR_tHqzHWjYUistA/sendMessage
2021-01-14 02:53:56,862 - __main__ - INFO - Отправка сообщения в телеграм: У вас проверили работу "AnastasiaSar__api_sp1_bot.zip"!

К сожалению в работе нашлись ошибки.
2021-01-14 02:53:59,241 - telegram.vendor.ptb_urllib3.urllib3.connectionpool - WARNING - Retrying (Retry(total=1, connect=None, read=None, redirect=None)) after connection broken by 'ConnectTimeoutError(<telegram.vendor.ptb_urllib3.urllib3.connection.VerifiedHTTPSConnection object at 0x000001B125FF8A90>, 'Connection to api.telegram.org timed out. (connect timeout=5.0)')': /bot1433757250:AAEo4RDod8FFHlZw0bnbR_tHqzHWjYUistA/sendMessage
2021-01-14 02:54:01,867 - telegram.vendor.ptb_urllib3.urllib3.connectionpool - WARNING - Retrying (Retry(total=2, connect=None, read=None, redirect=None)) after connection broken by 'ConnectTimeoutError(<telegram.vendor.ptb_urllib3.urllib3.connection.VerifiedHTTPSConnection object at 0x0000014622E58190>, 'Connection to api.telegram.org timed out. (connect timeout=5.0)')': /bot1433757250:AAEo4RDod8FFHlZw0bnbR_tHqzHWjYUistA/sendMessage
2021-01-14 02:54:04,245 - telegram.vendor.ptb_urllib3.urllib3.connectionpool - WARNING - Retrying (Retry(total=0, connect=None, read=None, redirect=None)) after connection broken by 'ConnectTimeoutError(<telegram.vendor.ptb_urllib3.urllib3.connection.VerifiedHTTPSConnection object at 0x000001B125FF88B0>, 'Connection to api.telegram.org timed out. (connect timeout=5.0)')': /bot1433757250:AAEo4RDod8FFHlZw0bnbR_tHqzHWjYUistA/sendMessage
2021-01-14 02:54:06,874 - telegram.vendor.ptb_urllib3.urllib3.connectionpool - WARNING - Retrying (Retry(total=1, connect=None, read=None, redirect=None)) after connection broken by 'ConnectTimeoutError(<telegram.vendor.ptb_urllib3.urllib3.connection.VerifiedHTTPSConnection object at 0x0000014622E0B3A0>, 'Connection to api.telegram.org timed out. (connect timeout=5.0)')': /bot1433757250:AAEo4RDod8FFHlZw0bnbR_tHqzHWjYUistA/sendMessage
2021-01-14 02:54:09,255 - __main__ - ERROR - Бот столкнулся с ошибкой: urllib3 HTTPError HTTPSConnectionPool(host='api.telegram.org', port=443): Max retries exceeded with url: /bot1433757250:AAEo4RDod8FFHlZw0bnbR_tHqzHWjYUistA/sendMessage (Caused by ConnectTimeoutError(<telegram.vendor.ptb_urllib3.urllib3.connection.VerifiedHTTPSConnection object at 0x000001B125FF86D0>, 'Connection to api.telegram.org timed out. (connect timeout=5.0)'))
2021-01-14 02:54:11,880 - telegram.vendor.ptb_urllib3.urllib3.connectionpool - WARNING - Retrying (Retry(total=0, connect=None, read=None, redirect=None)) after connection broken by 'ConnectTimeoutError(<telegram.vendor.ptb_urllib3.urllib3.connection.VerifiedHTTPSConnection object at 0x0000014622E0B850>, 'Connection to api.telegram.org timed out. (connect timeout=5.0)')': /bot1433757250:AAEo4RDod8FFHlZw0bnbR_tHqzHWjYUistA/sendMessage
2021-01-14 02:54:15,543 - __main__ - INFO - Отправка сообщения в телеграм: У вас проверили работу "AnastasiaSar__api_sp1_bot.zip"!

К сожалению в работе нашлись ошибки.
2021-01-14 02:54:16,891 - __main__ - ERROR - Бот столкнулся с ошибкой: urllib3 HTTPError HTTPSConnectionPool(host='api.telegram.org', port=443): Max retries exceeded with url: /bot1433757250:AAEo4RDod8FFHlZw0bnbR_tHqzHWjYUistA/sendMessage (Caused by ConnectTimeoutError(<telegram.vendor.ptb_urllib3.urllib3.connection.VerifiedHTTPSConnection object at 0x0000014622E0B250>, 'Connection to api.telegram.org timed out. (connect timeout=5.0)'))
2021-01-14 02:54:20,548 - telegram.vendor.ptb_urllib3.urllib3.connectionpool - WARNING - Retrying (Retry(total=2, connect=None, read=None, redirect=None)) after connection broken by 'ConnectTimeoutError(<telegram.vendor.ptb_urllib3.urllib3.connection.VerifiedHTTPSConnection object at 0x000001B125FF8820>, 'Connection to api.telegram.org timed out. (connect timeout=5.0)')': /bot1433757250:AAEo4RDod8FFHlZw0bnbR_tHqzHWjYUistA/sendMessage
2021-01-14 02:54:23,166 - __main__ - INFO - Отправка сообщения в телеграм: У вас проверили работу "AnastasiaSar__api_sp1_bot.zip"!

К сожалению в работе нашлись ошибки.
2021-01-14 02:54:25,562 - telegram.vendor.ptb_urllib3.urllib3.connectionpool - WARNING - Retrying (Retry(total=1, connect=None, read=None, redirect=None)) after connection broken by 'ConnectTimeoutError(<telegram.vendor.ptb_urllib3.urllib3.connection.VerifiedHTTPSConnection object at 0x000001B125FFF0A0>, 'Connection to api.telegram.org timed out. (connect timeout=5.0)')': /bot1433757250:AAEo4RDod8FFHlZw0bnbR_tHqzHWjYUistA/sendMessage
2021-01-14 02:54:28,181 - telegram.vendor.ptb_urllib3.urllib3.connectionpool - WARNING - Retrying (Retry(total=2, connect=None, read=None, redirect=None)) after connection broken by 'ConnectTimeoutError(<telegram.vendor.ptb_urllib3.urllib3.connection.VerifiedHTTPSConnection object at 0x0000014622E0B610>, 'Connection to api.telegram.org timed out. (connect timeout=5.0)')': /bot1433757250:AAEo4RDod8FFHlZw0bnbR_tHqzHWjYUistA/sendMessage
2021-01-14 02:54:30,578 - telegram.vendor.ptb_urllib3.urllib3.connectionpool - WARNING - Retrying (Retry(total=0, connect=None, read=None, redirect=None)) after connection broken by 'ConnectTimeoutError(<telegram.vendor.ptb_urllib3.urllib3.connection.VerifiedHTTPSConnection object at 0x000001B125FFF130>, 'Connection to api.telegram.org timed out. (connect timeout=5.0)')': /bot1433757250:AAEo4RDod8FFHlZw0bnbR_tHqzHWjYUistA/sendMessage
2021-01-14 02:54:33,186 - telegram.vendor.ptb_urllib3.urllib3.connectionpool - WARNING - Retrying (Retry(total=1, connect=None, read=None, redirect=None)) after connection broken by 'ConnectTimeoutError(<telegram.vendor.ptb_urllib3.urllib3.connection.VerifiedHTTPSConnection object at 0x0000014622E0B0D0>, 'Connection to api.telegram.org timed out. (connect timeout=5.0)')': /bot1433757250:AAEo4RDod8FFHlZw0bnbR_tHqzHWjYUistA/sendMessage
2021-01-14 02:54:35,587 - __main__ - ERROR - Бот столкнулся с ошибкой: urllib3 HTTPError HTTPSConnectionPool(host='api.telegram.org', port=443): Max retries exceeded with url: /bot1433757250:AAEo4RDod8FFHlZw0bnbR_tHqzHWjYUistA/sendMessage (Caused by ConnectTimeoutError(<telegram.vendor.ptb_urllib3.urllib3.connection.VerifiedHTTPSConnection object at 0x000001B125FFFA30>, 'Connection to api.telegram.org timed out. (connect timeout=5.0)'))
2021-01-14 02:54:38,195 - telegram.vendor.ptb_urllib3.urllib3.connectionpool - WARNING - Retrying (Retry(total=0, connect=None, read=None, redirect=None)) after connection broken by 'ConnectTimeoutError(<telegram.vendor.ptb_urllib3.urllib3.connection.VerifiedHTTPSConnection object at 0x0000014622E0B6A0>, 'Connection to api.telegram.org timed out. (connect timeout=5.0)')': /bot1433757250:AAEo4RDod8FFHlZw0bnbR_tHqzHWjYUistA/sendMessage
2021-01-14 02:54:41,787 - __main__ - INFO - Отправка сообщения в телеграм: У вас проверили работу "AnastasiaSar__api_sp1_bot.zip"!

К сожалению в работе нашлись ошибки.
2021-01-14 02:54:43,210 - __main__ - ERROR - Бот столкнулся с ошибкой: urllib3 HTTPError HTTPSConnectionPool(host='api.telegram.org', port=443): Max retries exceeded with url: /bot1433757250:AAEo4RDod8FFHlZw0bnbR_tHqzHWjYUistA/sendMessage (Caused by ConnectTimeoutError(<telegram.vendor.ptb_urllib3.urllib3.connection.VerifiedHTTPSConnection object at 0x0000014622E0B7C0>, 'Connection to api.telegram.org timed out. (connect timeout=5.0)'))
2021-01-14 02:54:46,804 - telegram.vendor.ptb_urllib3.urllib3.connectionpool - WARNING - Retrying (Retry(total=2, connect=None, read=None, redirect=None)) after connection broken by 'ConnectTimeoutError(<telegram.vendor.ptb_urllib3.urllib3.connection.VerifiedHTTPSConnection object at 0x000001B125FFFA60>, 'Connection to api.telegram.org timed out. (connect timeout=5.0)')': /bot1433757250:AAEo4RDod8FFHlZw0bnbR_tHqzHWjYUistA/sendMessage
2021-01-14 02:54:49,468 - __main__ - INFO - Отправка сообщения в телеграм: У вас проверили работу "AnastasiaSar__api_sp1_bot.zip"!

К сожалению в работе нашлись ошибки.
2021-01-14 02:54:51,820 - telegram.vendor.ptb_urllib3.urllib3.connectionpool - WARNING - Retrying (Retry(total=1, connect=None, read=None, redirect=None)) after connection broken by 'ConnectTimeoutError(<telegram.vendor.ptb_urllib3.urllib3.connection.VerifiedHTTPSConnection object at 0x000001B125FFF5E0>, 'Connection to api.telegram.org timed out. (connect timeout=5.0)')': /bot1433757250:AAEo4RDod8FFHlZw0bnbR_tHqzHWjYUistA/sendMessage
2021-01-14 02:54:54,479 - telegram.vendor.ptb_urllib3.urllib3.connectionpool - WARNING - Retrying (Retry(total=2, connect=None, read=None, redirect=None)) after connection broken by 'ConnectTimeoutError(<telegram.vendor.ptb_urllib3.urllib3.connection.VerifiedHTTPSConnection object at 0x0000014622E5F340>, 'Connection to api.telegram.org timed out. (connect timeout=5.0)')': /bot1433757250:AAEo4RDod8FFHlZw0bnbR_tHqzHWjYUistA/sendMessage
2021-01-14 02:54:56,824 - telegram.vendor.ptb_urllib3.urllib3.connectionpool - WARNING - Retrying (Retry(total=0, connect=None, read=None, redirect=None)) after connection broken by 'ConnectTimeoutError(<telegram.vendor.ptb_urllib3.urllib3.connection.VerifiedHTTPSConnection object at 0x000001B125FFFBE0>, 'Connection to api.telegram.org timed out. (connect timeout=5.0)')': /bot1433757250:AAEo4RDod8FFHlZw0bnbR_tHqzHWjYUistA/sendMessage
2021-01-14 02:54:59,480 - telegram.vendor.ptb_urllib3.urllib3.connectionpool - WARNING - Retrying (Retry(total=1, connect=None, read=None, redirect=None)) after connection broken by 'ConnectTimeoutError(<telegram.vendor.ptb_urllib3.urllib3.connection.VerifiedHTTPSConnection object at 0x0000014622E5FF70>, 'Connection to api.telegram.org timed out. (connect timeout=5.0)')': /bot1433757250:AAEo4RDod8FFHlZw0bnbR_tHqzHWjYUistA/sendMessage
2021-01-14 02:55:01,841 - __main__ - ERROR - Бот столкнулся с ошибкой: urllib3 HTTPError HTTPSConnectionPool(host='api.telegram.org', port=443): Max retries exceeded with url: /bot1433757250:AAEo4RDod8FFHlZw0bnbR_tHqzHWjYUistA/sendMessage (Caused by ConnectTimeoutError(<telegram.vendor.ptb_urllib3.urllib3.connection.VerifiedHTTPSConnection object at 0x000001B125FF8190>, 'Connection to api.telegram.org timed out. (connect timeout=5.0)'))
2021-01-14 02:55:04,489 - telegram.vendor.ptb_urllib3.urllib3.connectionpool - WARNING - Retrying (Retry(total=0, connect=None, read=None, redirect=None)) after connection broken by 'ConnectTimeoutError(<telegram.vendor.ptb_urllib3.urllib3.connection.VerifiedHTTPSConnection object at 0x0000014622E5FB80>, 'Connection to api.telegram.org timed out. (connect timeout=5.0)')': /bot1433757250:AAEo4RDod8FFHlZw0bnbR_tHqzHWjYUistA/sendMessage
2021-01-14 02:55:09,492 - __main__ - ERROR - Бот столкнулся с ошибкой: urllib3 HTTPError HTTPSConnectionPool(host='api.telegram.org', port=443): Max retries exceeded with url: /bot1433757250:AAEo4RDod8FFHlZw0bnbR_tHqzHWjYUistA/sendMessage (Caused by ConnectTimeoutError(<telegram.vendor.ptb_urllib3.urllib3.connection.VerifiedHTTPSConnection object at 0x0000014622E5F2B0>, 'Connection to api.telegram.org timed out. (connect timeout=5.0)'))
2021-01-14 02:55:10,749 - __main__ - INFO - Отправка сообщения в телеграм: У вас проверили работу "AnastasiaSar__api_sp1_bot.zip"!

К сожалению в работе нашлись ошибки.
2021-01-14 02:55:15,765 - telegram.vendor.ptb_urllib3.urllib3.connectionpool - WARNING - Retrying (Retry(total=2, connect=None, read=None, redirect=None)) after connection broken by 'ConnectTimeoutError(<telegram.vendor.ptb_urllib3.urllib3.connection.VerifiedHTTPSConnection object at 0x000001B125FF8790>, 'Connection to api.telegram.org timed out. (connect timeout=5.0)')': /bot1433757250:AAEo4RDod8FFHlZw0bnbR_tHqzHWjYUistA/sendMessage
2021-01-14 02:55:15,769 - __main__ - INFO - Отправка сообщения в телеграм: У вас проверили работу "AnastasiaSar__api_sp1_bot.zip"!

К сожалению в работе нашлись ошибки.
2021-01-14 02:55:20,776 - telegram.vendor.ptb_urllib3.urllib3.connectionpool - WARNING - Retrying (Retry(total=1, connect=None, read=None, redirect=None)) after connection broken by 'ConnectTimeoutError(<telegram.vendor.ptb_urllib3.urllib3.connection.VerifiedHTTPSConnection object at 0x000001B125FF8C10>, 'Connection to api.telegram.org timed out. (connect timeout=5.0)')': /bot1433757250:AAEo4RDod8FFHlZw0bnbR_tHqzHWjYUistA/sendMessage
2021-01-14 02:55:25,783 - telegram.vendor.ptb_urllib3.urllib3.connectionpool - WARNING - Retrying (Retry(total=0, connect=None, read=None, redirect=None)) after connection broken by 'ConnectTimeoutError(<telegram.vendor.ptb_urllib3.urllib3.connection.VerifiedHTTPSConnection object at 0x000001B125FF85B0>, 'Connection to api.telegram.org timed out. (connect timeout=5.0)')': /bot1433757250:AAEo4RDod8FFHlZw0bnbR_tHqzHWjYUistA/sendMessage
2021-01-14 02:55:30,789 - telegram.vendor.ptb_urllib3.urllib3.connectionpool - WARNING - Retrying (Retry(total=0, connect=None, read=None, redirect=None)) after connection broken by 'ConnectTimeoutError(<telegram.vendor.ptb_urllib3.urllib3.connection.VerifiedHTTPSConnection object at 0x0000014622E5F730>, 'Connection to api.telegram.org timed out. (connect timeout=5.0)')': /bot1433757250:AAEo4RDod8FFHlZw0bnbR_tHqzHWjYUistA/sendMessage
)
2021-01-14 02:55:35,791 - __main__ - ERROR - Бот столкнулся с ошибкой: urllib3 HTTPError HTTPSConnectionPool(host='api.telegram.org', port=443): Max retries exceeded with url: /bot1433757250:AAEo4RDod8FFHlZw0bnbR_tHqzHWjYUistA/sendMessage (Caused by ConnectTimeoutError(<telegram.vendor.ptb_urllib3.urllib3.connection.VerifiedHTTPSConnection object at 0x0000014622E5F700>, 'Connection to api.telegram.org timed out. (connect timeout=5.0)'))
2021-01-14 02:55:37,076 - __main__ - INFO - Отправка сообщения в телеграм: У вас проверили работу "AnastasiaSar__api_sp1_bot.zip"!

К сожалению в работе нашлись ошибки.
2021-01-14 02:55:42,077 - __main__ - INFO - Отправка сообщения в телеграм: У вас проверили работу "AnastasiaSar__api_sp1_bot.zip"!

К сожалению в работе нашлись ошибки.
2021-01-14 02:55:42,084 - telegram.vendor.ptb_urllib3.urllib3.connectionpool - WARNING - Retrying (Retry(total=2, connect=None, read=None, redirect=None)) after connection broken by 'ConnectTimeoutError(<telegram.vendor.ptb_urllib3.urllib3.connection.VerifiedHTTPSConnection object at 0x000001B125FF8700>, 'Connection to api.telegram.org timed out. (connect timeout=5.0)')': /bot1433757250:AAEo4RDod8FFHlZw0bnbR_tHqzHWjYUistA/sendMessage
2021-01-14 02:55:47,081 - telegram.vendor.ptb_urllib3.urllib3.connectionpool - WARNING - Retrying (Retry(total=2, connect=None, read=None, redirect=None)) after connection broken by 'ConnectTimeoutError(<telegram.vendor.ptb_urllib3.urllib3.connection.VerifiedHTTPSConnection object at 0x0000014622E0B7C0>, 'Connection to api.telegram.org timed out. (connect timeout=5.0)')': /bot1433757250:AAEo4RDod8FFHlZw0bnbR_tHqzHWjYUistA/sendMessage
2021-01-14 02:55:47,096 - telegram.vendor.ptb_urllib3.urllib3.connectionpool - WARNING - Retrying (Retry(total=1, connect=None, read=None, redirect=None)) after connection broken by 'ConnectTimeoutError(<telegram.vendor.ptb_urllib3.urllib3.connection.VerifiedHTTPSConnection object at 0x000001B125FF8CA0>, 'Connection to api.telegram.org timed out. (connect timeout=5.0)')': /bot1433757250:AAEo4RDod8FFHlZw0bnbR_tHqzHWjYUistA/sendMessage
2021-01-14 02:55:52,087 - telegram.vendor.ptb_urllib3.urllib3.connectionpool - WARNING - Retrying (Retry(total=1, connect=None, read=None, redirect=None)) after connection broken by 'ConnectTimeoutError(<telegram.vendor.ptb_urllib3.urllib3.connection.VerifiedHTTPSConnection object at 0x0000014622E0B580>, 'Connection to api.telegram.org timed out. (connect timeout=5.0)')': /bot1433757250:AAEo4RDod8FFHlZw0bnbR_tHqzHWjYUistA/sendMessage
2021-01-14 02:55:52,103 - telegram.vendor.ptb_urllib3.urllib3.connectionpool - WARNING - Retrying (Retry(total=0, connect=None, read=None, redirect=None)) after connection broken by 'ConnectTimeoutError(<telegram.vendor.ptb_urllib3.urllib3.connection.VerifiedHTTPSConnection object at 0x000001B125FF8D90>, 'Connection to api.telegram.org timed out. (connect timeout=5.0)')': /bot1433757250:AAEo4RDod8FFHlZw0bnbR_tHqzHWjYUistA/sendMessage
2021-01-14 02:55:57,098 - telegram.vendor.ptb_urllib3.urllib3.connectionpool - WARNING - Retrying (Retry(total=0, connect=None, read=None, redirect=None)) after connection broken by 'ConnectTimeoutError(<telegram.vendor.ptb_urllib3.urllib3.connection.VerifiedHTTPSConnection object at 0x0000014622E0B340>, 'Connection to api.telegram.org timed out. (connect timeout=5.0)')': /bot1433757250:AAEo4RDod8FFHlZw0bnbR_tHqzHWjYUistA/sendMessage
2021-01-14 02:55:57,114 - __main__ - ERROR - Бот столкнулся с ошибкой: urllib3 HTTPError HTTPSConnectionPool(host='api.telegram.org', port=443): Max retries exceeded with url: /bot1433757250:AAEo4RDod8FFHlZw0bnbR_tHqzHWjYUistA/sendMessage (Caused by ConnectTimeoutError(<telegram.vendor.ptb_urllib3.urllib3.connection.VerifiedHTTPSConnection object at 0x000001B125FF8F40>, 'Connection to api.telegram.org timed out. (connect timeout=5.0)'))
2021-01-14 02:56:02,102 - __main__ - ERROR - Бот столкнулся с ошибкой: urllib3 HTTPError HTTPSConnectionPool(host='api.telegram.org', port=443): Max retries exceeded with url: /bot1433757250:AAEo4RDod8FFHlZw0bnbR_tHqzHWjYUistA/sendMessage (Caused by ConnectTimeoutError(<telegram.vendor.ptb_urllib3.urllib3.connection.VerifiedHTTPSConnection object at 0x0000014622E0B370>, 'Connection to api.telegram.org timed out. (connect timeout=5.0)'))
2021-01-14 02:56:03,402 - __main__ - INFO - Отправка сообщения в телеграм: У вас проверили работу "AnastasiaSar__api_sp1_bot.zip"!

К сожалению в работе нашлись ошибки.
2021-01-14 02:56:08,364 - __main__ - INFO - Отправка сообщения в телеграм: У вас проверили работу "AnastasiaSar__api_sp1_bot.zip"!

К сожалению в работе нашлись ошибки.
2021-01-14 02:56:08,412 - telegram.vendor.ptb_urllib3.urllib3.connectionpool - WARNING - Retrying (Retry(total=2, connect=None, read=None, redirect=None)) after connection broken by 'ConnectTimeoutError(<telegram.vendor.ptb_urllib3.urllib3.connection.VerifiedHTTPSConnection object at 0x000001B125FAD6A0>, 'Connection to api.telegram.org timed out. (connect timeout=5.0)')': /bot1433757250:AAEo4RDod8FFHlZw0bnbR_tHqzHWjYUistA/sendMessage
2021-01-14 02:56:13,371 - telegram.vendor.ptb_urllib3.urllib3.connectionpool - WARNING - Retrying (Retry(total=2, connect=None, read=None, redirect=None)) after connection broken by 'ConnectTimeoutError(<telegram.vendor.ptb_urllib3.urllib3.connection.VerifiedHTTPSConnection object at 0x0000014622E0B220>, 'Connection to api.telegram.org timed out. (connect timeout=5.0)')': /bot1433757250:AAEo4RDod8FFHlZw0bnbR_tHqzHWjYUistA/sendMessage
2021-01-14 02:56:13,418 - telegram.vendor.ptb_urllib3.urllib3.connectionpool - WARNING - Retrying (Retry(total=1, connect=None, read=None, redirect=None)) after connection broken by 'ConnectTimeoutError(<telegram.vendor.ptb_urllib3.urllib3.connection.VerifiedHTTPSConnection object at 0x000001B125FAD910>, 'Connection to api.telegram.org timed out. (connect timeout=5.0)')': /bot1433757250:AAEo4RDod8FFHlZw0bnbR_tHqzHWjYUistA/sendMessage
2021-01-14 02:56:18,383 - telegram.vendor.ptb_urllib3.urllib3.connectionpool - WARNING - Retrying (Retry(total=1, connect=None, read=None, redirect=None)) after connection broken by 'ConnectTimeoutError(<telegram.vendor.ptb_urllib3.urllib3.connection.VerifiedHTTPSConnection object at 0x0000014622E0B6A0>, 'Connection to api.telegram.org timed out. (connect timeout=5.0)')': /bot1433757250:AAEo4RDod8FFHlZw0bnbR_tHqzHWjYUistA/sendMessage
2021-01-14 02:56:18,430 - telegram.vendor.ptb_urllib3.urllib3.connectionpool - WARNING - Retrying (Retry(total=0, connect=None, read=None, redirect=None)) after connection broken by 'ConnectTimeoutError(<telegram.vendor.ptb_urllib3.urllib3.connection.VerifiedHTTPSConnection object at 0x000001B125FAD460>, 'Connection to api.telegram.org timed out. (connect timeout=5.0)')': /bot1433757250:AAEo4RDod8FFHlZw0bnbR_tHqzHWjYUistA/sendMessage
2021-01-14 02:56:23,387 - telegram.vendor.ptb_urllib3.urllib3.connectionpool - WARNING - Retrying (Retry(total=0, connect=None, read=None, redirect=None)) after connection broken by 'ConnectTimeoutError(<telegram.vendor.ptb_urllib3.urllib3.connection.VerifiedHTTPSConnection object at 0x0000014622E0BF10>, 'Connection to api.telegram.org timed out. (connect timeout=5.0)')': /bot1433757250:AAEo4RDod8FFHlZw0bnbR_tHqzHWjYUistA/sendMessage
2021-01-14 02:56:23,434 - __main__ - ERROR - Бот столкнулся с ошибкой: urllib3 HTTPError HTTPSConnectionPool(host='api.telegram.org', port=443): Max retries exceeded with url: /bot1433757250:AAEo4RDod8FFHlZw0bnbR_tHqzHWjYUistA/sendMessage (Caused by ConnectTimeoutError(<telegram.vendor.ptb_urllib3.urllib3.connection.VerifiedHTTPSConnection object at 0x000001B125FAD6D0>, 'Connection to api.telegram.org timed out. (connect timeout=5.0)'))
2021-01-14 02:56:28,401 - __main__ - ERROR - Бот столкнулся с ошибкой: urllib3 HTTPError HTTPSConnectionPool(host='api.telegram.org', port=443): Max retries exceeded with url: /bot1433757250:AAEo4RDod8FFHlZw0bnbR_tHqzHWjYUistA/sendMessage (Caused by ConnectTimeoutError(<telegram.vendor.ptb_urllib3.urllib3.connection.VerifiedHTTPSConnection object at 0x0000014622E580A0>, 'Connection to api.telegram.org timed out. (connect timeout=5.0)'))
2021-01-14 02:56:29,581 - __main__ - INFO - Отправка сообщения в телеграм: У вас проверили работу "AnastasiaSar__api_sp1_bot.zip"!

К сожалению в работе нашлись ошибки.
2021-01-14 02:56:34,587 - telegram.vendor.ptb_urllib3.urllib3.connectionpool - WARNING - Retrying (Retry(total=2, connect=None, read=None, redirect=None)) after connection broken by 'ConnectTimeoutError(<telegram.vendor.ptb_urllib3.urllib3.connection.VerifiedHTTPSConnection object at 0x000001B125FAD730>, 'Connection to api.telegram.org timed out. (connect timeout=5.0)')': /bot1433757250:AAEo4RDod8FFHlZw0bnbR_tHqzHWjYUistA/sendMessage
2021-01-14 02:56:34,607 - __main__ - INFO - Отправка сообщения в телеграм: У вас проверили работу "AnastasiaSar__api_sp1_bot.zip"!

К сожалению в работе нашлись ошибки.
2021-01-14 02:56:39,593 - telegram.vendor.ptb_urllib3.urllib3.connectionpool - WARNING - Retrying (Retry(total=1, connect=None, read=None, redirect=None)) after connection broken by 'ConnectTimeoutError(<telegram.vendor.ptb_urllib3.urllib3.connection.VerifiedHTTPSConnection object at 0x000001B125FAD5E0>, 'Connection to api.telegram.org timed out. (connect timeout=5.0)')': /bot1433757250:AAEo4RDod8FFHlZw0bnbR_tHqzHWjYUistA/sendMessage
2021-01-14 02:56:39,608 - telegram.vendor.ptb_urllib3.urllib3.connectionpool - WARNING - Retrying (Retry(total=2, connect=None, read=None, redirect=None)) after connection broken by 'ConnectTimeoutError(<telegram.vendor.ptb_urllib3.urllib3.connection.VerifiedHTTPSConnection object at 0x0000014622E58D60>, 'Connection to api.telegram.org timed out. (connect timeout=5.0)')': /bot1433757250:AAEo4RDod8FFHlZw0bnbR_tHqzHWjYUistA/sendMessage
2021-01-14 02:56:44,606 - telegram.vendor.ptb_urllib3.urllib3.connectionpool - WARNING - Retrying (Retry(total=0, connect=None, read=None, redirect=None)) after connection broken by 'ConnectTimeoutError(<telegram.vendor.ptb_urllib3.urllib3.connection.VerifiedHTTPSConnection object at 0x000001B125FADFA0>, 'Connection to api.telegram.org timed out. (connect timeout=5.0)')': /bot1433757250:AAEo4RDod8FFHlZw0bnbR_tHqzHWjYUistA/sendMessage
2021-01-14 02:56:44,621 - telegram.vendor.ptb_urllib3.urllib3.connectionpool - WARNING - Retrying (Retry(total=1, connect=None, read=None, redirect=None)) after connection broken by 'ConnectTimeoutError(<telegram.vendor.ptb_urllib3.urllib3.connection.VerifiedHTTPSConnection object at 0x0000014622E58550>, 'Connection to api.telegram.org timed out. (connect timeout=5.0)')': /bot1433757250:AAEo4RDod8FFHlZw0bnbR_tHqzHWjYUistA/sendMessage
2021-01-14 02:56:49,610 - __main__ - ERROR - Бот столкнулся с ошибкой: urllib3 HTTPError HTTPSConnectionPool(host='api.telegram.org', port=443): Max retries exceeded with url: /bot1433757250:AAEo4RDod8FFHlZw0bnbR_tHqzHWjYUistA/sendMessage (Caused by ConnectTimeoutError(<telegram.vendor.ptb_urllib3.urllib3.connection.VerifiedHTTPSConnection object at 0x000001B125FADDF0>, 'Connection to api.telegram.org timed out. (connect timeout=5.0)'))
2021-01-14 02:56:49,625 - telegram.vendor.ptb_urllib3.urllib3.connectionpool - WARNING - Retrying (Retry(total=0, connect=None, read=None, redirect=None)) after connection broken by 'ConnectTimeoutError(<telegram.vendor.ptb_urllib3.urllib3.connection.VerifiedHTTPSConnection object at 0x0000014622E58730>, 'Connection to api.telegram.org timed out. (connect timeout=5.0)')': /bot1433757250:AAEo4RDod8FFHlZw0bnbR_tHqzHWjYUistA/sendMessage
2021-01-14 02:56:54,641 - __main__ - ERROR - Бот столкнулся с ошибкой: urllib3 HTTPError HTTPSConnectionPool(host='api.telegram.org', port=443): Max retries exceeded with url: /bot1433757250:AAEo4RDod8FFHlZw0bnbR_tHqzHWjYUistA/sendMessage (Caused by ConnectTimeoutError(<telegram.vendor.ptb_urllib3.urllib3.connection.VerifiedHTTPSConnection object at 0x0000014622E58130>, 'Connection to api.telegram.org timed out. (connect timeout=5.0)'))
2021-01-14 02:56:56,359 - __main__ - INFO - Отправка сообщения в телеграм: У вас проверили работу "AnastasiaSar__api_sp1_bot.zip"!

К сожалению в работе нашлись ошибки.
2021-01-14 02:57:00,969 - __main__ - INFO - Отправка сообщения в телеграм: У вас проверили работу "AnastasiaSar__api_sp1_bot.zip"!

К сожалению в работе нашлись ошибки.
2021-01-14 02:57:01,374 - telegram.vendor.ptb_urllib3.urllib3.connectionpool - WARNING - Retrying (Retry(total=2, connect=None, read=None, redirect=None)) after connection broken by 'ConnectTimeoutError(<telegram.vendor.ptb_urllib3.urllib3.connection.VerifiedHTTPSConnection object at 0x000001B125FFFA30>, 'Connection to api.telegram.org timed out. (connect timeout=5.0)')': /bot1433757250:AAEo4RDod8FFHlZw0bnbR_tHqzHWjYUistA/sendMessage
2021-01-14 02:57:05,975 - telegram.vendor.ptb_urllib3.urllib3.connectionpool - WARNING - Retrying (Retry(total=2, connect=None, read=None, redirect=None)) after connection broken by 'ConnectTimeoutError(<telegram.vendor.ptb_urllib3.urllib3.connection.VerifiedHTTPSConnection object at 0x0000014622E58CD0>, 'Connection to api.telegram.org timed out. (connect timeout=5.0)')': /bot1433757250:AAEo4RDod8FFHlZw0bnbR_tHqzHWjYUistA/sendMessage
2021-01-14 02:57:06,380 - telegram.vendor.ptb_urllib3.urllib3.connectionpool - WARNING - Retrying (Retry(total=1, connect=None, read=None, redirect=None)) after connection broken by 'ConnectTimeoutError(<telegram.vendor.ptb_urllib3.urllib3.connection.VerifiedHTTPSConnection object at 0x000001B125FFF640>, 'Connection to api.telegram.org timed out. (connect timeout=5.0)')': /bot1433757250:AAEo4RDod8FFHlZw0bnbR_tHqzHWjYUistA/sendMessage
2021-01-14 02:57:11,001 - telegram.vendor.ptb_urllib3.urllib3.connectionpool - WARNING - Retrying (Retry(total=1, connect=None, read=None, redirect=None)) after connection broken by 'ConnectTimeoutError(<telegram.vendor.ptb_urllib3.urllib3.connection.VerifiedHTTPSConnection object at 0x0000014622E58850>, 'Connection to api.telegram.org timed out. (connect timeout=5.0)')': /bot1433757250:AAEo4RDod8FFHlZw0bnbR_tHqzHWjYUistA/sendMessage
2021-01-14 02:57:11,392 - telegram.vendor.ptb_urllib3.urllib3.connectionpool - WARNING - Retrying (Retry(total=0, connect=None, read=None, redirect=None)) after connection broken by 'ConnectTimeoutError(<telegram.vendor.ptb_urllib3.urllib3.connection.VerifiedHTTPSConnection object at 0x000001B125FFFDC0>, 'Connection to api.telegram.org timed out. (connect timeout=5.0)')': /bot1433757250:AAEo4RDod8FFHlZw0bnbR_tHqzHWjYUistA/sendMessage
2021-01-14 02:57:16,007 - telegram.vendor.ptb_urllib3.urllib3.connectionpool - WARNING - Retrying (Retry(total=0, connect=None, read=None, redirect=None)) after connection broken by 'ConnectTimeoutError(<telegram.vendor.ptb_urllib3.urllib3.connection.VerifiedHTTPSConnection object at 0x0000014622E58E80>, 'Connection to api.telegram.org timed out. (connect timeout=5.0)')': /bot1433757250:AAEo4RDod8FFHlZw0bnbR_tHqzHWjYUistA/sendMessage
2021-01-14 02:57:16,409 - __main__ - ERROR - Бот столкнулся с ошибкой: urllib3 HTTPError HTTPSConnectionPool(host='api.telegram.org', port=443): Max retries exceeded with url: /bot1433757250:AAEo4RDod8FFHlZw0bnbR_tHqzHWjYUistA/sendMessage (Caused by ConnectTimeoutError(<telegram.vendor.ptb_urllib3.urllib3.connection.VerifiedHTTPSConnection object at 0x000001B125FFFBB0>, 'Connection to api.telegram.org timed out. (connect timeout=5.0)'))
2021-01-14 02:57:21,024 - __main__ - ERROR - Бот столкнулся с ошибкой: urllib3 HTTPError HTTPSConnectionPool(host='api.telegram.org', port=443): Max retries exceeded with url: /bot1433757250:AAEo4RDod8FFHlZw0bnbR_tHqzHWjYUistA/sendMessage (Caused by ConnectTimeoutError(<telegram.vendor.ptb_urllib3.urllib3.connection.VerifiedHTTPSConnection object at 0x0000014622E58370>, 'Connection to api.telegram.org timed out. (connect timeout=5.0)'))
2021-01-14 02:57:22,597 - __main__ - INFO - Отправка сообщения в телеграм: У вас проверили работу "AnastasiaSar__api_sp1_bot.zip"!

К сожалению в работе нашлись ошибки.
2021-01-14 02:57:27,257 - __main__ - INFO - Отправка сообщения в телеграм: У вас проверили работу "AnastasiaSar__api_sp1_bot.zip"!

К сожалению в работе нашлись ошибки.
2021-01-14 02:57:27,607 - telegram.vendor.ptb_urllib3.urllib3.connectionpool - WARNING - Retrying (Retry(total=2, connect=None, read=None, redirect=None)) after connection broken by 'ConnectTimeoutError(<telegram.vendor.ptb_urllib3.urllib3.connection.VerifiedHTTPSConnection object at 0x000001B125FFFA00>, 'Connection to api.telegram.org timed out. (connect timeout=5.0)')': /bot1433757250:AAEo4RDod8FFHlZw0bnbR_tHqzHWjYUistA/sendMessage
2021-01-14 02:57:32,273 - telegram.vendor.ptb_urllib3.urllib3.connectionpool - WARNING - Retrying (Retry(total=2, connect=None, read=None, redirect=None)) after connection broken by 'ConnectTimeoutError(<telegram.vendor.ptb_urllib3.urllib3.connection.VerifiedHTTPSConnection object at 0x0000014622E0BA90>, 'Connection to api.telegram.org timed out. (connect timeout=5.0)')': /bot1433757250:AAEo4RDod8FFHlZw0bnbR_tHqzHWjYUistA/sendMessage
2021-01-14 02:57:32,615 - telegram.vendor.ptb_urllib3.urllib3.connectionpool - WARNING - Retrying (Retry(total=1, connect=None, read=None, redirect=None)) after connection broken by 'ConnectTimeoutError(<telegram.vendor.ptb_urllib3.urllib3.connection.VerifiedHTTPSConnection object at 0x000001B125FFFA90>, 'Connection to api.telegram.org timed out. (connect timeout=5.0)')': /bot1433757250:AAEo4RDod8FFHlZw0bnbR_tHqzHWjYUistA/sendMessage
2021-01-14 02:57:37,279 - telegram.vendor.ptb_urllib3.urllib3.connectionpool - WARNING - Retrying (Retry(total=1, connect=None, read=None, redirect=None)) after connection broken by 'ConnectTimeoutError(<telegram.vendor.ptb_urllib3.urllib3.connection.VerifiedHTTPSConnection object at 0x0000014622E5F340>, 'Connection to api.telegram.org timed out. (connect timeout=5.0)')': /bot1433757250:AAEo4RDod8FFHlZw0bnbR_tHqzHWjYUistA/sendMessage
2021-01-14 02:57:37,622 - telegram.vendor.ptb_urllib3.urllib3.connectionpool - WARNING - Retrying (Retry(total=0, connect=None, read=None, redirect=None)) after connection broken by 'ConnectTimeoutError(<telegram.vendor.ptb_urllib3.urllib3.connection.VerifiedHTTPSConnection object at 0x000001B125FFFD90>, 'Connection to api.telegram.org timed out. (connect timeout=5.0)')': /bot1433757250:AAEo4RDod8FFHlZw0bnbR_tHqzHWjYUistA/sendMessage
2021-01-14 02:57:42,297 - telegram.vendor.ptb_urllib3.urllib3.connectionpool - WARNING - Retrying (Retry(total=0, connect=None, read=None, redirect=None)) after connection broken by 'ConnectTimeoutError(<telegram.vendor.ptb_urllib3.urllib3.connection.VerifiedHTTPSConnection object at 0x0000014622E5FBE0>, 'Connection to api.telegram.org timed out. (connect timeout=5.0)')': /bot1433757250:AAEo4RDod8FFHlZw0bnbR_tHqzHWjYUistA/sendMessage
2021-01-14 02:57:42,641 - __main__ - ERROR - Бот столкнулся с ошибкой: urllib3 HTTPError HTTPSConnectionPool(host='api.telegram.org', port=443): Max retries exceeded with url: /bot1433757250:AAEo4RDod8FFHlZw0bnbR_tHqzHWjYUistA/sendMessage (Caused by ConnectTimeoutError(<telegram.vendor.ptb_urllib3.urllib3.connection.VerifiedHTTPSConnection object at 0x000001B125FFF490>, 'Connection to api.telegram.org timed out. (connect timeout=5.0)'))
2021-01-14 02:57:47,300 - __main__ - ERROR - Бот столкнулся с ошибкой: urllib3 HTTPError HTTPSConnectionPool(host='api.telegram.org', port=443): Max retries exceeded with url: /bot1433757250:AAEo4RDod8FFHlZw0bnbR_tHqzHWjYUistA/sendMessage (Caused by ConnectTimeoutError(<telegram.vendor.ptb_urllib3.urllib3.connection.VerifiedHTTPSConnection object at 0x0000014622E5F1C0>, 'Connection to api.telegram.org timed out. (connect timeout=5.0)'))
2021-01-14 02:57:48,914 - __main__ - INFO - Отправка сообщения в телеграм: У вас проверили работу "AnastasiaSar__api_sp1_bot.zip"!

К сожалению в работе нашлись ошибки.
2021-01-14 02:57:53,550 - __main__ - INFO - Отправка сообщения в телеграм: У вас проверили работу "AnastasiaSar__api_sp1_bot.zip"!

К сожалению в работе нашлись ошибки.
2021-01-14 02:57:53,921 - telegram.vendor.ptb_urllib3.urllib3.connectionpool - WARNING - Retrying (Retry(total=2, connect=None, read=None, redirect=None)) after connection broken by 'ConnectTimeoutError(<telegram.vendor.ptb_urllib3.urllib3.connection.VerifiedHTTPSConnection object at 0x000001B125FAD040>, 'Connection to api.telegram.org timed out. (connect timeout=5.0)')': /bot1433757250:AAEo4RDod8FFHlZw0bnbR_tHqzHWjYUistA/sendMessage
2021-01-14 02:57:58,560 - telegram.vendor.ptb_urllib3.urllib3.connectionpool - WARNING - Retrying (Retry(total=2, connect=None, read=None, redirect=None)) after connection broken by 'ConnectTimeoutError(<telegram.vendor.ptb_urllib3.urllib3.connection.VerifiedHTTPSConnection object at 0x0000014622E5FF10>, 'Connection to api.telegram.org timed out. (connect timeout=5.0)')': /bot1433757250:AAEo4RDod8FFHlZw0bnbR_tHqzHWjYUistA/sendMessage
2021-01-14 02:57:58,932 - telegram.vendor.ptb_urllib3.urllib3.connectionpool - WARNING - Retrying (Retry(total=1, connect=None, read=None, redirect=None)) after connection broken by 'ConnectTimeoutError(<telegram.vendor.ptb_urllib3.urllib3.connection.VerifiedHTTPSConnection object at 0x000001B125FAD550>, 'Connection to api.telegram.org timed out. (connect timeout=5.0)')': /bot1433757250:AAEo4RDod8FFHlZw0bnbR_tHqzHWjYUistA/sendMessage
2021-01-14 02:58:03,573 - telegram.vendor.ptb_urllib3.urllib3.connectionpool - WARNING - Retrying (Retry(total=1, connect=None, read=None, redirect=None)) after connection broken by 'ConnectTimeoutError(<telegram.vendor.ptb_urllib3.urllib3.connection.VerifiedHTTPSConnection object at 0x0000014622E58100>, 'Connection to api.telegram.org timed out. (connect timeout=5.0)')': /bot1433757250:AAEo4RDod8FFHlZw0bnbR_tHqzHWjYUistA/sendMessage
2021-01-14 02:58:03,947 - telegram.vendor.ptb_urllib3.urllib3.connectionpool - WARNING - Retrying (Retry(total=0, connect=None, read=None, redirect=None)) after connection broken by 'ConnectTimeoutError(<telegram.vendor.ptb_urllib3.urllib3.connection.VerifiedHTTPSConnection object at 0x000001B125FAD490>, 'Connection to api.telegram.org timed out. (connect timeout=5.0)')': /bot1433757250:AAEo4RDod8FFHlZw0bnbR_tHqzHWjYUistA/sendMessage
2021-01-14 02:58:08,587 - telegram.vendor.ptb_urllib3.urllib3.connectionpool - WARNING - Retrying (Retry(total=0, connect=None, read=None, redirect=None)) after connection broken by 'ConnectTimeoutError(<telegram.vendor.ptb_urllib3.urllib3.connection.VerifiedHTTPSConnection object at 0x0000014622E74520>, 'Connection to api.telegram.org timed out. (connect timeout=5.0)')': /bot1433757250:AAEo4RDod8FFHlZw0bnbR_tHqzHWjYUistA/sendMessage
2021-01-14 02:58:08,959 - __main__ - ERROR - Бот столкнулся с ошибкой: urllib3 HTTPError HTTPSConnectionPool(host='api.telegram.org', port=443): Max retries exceeded with url: /bot1433757250:AAEo4RDod8FFHlZw0bnbR_tHqzHWjYUistA/sendMessage (Caused by ConnectTimeoutError(<telegram.vendor.ptb_urllib3.urllib3.connection.VerifiedHTTPSConnection object at 0x000001B125FAD340>, 'Connection to api.telegram.org timed out. (connect timeout=5.0)'))
2021-01-14 02:58:13,610 - __main__ - ERROR - Бот столкнулся с ошибкой: urllib3 HTTPError HTTPSConnectionPool(host='api.telegram.org', port=443): Max retries exceeded with url: /bot1433757250:AAEo4RDod8FFHlZw0bnbR_tHqzHWjYUistA/sendMessage (Caused by ConnectTimeoutError(<telegram.vendor.ptb_urllib3.urllib3.connection.VerifiedHTTPSConnection object at 0x0000014622E746A0>, 'Connection to api.telegram.org timed out. (connect timeout=5.0)'))
2021-01-14 02:58:16,620 - __main__ - INFO - Отправка сообщения в телеграм: У вас проверили работу "AnastasiaSar__api_sp1_bot.zip"!

К сожалению в работе нашлись ошибки.
2021-01-14 02:58:19,953 - __main__ - INFO - Отправка сообщения в телеграм: У вас проверили работу "AnastasiaSar__api_sp1_bot.zip"!

К сожалению в работе нашлись ошибки.
2021-01-14 02:58:21,625 - telegram.vendor.ptb_urllib3.urllib3.connectionpool - WARNING - Retrying (Retry(total=2, connect=None, read=None, redirect=None)) after connection broken by 'ConnectTimeoutError(<telegram.vendor.ptb_urllib3.urllib3.connection.VerifiedHTTPSConnection object at 0x000001B125FAD460>, 'Connection to api.telegram.org timed out. (connect timeout=5.0)')': /bot1433757250:AAEo4RDod8FFHlZw0bnbR_tHqzHWjYUistA/sendMessage
